[2016-11-04 16:31:12] DEBUG [django.db.backends:90] (0.016) 
            SELECT name, type FROM sqlite_master
            WHERE type in ('table', 'view') AND NOT name='sqlite_sequence'
            ORDER BY name; args=None
[2016-11-04 16:31:12] DEBUG [django.db.backends:90] (0.000) SELECT "django_migrations"."app", "django_migrations"."name" FROM "django_migrations"; args=()
[2016-11-04 17:24:54] DEBUG [django.db.backends:90] (0.004) 
            SELECT name, type FROM sqlite_master
            WHERE type in ('table', 'view') AND NOT name='sqlite_sequence'
            ORDER BY name; args=None
[2016-11-04 17:24:54] DEBUG [django.db.backends:90] (0.000) SELECT "django_migrations"."app", "django_migrations"."name" FROM "django_migrations"; args=()
[2016-11-04 17:27:55] DEBUG [django.db.backends:90] (0.000) 
            SELECT name, type FROM sqlite_master
            WHERE type in ('table', 'view') AND NOT name='sqlite_sequence'
            ORDER BY name; args=None
[2016-11-04 17:27:55] DEBUG [django.db.backends:90] (0.000) SELECT "django_migrations"."app", "django_migrations"."name" FROM "django_migrations"; args=()
[2016-11-04 17:28:27] INFO [django.server:131] "OPTIONS /api/auths/localuserinfo/ HTTP/1.1" 200 0
[2016-11-04 17:28:27] INFO [django.server:131] "OPTIONS /api/auths/usermenu/ HTTP/1.1" 200 0
[2016-11-04 17:28:27] DEBUG [django.db.backends:90] (0.003) SELECT "oauth2_provider_accesstoken"."id", "oauth2_provider_accesstoken"."user_id", "oauth2_provider_accesstoken"."token", "oauth2_provider_accesstoken"."application_id", "oauth2_provider_accesstoken"."expires", "oauth2_provider_accesstoken"."scope", "auths_user"."password", "auths_user"."last_login", "auths_user"."is_superuser", "auths_user"."username", "auths_user"."first_name", "auths_user"."last_name", "auths_user"."email", "auths_user"."is_staff", "auths_user"."is_active", "auths_user"."date_joined", "auths_user"."id", "auths_user"."last_hierarchy_id", "auths_user"."last_module_id", "auths_user"."person_id", "auths_user"."updated_at", "auths_user"."registered_by", "oauth2_provider_application"."id", "oauth2_provider_application"."client_id", "oauth2_provider_application"."user_id", "oauth2_provider_application"."redirect_uris", "oauth2_provider_application"."client_type", "oauth2_provider_application"."authorization_grant_type", "oauth2_provider_application"."client_secret", "oauth2_provider_application"."name", "oauth2_provider_application"."skip_authorization" FROM "oauth2_provider_accesstoken" LEFT OUTER JOIN "auths_user" ON ("oauth2_provider_accesstoken"."user_id" = "auths_user"."id") INNER JOIN "oauth2_provider_application" ON ("oauth2_provider_accesstoken"."application_id" = "oauth2_provider_application"."id") WHERE "oauth2_provider_accesstoken"."token" = 'x9lprEdE6lbYgXrpP8ILKvrUM7UqFh'; args=('x9lprEdE6lbYgXrpP8ILKvrUM7UqFh',)
[2016-11-04 17:28:27] WARNING [django.server:131] "GET /api/auths/localuserinfo/ HTTP/1.1" 401 58
[2016-11-04 17:28:27] DEBUG [django.db.backends:90] (0.005) SELECT "oauth2_provider_accesstoken"."id", "oauth2_provider_accesstoken"."user_id", "oauth2_provider_accesstoken"."token", "oauth2_provider_accesstoken"."application_id", "oauth2_provider_accesstoken"."expires", "oauth2_provider_accesstoken"."scope", "auths_user"."password", "auths_user"."last_login", "auths_user"."is_superuser", "auths_user"."username", "auths_user"."first_name", "auths_user"."last_name", "auths_user"."email", "auths_user"."is_staff", "auths_user"."is_active", "auths_user"."date_joined", "auths_user"."id", "auths_user"."last_hierarchy_id", "auths_user"."last_module_id", "auths_user"."person_id", "auths_user"."updated_at", "auths_user"."registered_by", "oauth2_provider_application"."id", "oauth2_provider_application"."client_id", "oauth2_provider_application"."user_id", "oauth2_provider_application"."redirect_uris", "oauth2_provider_application"."client_type", "oauth2_provider_application"."authorization_grant_type", "oauth2_provider_application"."client_secret", "oauth2_provider_application"."name", "oauth2_provider_application"."skip_authorization" FROM "oauth2_provider_accesstoken" LEFT OUTER JOIN "auths_user" ON ("oauth2_provider_accesstoken"."user_id" = "auths_user"."id") INNER JOIN "oauth2_provider_application" ON ("oauth2_provider_accesstoken"."application_id" = "oauth2_provider_application"."id") WHERE "oauth2_provider_accesstoken"."token" = 'x9lprEdE6lbYgXrpP8ILKvrUM7UqFh'; args=('x9lprEdE6lbYgXrpP8ILKvrUM7UqFh',)
[2016-11-04 17:28:27] WARNING [django.server:131] "GET /api/auths/usermenu/ HTTP/1.1" 401 58
[2016-11-04 17:28:28] ERROR [django.server:131] "GET /api/auths/usermenu/ HTTP/1.1" 500 59
[2016-11-04 17:28:28] DEBUG [django.db.backends:90] (0.002) SELECT "auths_menu"."router_json" FROM "auths_menu" ORDER BY "auths_menu"."pos" ASC; args=()
[2016-11-04 17:28:28] INFO [django.server:131] "GET /api/auths/routers/ HTTP/1.1" 200 2
[2016-11-04 17:28:38] DEBUG [django.db.backends:90] (0.003) SELECT "oauth2_provider_application"."id", "oauth2_provider_application"."client_id", "oauth2_provider_application"."user_id", "oauth2_provider_application"."redirect_uris", "oauth2_provider_application"."client_type", "oauth2_provider_application"."authorization_grant_type", "oauth2_provider_application"."client_secret", "oauth2_provider_application"."name", "oauth2_provider_application"."skip_authorization" FROM "oauth2_provider_application" WHERE "oauth2_provider_application"."client_id" = 'gyEJ310NDKMKrYvOMbwSnu9UFkJkXE5E48dCLRZK'; args=('gyEJ310NDKMKrYvOMbwSnu9UFkJkXE5E48dCLRZK',)
[2016-11-04 17:28:38] DEBUG [django.db.backends:90] (0.001) SELECT "auths_user"."password", "auths_user"."last_login", "auths_user"."is_superuser", "auths_user"."username", "auths_user"."first_name", "auths_user"."last_name", "auths_user"."email", "auths_user"."is_staff", "auths_user"."is_active", "auths_user"."date_joined", "auths_user"."id", "auths_user"."last_hierarchy_id", "auths_user"."last_module_id", "auths_user"."person_id", "auths_user"."updated_at", "auths_user"."registered_by" FROM "auths_user" WHERE "auths_user"."username" = 'admin'; args=('admin',)
[2016-11-04 17:28:38] DEBUG [django.db.backends:90] (0.000) BEGIN; args=None
[2016-11-04 17:28:38] DEBUG [django.db.backends:90] (0.029) INSERT INTO "oauth2_provider_accesstoken" ("user_id", "token", "application_id", "expires", "scope") VALUES ('3651942c1384420da02bbf9e5eca3faa', 'CqxqZcZN71EyXOvauC8JLnQjgmobZv', 1, '2016-11-05 08:28:38.603437', 'read write'); args=['3651942c1384420da02bbf9e5eca3faa', 'CqxqZcZN71EyXOvauC8JLnQjgmobZv', 1, '2016-11-05 08:28:38.603437', 'read write']
[2016-11-04 17:28:38] DEBUG [django.db.backends:90] (0.000) BEGIN; args=None
[2016-11-04 17:28:38] DEBUG [django.db.backends:90] (0.002) INSERT INTO "oauth2_provider_refreshtoken" ("user_id", "token", "application_id", "access_token_id") VALUES ('3651942c1384420da02bbf9e5eca3faa', 'A268YJ4rrlBa05AyLm30qLtkBwTJEN', 1, 4); args=['3651942c1384420da02bbf9e5eca3faa', 'A268YJ4rrlBa05AyLm30qLtkBwTJEN', 1, 4]
[2016-11-04 17:28:38] INFO [django.server:131] "POST /o/token/ HTTP/1.1" 200 169
[2016-11-04 17:28:40] DEBUG [django.db.backends:90] (0.004) SELECT "oauth2_provider_accesstoken"."id", "oauth2_provider_accesstoken"."user_id", "oauth2_provider_accesstoken"."token", "oauth2_provider_accesstoken"."application_id", "oauth2_provider_accesstoken"."expires", "oauth2_provider_accesstoken"."scope", "auths_user"."password", "auths_user"."last_login", "auths_user"."is_superuser", "auths_user"."username", "auths_user"."first_name", "auths_user"."last_name", "auths_user"."email", "auths_user"."is_staff", "auths_user"."is_active", "auths_user"."date_joined", "auths_user"."id", "auths_user"."last_hierarchy_id", "auths_user"."last_module_id", "auths_user"."person_id", "auths_user"."updated_at", "auths_user"."registered_by", "oauth2_provider_application"."id", "oauth2_provider_application"."client_id", "oauth2_provider_application"."user_id", "oauth2_provider_application"."redirect_uris", "oauth2_provider_application"."client_type", "oauth2_provider_application"."authorization_grant_type", "oauth2_provider_application"."client_secret", "oauth2_provider_application"."name", "oauth2_provider_application"."skip_authorization" FROM "oauth2_provider_accesstoken" LEFT OUTER JOIN "auths_user" ON ("oauth2_provider_accesstoken"."user_id" = "auths_user"."id") INNER JOIN "oauth2_provider_application" ON ("oauth2_provider_accesstoken"."application_id" = "oauth2_provider_application"."id") WHERE "oauth2_provider_accesstoken"."token" = 'CqxqZcZN71EyXOvauC8JLnQjgmobZv'; args=('CqxqZcZN71EyXOvauC8JLnQjgmobZv',)
[2016-11-04 17:28:40] INFO [django.server:131] "OPTIONS /api/auths/usermenu/ HTTP/1.1" 200 0
[2016-11-04 17:28:41] DEBUG [django.db.backends:90] (0.000) SELECT "auth_group"."id", "auth_group"."name" FROM "auth_group" INNER JOIN "auths_user_groups" ON ("auth_group"."id" = "auths_user_groups"."group_id") WHERE "auths_user_groups"."user_id" = '3651942c1384420da02bbf9e5eca3faa'; args=('3651942c1384420da02bbf9e5eca3faa',)
[2016-11-04 17:28:41] DEBUG [django.db.backends:90] (0.001) SELECT "auth_permission"."id", "auth_permission"."name", "auth_permission"."content_type_id", "auth_permission"."codename" FROM "auth_permission" INNER JOIN "auths_user_user_permissions" ON ("auth_permission"."id" = "auths_user_user_permissions"."permission_id") INNER JOIN "django_content_type" ON ("auth_permission"."content_type_id" = "django_content_type"."id") WHERE "auths_user_user_permissions"."user_id" = '3651942c1384420da02bbf9e5eca3faa' ORDER BY "django_content_type"."app_label" ASC, "django_content_type"."model" ASC, "auth_permission"."codename" ASC; args=('3651942c1384420da02bbf9e5eca3faa',)
[2016-11-04 17:28:41] INFO [django.server:131] "GET /api/auths/localuserinfo/ HTTP/1.1" 200 496
[2016-11-04 17:28:41] DEBUG [django.db.backends:90] (0.003) SELECT "oauth2_provider_accesstoken"."id", "oauth2_provider_accesstoken"."user_id", "oauth2_provider_accesstoken"."token", "oauth2_provider_accesstoken"."application_id", "oauth2_provider_accesstoken"."expires", "oauth2_provider_accesstoken"."scope", "auths_user"."password", "auths_user"."last_login", "auths_user"."is_superuser", "auths_user"."username", "auths_user"."first_name", "auths_user"."last_name", "auths_user"."email", "auths_user"."is_staff", "auths_user"."is_active", "auths_user"."date_joined", "auths_user"."id", "auths_user"."last_hierarchy_id", "auths_user"."last_module_id", "auths_user"."person_id", "auths_user"."updated_at", "auths_user"."registered_by", "oauth2_provider_application"."id", "oauth2_provider_application"."client_id", "oauth2_provider_application"."user_id", "oauth2_provider_application"."redirect_uris", "oauth2_provider_application"."client_type", "oauth2_provider_application"."authorization_grant_type", "oauth2_provider_application"."client_secret", "oauth2_provider_application"."name", "oauth2_provider_application"."skip_authorization" FROM "oauth2_provider_accesstoken" LEFT OUTER JOIN "auths_user" ON ("oauth2_provider_accesstoken"."user_id" = "auths_user"."id") INNER JOIN "oauth2_provider_application" ON ("oauth2_provider_accesstoken"."application_id" = "oauth2_provider_application"."id") WHERE "oauth2_provider_accesstoken"."token" = 'CqxqZcZN71EyXOvauC8JLnQjgmobZv'; args=('CqxqZcZN71EyXOvauC8JLnQjgmobZv',)
[2016-11-04 17:28:41] DEBUG [django.db.backends:90] (0.001) SELECT "auths_menu"."id" FROM "auths_menu" WHERE ("auths_menu"."id" IS NOT NULL AND "auths_menu"."is_active" = 1 AND "auths_menu"."module" = 'BACKEND') ORDER BY "auths_menu"."pos" ASC; args=(True, 'BACKEND')
[2016-11-04 17:28:41] DEBUG [django.db.backends:90] (0.002) SELECT (1) AS "a" FROM "django_session" WHERE "django_session"."session_key" = 'xc998533c4ap5zx4diq15ytcwq83ogsy' LIMIT 1; args=('xc998533c4ap5zx4diq15ytcwq83ogsy',)
[2016-11-04 17:28:41] DEBUG [django.db.backends:90] (0.000) BEGIN; args=None
[2016-11-04 17:28:41] DEBUG [django.db.backends:90] (0.003) INSERT INTO "django_session" ("session_key", "session_data", "expire_date") SELECT 'xc998533c4ap5zx4diq15ytcwq83ogsy', 'NmE3M2Q3NmYwOTU3YjJmZDBjYmQxYTVjODc5MTExNzM3NjY1YzYzNzp7Il9zZXNzaW9uX2V4cGlyeSI6MzB9', '2016-11-04 22:29:11.588803'; args=('xc998533c4ap5zx4diq15ytcwq83ogsy', 'NmE3M2Q3NmYwOTU3YjJmZDBjYmQxYTVjODc5MTExNzM3NjY1YzYzNzp7Il9zZXNzaW9uX2V4cGlyeSI6MzB9', '2016-11-04 22:29:11.588803')
[2016-11-04 17:28:41] INFO [django.server:131] "GET /api/auths/usermenu/ HTTP/1.1" 200 11
[2016-11-04 17:28:54] INFO [django.server:131] "OPTIONS /api/catalogo/categorias/ HTTP/1.1" 200 0
[2016-11-04 17:28:54] DEBUG [django.db.backends:90] (0.004) SELECT "oauth2_provider_accesstoken"."id", "oauth2_provider_accesstoken"."user_id", "oauth2_provider_accesstoken"."token", "oauth2_provider_accesstoken"."application_id", "oauth2_provider_accesstoken"."expires", "oauth2_provider_accesstoken"."scope", "auths_user"."password", "auths_user"."last_login", "auths_user"."is_superuser", "auths_user"."username", "auths_user"."first_name", "auths_user"."last_name", "auths_user"."email", "auths_user"."is_staff", "auths_user"."is_active", "auths_user"."date_joined", "auths_user"."id", "auths_user"."last_hierarchy_id", "auths_user"."last_module_id", "auths_user"."person_id", "auths_user"."updated_at", "auths_user"."registered_by", "oauth2_provider_application"."id", "oauth2_provider_application"."client_id", "oauth2_provider_application"."user_id", "oauth2_provider_application"."redirect_uris", "oauth2_provider_application"."client_type", "oauth2_provider_application"."authorization_grant_type", "oauth2_provider_application"."client_secret", "oauth2_provider_application"."name", "oauth2_provider_application"."skip_authorization" FROM "oauth2_provider_accesstoken" LEFT OUTER JOIN "auths_user" ON ("oauth2_provider_accesstoken"."user_id" = "auths_user"."id") INNER JOIN "oauth2_provider_application" ON ("oauth2_provider_accesstoken"."application_id" = "oauth2_provider_application"."id") WHERE "oauth2_provider_accesstoken"."token" = 'CqxqZcZN71EyXOvauC8JLnQjgmobZv'; args=('CqxqZcZN71EyXOvauC8JLnQjgmobZv',)
[2016-11-04 17:28:54] DEBUG [django.db.backends:90] (0.001) SELECT "catalogo_categoria"."id", "catalogo_categoria"."nombre", "catalogo_categoria"."codigo", "catalogo_categoria"."estado" FROM "catalogo_categoria" WHERE ("catalogo_categoria"."codigo" LIKE '%%' ESCAPE '\' OR "catalogo_categoria"."nombre" LIKE '%%' ESCAPE '\'); args=('%%', '%%')
[2016-11-04 17:28:54] INFO [django.server:131] "GET /api/catalogo/categorias/ HTTP/1.1" 200 2
[2016-11-04 17:28:56] INFO [django.server:131] "OPTIONS /api/catalogo/autors/ HTTP/1.1" 200 0
[2016-11-04 17:28:56] DEBUG [django.db.backends:90] (0.006) SELECT "oauth2_provider_accesstoken"."id", "oauth2_provider_accesstoken"."user_id", "oauth2_provider_accesstoken"."token", "oauth2_provider_accesstoken"."application_id", "oauth2_provider_accesstoken"."expires", "oauth2_provider_accesstoken"."scope", "auths_user"."password", "auths_user"."last_login", "auths_user"."is_superuser", "auths_user"."username", "auths_user"."first_name", "auths_user"."last_name", "auths_user"."email", "auths_user"."is_staff", "auths_user"."is_active", "auths_user"."date_joined", "auths_user"."id", "auths_user"."last_hierarchy_id", "auths_user"."last_module_id", "auths_user"."person_id", "auths_user"."updated_at", "auths_user"."registered_by", "oauth2_provider_application"."id", "oauth2_provider_application"."client_id", "oauth2_provider_application"."user_id", "oauth2_provider_application"."redirect_uris", "oauth2_provider_application"."client_type", "oauth2_provider_application"."authorization_grant_type", "oauth2_provider_application"."client_secret", "oauth2_provider_application"."name", "oauth2_provider_application"."skip_authorization" FROM "oauth2_provider_accesstoken" LEFT OUTER JOIN "auths_user" ON ("oauth2_provider_accesstoken"."user_id" = "auths_user"."id") INNER JOIN "oauth2_provider_application" ON ("oauth2_provider_accesstoken"."application_id" = "oauth2_provider_application"."id") WHERE "oauth2_provider_accesstoken"."token" = 'CqxqZcZN71EyXOvauC8JLnQjgmobZv'; args=('CqxqZcZN71EyXOvauC8JLnQjgmobZv',)
[2016-11-04 17:28:56] DEBUG [django.db.backends:90] (0.000) SELECT COUNT(*) AS "__count" FROM "catalogo_autor"; args=()
[2016-11-04 17:28:56] INFO [django.server:131] "GET /api/catalogo/autors/ HTTP/1.1" 200 124
[2016-11-04 17:31:55] DEBUG [django.db.backends:90] (0.004) SELECT "oauth2_provider_accesstoken"."id", "oauth2_provider_accesstoken"."user_id", "oauth2_provider_accesstoken"."token", "oauth2_provider_accesstoken"."application_id", "oauth2_provider_accesstoken"."expires", "oauth2_provider_accesstoken"."scope", "auths_user"."password", "auths_user"."last_login", "auths_user"."is_superuser", "auths_user"."username", "auths_user"."first_name", "auths_user"."last_name", "auths_user"."email", "auths_user"."is_staff", "auths_user"."is_active", "auths_user"."date_joined", "auths_user"."id", "auths_user"."last_hierarchy_id", "auths_user"."last_module_id", "auths_user"."person_id", "auths_user"."updated_at", "auths_user"."registered_by", "oauth2_provider_application"."id", "oauth2_provider_application"."client_id", "oauth2_provider_application"."user_id", "oauth2_provider_application"."redirect_uris", "oauth2_provider_application"."client_type", "oauth2_provider_application"."authorization_grant_type", "oauth2_provider_application"."client_secret", "oauth2_provider_application"."name", "oauth2_provider_application"."skip_authorization" FROM "oauth2_provider_accesstoken" LEFT OUTER JOIN "auths_user" ON ("oauth2_provider_accesstoken"."user_id" = "auths_user"."id") INNER JOIN "oauth2_provider_application" ON ("oauth2_provider_accesstoken"."application_id" = "oauth2_provider_application"."id") WHERE "oauth2_provider_accesstoken"."token" = 'CqxqZcZN71EyXOvauC8JLnQjgmobZv'; args=('CqxqZcZN71EyXOvauC8JLnQjgmobZv',)
[2016-11-04 17:31:55] DEBUG [django.db.backends:90] (0.007) SELECT "oauth2_provider_accesstoken"."id", "oauth2_provider_accesstoken"."user_id", "oauth2_provider_accesstoken"."token", "oauth2_provider_accesstoken"."application_id", "oauth2_provider_accesstoken"."expires", "oauth2_provider_accesstoken"."scope", "auths_user"."password", "auths_user"."last_login", "auths_user"."is_superuser", "auths_user"."username", "auths_user"."first_name", "auths_user"."last_name", "auths_user"."email", "auths_user"."is_staff", "auths_user"."is_active", "auths_user"."date_joined", "auths_user"."id", "auths_user"."last_hierarchy_id", "auths_user"."last_module_id", "auths_user"."person_id", "auths_user"."updated_at", "auths_user"."registered_by", "oauth2_provider_application"."id", "oauth2_provider_application"."client_id", "oauth2_provider_application"."user_id", "oauth2_provider_application"."redirect_uris", "oauth2_provider_application"."client_type", "oauth2_provider_application"."authorization_grant_type", "oauth2_provider_application"."client_secret", "oauth2_provider_application"."name", "oauth2_provider_application"."skip_authorization" FROM "oauth2_provider_accesstoken" LEFT OUTER JOIN "auths_user" ON ("oauth2_provider_accesstoken"."user_id" = "auths_user"."id") INNER JOIN "oauth2_provider_application" ON ("oauth2_provider_accesstoken"."application_id" = "oauth2_provider_application"."id") WHERE "oauth2_provider_accesstoken"."token" = 'CqxqZcZN71EyXOvauC8JLnQjgmobZv'; args=('CqxqZcZN71EyXOvauC8JLnQjgmobZv',)
[2016-11-04 17:31:55] DEBUG [django.db.backends:90] (0.001) SELECT "auths_menu"."id" FROM "auths_menu" WHERE ("auths_menu"."id" IS NOT NULL AND "auths_menu"."is_active" = 1 AND "auths_menu"."module" = 'BACKEND') ORDER BY "auths_menu"."pos" ASC; args=(True, 'BACKEND')
[2016-11-04 17:31:55] DEBUG [django.db.backends:90] (0.001) SELECT "auth_group"."id", "auth_group"."name" FROM "auth_group" INNER JOIN "auths_user_groups" ON ("auth_group"."id" = "auths_user_groups"."group_id") WHERE "auths_user_groups"."user_id" = '3651942c1384420da02bbf9e5eca3faa'; args=('3651942c1384420da02bbf9e5eca3faa',)
[2016-11-04 17:31:55] DEBUG [django.db.backends:90] (0.012) SELECT (1) AS "a" FROM "django_session" WHERE "django_session"."session_key" = 'syeidip8uc22tcy9wwe1aecey49c8kno' LIMIT 1; args=('syeidip8uc22tcy9wwe1aecey49c8kno',)
[2016-11-04 17:31:55] DEBUG [django.db.backends:90] (0.001) BEGIN; args=None
[2016-11-04 17:31:55] DEBUG [django.db.backends:90] (0.002) SELECT "auth_permission"."id", "auth_permission"."name", "auth_permission"."content_type_id", "auth_permission"."codename" FROM "auth_permission" INNER JOIN "auths_user_user_permissions" ON ("auth_permission"."id" = "auths_user_user_permissions"."permission_id") INNER JOIN "django_content_type" ON ("auth_permission"."content_type_id" = "django_content_type"."id") WHERE "auths_user_user_permissions"."user_id" = '3651942c1384420da02bbf9e5eca3faa' ORDER BY "django_content_type"."app_label" ASC, "django_content_type"."model" ASC, "auth_permission"."codename" ASC; args=('3651942c1384420da02bbf9e5eca3faa',)
[2016-11-04 17:31:55] INFO [django.server:131] "GET /api/auths/localuserinfo/ HTTP/1.1" 200 496
[2016-11-04 17:31:55] DEBUG [django.db.backends:90] (0.003) INSERT INTO "django_session" ("session_key", "session_data", "expire_date") SELECT 'syeidip8uc22tcy9wwe1aecey49c8kno', 'NmE3M2Q3NmYwOTU3YjJmZDBjYmQxYTVjODc5MTExNzM3NjY1YzYzNzp7Il9zZXNzaW9uX2V4cGlyeSI6MzB9', '2016-11-04 22:32:25.844722'; args=('syeidip8uc22tcy9wwe1aecey49c8kno', 'NmE3M2Q3NmYwOTU3YjJmZDBjYmQxYTVjODc5MTExNzM3NjY1YzYzNzp7Il9zZXNzaW9uX2V4cGlyeSI6MzB9', '2016-11-04 22:32:25.844722')
[2016-11-04 17:31:55] INFO [django.server:131] "GET /api/auths/usermenu/ HTTP/1.1" 200 11
[2016-11-04 17:31:56] DEBUG [django.db.backends:90] (0.003) SELECT "oauth2_provider_accesstoken"."id", "oauth2_provider_accesstoken"."user_id", "oauth2_provider_accesstoken"."token", "oauth2_provider_accesstoken"."application_id", "oauth2_provider_accesstoken"."expires", "oauth2_provider_accesstoken"."scope", "auths_user"."password", "auths_user"."last_login", "auths_user"."is_superuser", "auths_user"."username", "auths_user"."first_name", "auths_user"."last_name", "auths_user"."email", "auths_user"."is_staff", "auths_user"."is_active", "auths_user"."date_joined", "auths_user"."id", "auths_user"."last_hierarchy_id", "auths_user"."last_module_id", "auths_user"."person_id", "auths_user"."updated_at", "auths_user"."registered_by", "oauth2_provider_application"."id", "oauth2_provider_application"."client_id", "oauth2_provider_application"."user_id", "oauth2_provider_application"."redirect_uris", "oauth2_provider_application"."client_type", "oauth2_provider_application"."authorization_grant_type", "oauth2_provider_application"."client_secret", "oauth2_provider_application"."name", "oauth2_provider_application"."skip_authorization" FROM "oauth2_provider_accesstoken" LEFT OUTER JOIN "auths_user" ON ("oauth2_provider_accesstoken"."user_id" = "auths_user"."id") INNER JOIN "oauth2_provider_application" ON ("oauth2_provider_accesstoken"."application_id" = "oauth2_provider_application"."id") WHERE "oauth2_provider_accesstoken"."token" = 'CqxqZcZN71EyXOvauC8JLnQjgmobZv'; args=('CqxqZcZN71EyXOvauC8JLnQjgmobZv',)
[2016-11-04 17:31:56] DEBUG [django.db.backends:90] (0.000) SELECT COUNT(*) AS "__count" FROM "catalogo_autor"; args=()
[2016-11-04 17:31:56] INFO [django.server:131] "GET /api/catalogo/autors/ HTTP/1.1" 200 124
[2016-11-04 17:34:36] DEBUG [django.db.backends:90] (0.008) SELECT "oauth2_provider_accesstoken"."id", "oauth2_provider_accesstoken"."user_id", "oauth2_provider_accesstoken"."token", "oauth2_provider_accesstoken"."application_id", "oauth2_provider_accesstoken"."expires", "oauth2_provider_accesstoken"."scope", "auths_user"."password", "auths_user"."last_login", "auths_user"."is_superuser", "auths_user"."username", "auths_user"."first_name", "auths_user"."last_name", "auths_user"."email", "auths_user"."is_staff", "auths_user"."is_active", "auths_user"."date_joined", "auths_user"."id", "auths_user"."last_hierarchy_id", "auths_user"."last_module_id", "auths_user"."person_id", "auths_user"."updated_at", "auths_user"."registered_by", "oauth2_provider_application"."id", "oauth2_provider_application"."client_id", "oauth2_provider_application"."user_id", "oauth2_provider_application"."redirect_uris", "oauth2_provider_application"."client_type", "oauth2_provider_application"."authorization_grant_type", "oauth2_provider_application"."client_secret", "oauth2_provider_application"."name", "oauth2_provider_application"."skip_authorization" FROM "oauth2_provider_accesstoken" LEFT OUTER JOIN "auths_user" ON ("oauth2_provider_accesstoken"."user_id" = "auths_user"."id") INNER JOIN "oauth2_provider_application" ON ("oauth2_provider_accesstoken"."application_id" = "oauth2_provider_application"."id") WHERE "oauth2_provider_accesstoken"."token" = 'CqxqZcZN71EyXOvauC8JLnQjgmobZv'; args=('CqxqZcZN71EyXOvauC8JLnQjgmobZv',)
[2016-11-04 17:34:36] DEBUG [django.db.backends:90] (0.003) SELECT "oauth2_provider_accesstoken"."id", "oauth2_provider_accesstoken"."user_id", "oauth2_provider_accesstoken"."token", "oauth2_provider_accesstoken"."application_id", "oauth2_provider_accesstoken"."expires", "oauth2_provider_accesstoken"."scope", "auths_user"."password", "auths_user"."last_login", "auths_user"."is_superuser", "auths_user"."username", "auths_user"."first_name", "auths_user"."last_name", "auths_user"."email", "auths_user"."is_staff", "auths_user"."is_active", "auths_user"."date_joined", "auths_user"."id", "auths_user"."last_hierarchy_id", "auths_user"."last_module_id", "auths_user"."person_id", "auths_user"."updated_at", "auths_user"."registered_by", "oauth2_provider_application"."id", "oauth2_provider_application"."client_id", "oauth2_provider_application"."user_id", "oauth2_provider_application"."redirect_uris", "oauth2_provider_application"."client_type", "oauth2_provider_application"."authorization_grant_type", "oauth2_provider_application"."client_secret", "oauth2_provider_application"."name", "oauth2_provider_application"."skip_authorization" FROM "oauth2_provider_accesstoken" LEFT OUTER JOIN "auths_user" ON ("oauth2_provider_accesstoken"."user_id" = "auths_user"."id") INNER JOIN "oauth2_provider_application" ON ("oauth2_provider_accesstoken"."application_id" = "oauth2_provider_application"."id") WHERE "oauth2_provider_accesstoken"."token" = 'CqxqZcZN71EyXOvauC8JLnQjgmobZv'; args=('CqxqZcZN71EyXOvauC8JLnQjgmobZv',)
[2016-11-04 17:34:36] DEBUG [django.db.backends:90] (0.001) SELECT "auths_menu"."id" FROM "auths_menu" WHERE ("auths_menu"."id" IS NOT NULL AND "auths_menu"."is_active" = 1 AND "auths_menu"."module" = 'BACKEND') ORDER BY "auths_menu"."pos" ASC; args=(True, 'BACKEND')
[2016-11-04 17:34:36] DEBUG [django.db.backends:90] (0.000) SELECT "auth_group"."id", "auth_group"."name" FROM "auth_group" INNER JOIN "auths_user_groups" ON ("auth_group"."id" = "auths_user_groups"."group_id") WHERE "auths_user_groups"."user_id" = '3651942c1384420da02bbf9e5eca3faa'; args=('3651942c1384420da02bbf9e5eca3faa',)
[2016-11-04 17:34:36] DEBUG [django.db.backends:90] (0.001) SELECT "auth_permission"."id", "auth_permission"."name", "auth_permission"."content_type_id", "auth_permission"."codename" FROM "auth_permission" INNER JOIN "auths_user_user_permissions" ON ("auth_permission"."id" = "auths_user_user_permissions"."permission_id") INNER JOIN "django_content_type" ON ("auth_permission"."content_type_id" = "django_content_type"."id") WHERE "auths_user_user_permissions"."user_id" = '3651942c1384420da02bbf9e5eca3faa' ORDER BY "django_content_type"."app_label" ASC, "django_content_type"."model" ASC, "auth_permission"."codename" ASC; args=('3651942c1384420da02bbf9e5eca3faa',)
[2016-11-04 17:34:36] INFO [django.server:131] "GET /api/auths/localuserinfo/ HTTP/1.1" 200 496
[2016-11-04 17:34:36] DEBUG [django.db.backends:90] (0.001) SELECT (1) AS "a" FROM "django_session" WHERE "django_session"."session_key" = '19rtgwgw3breue865l501xvg3z3iqqtn' LIMIT 1; args=('19rtgwgw3breue865l501xvg3z3iqqtn',)
[2016-11-04 17:34:36] DEBUG [django.db.backends:90] (0.000) BEGIN; args=None
[2016-11-04 17:34:36] DEBUG [django.db.backends:90] (0.011) INSERT INTO "django_session" ("session_key", "session_data", "expire_date") SELECT '19rtgwgw3breue865l501xvg3z3iqqtn', 'NmE3M2Q3NmYwOTU3YjJmZDBjYmQxYTVjODc5MTExNzM3NjY1YzYzNzp7Il9zZXNzaW9uX2V4cGlyeSI6MzB9', '2016-11-04 22:35:06.533533'; args=('19rtgwgw3breue865l501xvg3z3iqqtn', 'NmE3M2Q3NmYwOTU3YjJmZDBjYmQxYTVjODc5MTExNzM3NjY1YzYzNzp7Il9zZXNzaW9uX2V4cGlyeSI6MzB9', '2016-11-04 22:35:06.533533')
[2016-11-04 17:34:36] INFO [django.server:131] "GET /api/auths/usermenu/ HTTP/1.1" 200 11
[2016-11-04 17:34:36] DEBUG [django.db.backends:90] (0.076) SELECT "oauth2_provider_accesstoken"."id", "oauth2_provider_accesstoken"."user_id", "oauth2_provider_accesstoken"."token", "oauth2_provider_accesstoken"."application_id", "oauth2_provider_accesstoken"."expires", "oauth2_provider_accesstoken"."scope", "auths_user"."password", "auths_user"."last_login", "auths_user"."is_superuser", "auths_user"."username", "auths_user"."first_name", "auths_user"."last_name", "auths_user"."email", "auths_user"."is_staff", "auths_user"."is_active", "auths_user"."date_joined", "auths_user"."id", "auths_user"."last_hierarchy_id", "auths_user"."last_module_id", "auths_user"."person_id", "auths_user"."updated_at", "auths_user"."registered_by", "oauth2_provider_application"."id", "oauth2_provider_application"."client_id", "oauth2_provider_application"."user_id", "oauth2_provider_application"."redirect_uris", "oauth2_provider_application"."client_type", "oauth2_provider_application"."authorization_grant_type", "oauth2_provider_application"."client_secret", "oauth2_provider_application"."name", "oauth2_provider_application"."skip_authorization" FROM "oauth2_provider_accesstoken" LEFT OUTER JOIN "auths_user" ON ("oauth2_provider_accesstoken"."user_id" = "auths_user"."id") INNER JOIN "oauth2_provider_application" ON ("oauth2_provider_accesstoken"."application_id" = "oauth2_provider_application"."id") WHERE "oauth2_provider_accesstoken"."token" = 'CqxqZcZN71EyXOvauC8JLnQjgmobZv'; args=('CqxqZcZN71EyXOvauC8JLnQjgmobZv',)
[2016-11-04 17:34:37] DEBUG [django.db.backends:90] (0.000) SELECT COUNT(*) AS "__count" FROM "catalogo_autor"; args=()
[2016-11-04 17:34:37] INFO [django.server:131] "GET /api/catalogo/autors/ HTTP/1.1" 200 124
[2016-11-04 17:34:49] DEBUG [django.db.backends:90] (0.006) SELECT "oauth2_provider_accesstoken"."id", "oauth2_provider_accesstoken"."user_id", "oauth2_provider_accesstoken"."token", "oauth2_provider_accesstoken"."application_id", "oauth2_provider_accesstoken"."expires", "oauth2_provider_accesstoken"."scope", "auths_user"."password", "auths_user"."last_login", "auths_user"."is_superuser", "auths_user"."username", "auths_user"."first_name", "auths_user"."last_name", "auths_user"."email", "auths_user"."is_staff", "auths_user"."is_active", "auths_user"."date_joined", "auths_user"."id", "auths_user"."last_hierarchy_id", "auths_user"."last_module_id", "auths_user"."person_id", "auths_user"."updated_at", "auths_user"."registered_by", "oauth2_provider_application"."id", "oauth2_provider_application"."client_id", "oauth2_provider_application"."user_id", "oauth2_provider_application"."redirect_uris", "oauth2_provider_application"."client_type", "oauth2_provider_application"."authorization_grant_type", "oauth2_provider_application"."client_secret", "oauth2_provider_application"."name", "oauth2_provider_application"."skip_authorization" FROM "oauth2_provider_accesstoken" LEFT OUTER JOIN "auths_user" ON ("oauth2_provider_accesstoken"."user_id" = "auths_user"."id") INNER JOIN "oauth2_provider_application" ON ("oauth2_provider_accesstoken"."application_id" = "oauth2_provider_application"."id") WHERE "oauth2_provider_accesstoken"."token" = 'CqxqZcZN71EyXOvauC8JLnQjgmobZv'; args=('CqxqZcZN71EyXOvauC8JLnQjgmobZv',)
[2016-11-04 17:34:49] DEBUG [django.db.backends:90] (0.001) SELECT "catalogo_categoria"."id", "catalogo_categoria"."nombre", "catalogo_categoria"."codigo", "catalogo_categoria"."estado" FROM "catalogo_categoria" WHERE ("catalogo_categoria"."codigo" LIKE '%%' ESCAPE '\' OR "catalogo_categoria"."nombre" LIKE '%%' ESCAPE '\'); args=('%%', '%%')
[2016-11-04 17:34:49] INFO [django.server:131] "GET /api/catalogo/categorias/ HTTP/1.1" 200 2
[2016-11-04 17:34:51] DEBUG [django.db.backends:90] (0.016) SELECT "oauth2_provider_accesstoken"."id", "oauth2_provider_accesstoken"."user_id", "oauth2_provider_accesstoken"."token", "oauth2_provider_accesstoken"."application_id", "oauth2_provider_accesstoken"."expires", "oauth2_provider_accesstoken"."scope", "auths_user"."password", "auths_user"."last_login", "auths_user"."is_superuser", "auths_user"."username", "auths_user"."first_name", "auths_user"."last_name", "auths_user"."email", "auths_user"."is_staff", "auths_user"."is_active", "auths_user"."date_joined", "auths_user"."id", "auths_user"."last_hierarchy_id", "auths_user"."last_module_id", "auths_user"."person_id", "auths_user"."updated_at", "auths_user"."registered_by", "oauth2_provider_application"."id", "oauth2_provider_application"."client_id", "oauth2_provider_application"."user_id", "oauth2_provider_application"."redirect_uris", "oauth2_provider_application"."client_type", "oauth2_provider_application"."authorization_grant_type", "oauth2_provider_application"."client_secret", "oauth2_provider_application"."name", "oauth2_provider_application"."skip_authorization" FROM "oauth2_provider_accesstoken" LEFT OUTER JOIN "auths_user" ON ("oauth2_provider_accesstoken"."user_id" = "auths_user"."id") INNER JOIN "oauth2_provider_application" ON ("oauth2_provider_accesstoken"."application_id" = "oauth2_provider_application"."id") WHERE "oauth2_provider_accesstoken"."token" = 'CqxqZcZN71EyXOvauC8JLnQjgmobZv'; args=('CqxqZcZN71EyXOvauC8JLnQjgmobZv',)
[2016-11-04 17:34:52] DEBUG [django.db.backends:90] (0.001) SELECT COUNT(*) AS "__count" FROM "catalogo_autor"; args=()
[2016-11-04 17:34:52] INFO [django.server:131] "GET /api/catalogo/autors/ HTTP/1.1" 200 124
[2016-11-04 17:39:29] DEBUG [django.db.backends:90] (0.003) SELECT "oauth2_provider_accesstoken"."id", "oauth2_provider_accesstoken"."user_id", "oauth2_provider_accesstoken"."token", "oauth2_provider_accesstoken"."application_id", "oauth2_provider_accesstoken"."expires", "oauth2_provider_accesstoken"."scope", "auths_user"."password", "auths_user"."last_login", "auths_user"."is_superuser", "auths_user"."username", "auths_user"."first_name", "auths_user"."last_name", "auths_user"."email", "auths_user"."is_staff", "auths_user"."is_active", "auths_user"."date_joined", "auths_user"."id", "auths_user"."last_hierarchy_id", "auths_user"."last_module_id", "auths_user"."person_id", "auths_user"."updated_at", "auths_user"."registered_by", "oauth2_provider_application"."id", "oauth2_provider_application"."client_id", "oauth2_provider_application"."user_id", "oauth2_provider_application"."redirect_uris", "oauth2_provider_application"."client_type", "oauth2_provider_application"."authorization_grant_type", "oauth2_provider_application"."client_secret", "oauth2_provider_application"."name", "oauth2_provider_application"."skip_authorization" FROM "oauth2_provider_accesstoken" LEFT OUTER JOIN "auths_user" ON ("oauth2_provider_accesstoken"."user_id" = "auths_user"."id") INNER JOIN "oauth2_provider_application" ON ("oauth2_provider_accesstoken"."application_id" = "oauth2_provider_application"."id") WHERE "oauth2_provider_accesstoken"."token" = 'CqxqZcZN71EyXOvauC8JLnQjgmobZv'; args=('CqxqZcZN71EyXOvauC8JLnQjgmobZv',)
[2016-11-04 17:39:29] DEBUG [django.db.backends:90] (0.003) SELECT "oauth2_provider_accesstoken"."id", "oauth2_provider_accesstoken"."user_id", "oauth2_provider_accesstoken"."token", "oauth2_provider_accesstoken"."application_id", "oauth2_provider_accesstoken"."expires", "oauth2_provider_accesstoken"."scope", "auths_user"."password", "auths_user"."last_login", "auths_user"."is_superuser", "auths_user"."username", "auths_user"."first_name", "auths_user"."last_name", "auths_user"."email", "auths_user"."is_staff", "auths_user"."is_active", "auths_user"."date_joined", "auths_user"."id", "auths_user"."last_hierarchy_id", "auths_user"."last_module_id", "auths_user"."person_id", "auths_user"."updated_at", "auths_user"."registered_by", "oauth2_provider_application"."id", "oauth2_provider_application"."client_id", "oauth2_provider_application"."user_id", "oauth2_provider_application"."redirect_uris", "oauth2_provider_application"."client_type", "oauth2_provider_application"."authorization_grant_type", "oauth2_provider_application"."client_secret", "oauth2_provider_application"."name", "oauth2_provider_application"."skip_authorization" FROM "oauth2_provider_accesstoken" LEFT OUTER JOIN "auths_user" ON ("oauth2_provider_accesstoken"."user_id" = "auths_user"."id") INNER JOIN "oauth2_provider_application" ON ("oauth2_provider_accesstoken"."application_id" = "oauth2_provider_application"."id") WHERE "oauth2_provider_accesstoken"."token" = 'CqxqZcZN71EyXOvauC8JLnQjgmobZv'; args=('CqxqZcZN71EyXOvauC8JLnQjgmobZv',)
[2016-11-04 17:39:29] DEBUG [django.db.backends:90] (0.000) SELECT "auths_menu"."id" FROM "auths_menu" WHERE ("auths_menu"."id" IS NOT NULL AND "auths_menu"."is_active" = 1 AND "auths_menu"."module" = 'BACKEND') ORDER BY "auths_menu"."pos" ASC; args=(True, 'BACKEND')
[2016-11-04 17:39:29] DEBUG [django.db.backends:90] (0.002) SELECT (1) AS "a" FROM "django_session" WHERE "django_session"."session_key" = 'jgc7xdqznu3v7svlm89zaaog6n5wn9o4' LIMIT 1; args=('jgc7xdqznu3v7svlm89zaaog6n5wn9o4',)
[2016-11-04 17:39:29] DEBUG [django.db.backends:90] (0.000) BEGIN; args=None
[2016-11-04 17:39:29] DEBUG [django.db.backends:90] (0.000) SELECT "auth_group"."id", "auth_group"."name" FROM "auth_group" INNER JOIN "auths_user_groups" ON ("auth_group"."id" = "auths_user_groups"."group_id") WHERE "auths_user_groups"."user_id" = '3651942c1384420da02bbf9e5eca3faa'; args=('3651942c1384420da02bbf9e5eca3faa',)
[2016-11-04 17:39:29] DEBUG [django.db.backends:90] (0.000) SELECT "auth_permission"."id", "auth_permission"."name", "auth_permission"."content_type_id", "auth_permission"."codename" FROM "auth_permission" INNER JOIN "auths_user_user_permissions" ON ("auth_permission"."id" = "auths_user_user_permissions"."permission_id") INNER JOIN "django_content_type" ON ("auth_permission"."content_type_id" = "django_content_type"."id") WHERE "auths_user_user_permissions"."user_id" = '3651942c1384420da02bbf9e5eca3faa' ORDER BY "django_content_type"."app_label" ASC, "django_content_type"."model" ASC, "auth_permission"."codename" ASC; args=('3651942c1384420da02bbf9e5eca3faa',)
[2016-11-04 17:39:29] INFO [django.server:131] "GET /api/auths/localuserinfo/ HTTP/1.1" 200 496
[2016-11-04 17:39:29] DEBUG [django.db.backends:90] (0.045) INSERT INTO "django_session" ("session_key", "session_data", "expire_date") SELECT 'jgc7xdqznu3v7svlm89zaaog6n5wn9o4', 'NmE3M2Q3NmYwOTU3YjJmZDBjYmQxYTVjODc5MTExNzM3NjY1YzYzNzp7Il9zZXNzaW9uX2V4cGlyeSI6MzB9', '2016-11-04 22:39:59.293752'; args=('jgc7xdqznu3v7svlm89zaaog6n5wn9o4', 'NmE3M2Q3NmYwOTU3YjJmZDBjYmQxYTVjODc5MTExNzM3NjY1YzYzNzp7Il9zZXNzaW9uX2V4cGlyeSI6MzB9', '2016-11-04 22:39:59.293752')
[2016-11-04 17:39:29] INFO [django.server:131] "GET /api/auths/usermenu/ HTTP/1.1" 200 11
[2016-11-04 17:39:29] DEBUG [django.db.backends:90] (0.006) SELECT "oauth2_provider_accesstoken"."id", "oauth2_provider_accesstoken"."user_id", "oauth2_provider_accesstoken"."token", "oauth2_provider_accesstoken"."application_id", "oauth2_provider_accesstoken"."expires", "oauth2_provider_accesstoken"."scope", "auths_user"."password", "auths_user"."last_login", "auths_user"."is_superuser", "auths_user"."username", "auths_user"."first_name", "auths_user"."last_name", "auths_user"."email", "auths_user"."is_staff", "auths_user"."is_active", "auths_user"."date_joined", "auths_user"."id", "auths_user"."last_hierarchy_id", "auths_user"."last_module_id", "auths_user"."person_id", "auths_user"."updated_at", "auths_user"."registered_by", "oauth2_provider_application"."id", "oauth2_provider_application"."client_id", "oauth2_provider_application"."user_id", "oauth2_provider_application"."redirect_uris", "oauth2_provider_application"."client_type", "oauth2_provider_application"."authorization_grant_type", "oauth2_provider_application"."client_secret", "oauth2_provider_application"."name", "oauth2_provider_application"."skip_authorization" FROM "oauth2_provider_accesstoken" LEFT OUTER JOIN "auths_user" ON ("oauth2_provider_accesstoken"."user_id" = "auths_user"."id") INNER JOIN "oauth2_provider_application" ON ("oauth2_provider_accesstoken"."application_id" = "oauth2_provider_application"."id") WHERE "oauth2_provider_accesstoken"."token" = 'CqxqZcZN71EyXOvauC8JLnQjgmobZv'; args=('CqxqZcZN71EyXOvauC8JLnQjgmobZv',)
[2016-11-04 17:39:29] DEBUG [django.db.backends:90] (0.000) SELECT COUNT(*) AS "__count" FROM "catalogo_autor"; args=()
[2016-11-04 17:39:29] INFO [django.server:131] "GET /api/catalogo/autors/ HTTP/1.1" 200 124
[2016-11-04 17:39:36] DEBUG [django.db.backends:90] (0.003) SELECT "oauth2_provider_accesstoken"."id", "oauth2_provider_accesstoken"."user_id", "oauth2_provider_accesstoken"."token", "oauth2_provider_accesstoken"."application_id", "oauth2_provider_accesstoken"."expires", "oauth2_provider_accesstoken"."scope", "auths_user"."password", "auths_user"."last_login", "auths_user"."is_superuser", "auths_user"."username", "auths_user"."first_name", "auths_user"."last_name", "auths_user"."email", "auths_user"."is_staff", "auths_user"."is_active", "auths_user"."date_joined", "auths_user"."id", "auths_user"."last_hierarchy_id", "auths_user"."last_module_id", "auths_user"."person_id", "auths_user"."updated_at", "auths_user"."registered_by", "oauth2_provider_application"."id", "oauth2_provider_application"."client_id", "oauth2_provider_application"."user_id", "oauth2_provider_application"."redirect_uris", "oauth2_provider_application"."client_type", "oauth2_provider_application"."authorization_grant_type", "oauth2_provider_application"."client_secret", "oauth2_provider_application"."name", "oauth2_provider_application"."skip_authorization" FROM "oauth2_provider_accesstoken" LEFT OUTER JOIN "auths_user" ON ("oauth2_provider_accesstoken"."user_id" = "auths_user"."id") INNER JOIN "oauth2_provider_application" ON ("oauth2_provider_accesstoken"."application_id" = "oauth2_provider_application"."id") WHERE "oauth2_provider_accesstoken"."token" = 'CqxqZcZN71EyXOvauC8JLnQjgmobZv'; args=('CqxqZcZN71EyXOvauC8JLnQjgmobZv',)
[2016-11-04 17:39:36] DEBUG [django.db.backends:90] (0.000) SELECT "catalogo_categoria"."id", "catalogo_categoria"."nombre", "catalogo_categoria"."codigo", "catalogo_categoria"."estado" FROM "catalogo_categoria" WHERE ("catalogo_categoria"."codigo" LIKE '%%' ESCAPE '\' OR "catalogo_categoria"."nombre" LIKE '%%' ESCAPE '\'); args=('%%', '%%')
[2016-11-04 17:39:36] INFO [django.server:131] "GET /api/catalogo/categorias/ HTTP/1.1" 200 2
[2016-11-04 17:42:29] DEBUG [django.db.backends:90] (0.003) SELECT "oauth2_provider_accesstoken"."id", "oauth2_provider_accesstoken"."user_id", "oauth2_provider_accesstoken"."token", "oauth2_provider_accesstoken"."application_id", "oauth2_provider_accesstoken"."expires", "oauth2_provider_accesstoken"."scope", "auths_user"."password", "auths_user"."last_login", "auths_user"."is_superuser", "auths_user"."username", "auths_user"."first_name", "auths_user"."last_name", "auths_user"."email", "auths_user"."is_staff", "auths_user"."is_active", "auths_user"."date_joined", "auths_user"."id", "auths_user"."last_hierarchy_id", "auths_user"."last_module_id", "auths_user"."person_id", "auths_user"."updated_at", "auths_user"."registered_by", "oauth2_provider_application"."id", "oauth2_provider_application"."client_id", "oauth2_provider_application"."user_id", "oauth2_provider_application"."redirect_uris", "oauth2_provider_application"."client_type", "oauth2_provider_application"."authorization_grant_type", "oauth2_provider_application"."client_secret", "oauth2_provider_application"."name", "oauth2_provider_application"."skip_authorization" FROM "oauth2_provider_accesstoken" LEFT OUTER JOIN "auths_user" ON ("oauth2_provider_accesstoken"."user_id" = "auths_user"."id") INNER JOIN "oauth2_provider_application" ON ("oauth2_provider_accesstoken"."application_id" = "oauth2_provider_application"."id") WHERE "oauth2_provider_accesstoken"."token" = 'CqxqZcZN71EyXOvauC8JLnQjgmobZv'; args=('CqxqZcZN71EyXOvauC8JLnQjgmobZv',)
[2016-11-04 17:42:29] DEBUG [django.db.backends:90] (0.003) SELECT "oauth2_provider_accesstoken"."id", "oauth2_provider_accesstoken"."user_id", "oauth2_provider_accesstoken"."token", "oauth2_provider_accesstoken"."application_id", "oauth2_provider_accesstoken"."expires", "oauth2_provider_accesstoken"."scope", "auths_user"."password", "auths_user"."last_login", "auths_user"."is_superuser", "auths_user"."username", "auths_user"."first_name", "auths_user"."last_name", "auths_user"."email", "auths_user"."is_staff", "auths_user"."is_active", "auths_user"."date_joined", "auths_user"."id", "auths_user"."last_hierarchy_id", "auths_user"."last_module_id", "auths_user"."person_id", "auths_user"."updated_at", "auths_user"."registered_by", "oauth2_provider_application"."id", "oauth2_provider_application"."client_id", "oauth2_provider_application"."user_id", "oauth2_provider_application"."redirect_uris", "oauth2_provider_application"."client_type", "oauth2_provider_application"."authorization_grant_type", "oauth2_provider_application"."client_secret", "oauth2_provider_application"."name", "oauth2_provider_application"."skip_authorization" FROM "oauth2_provider_accesstoken" LEFT OUTER JOIN "auths_user" ON ("oauth2_provider_accesstoken"."user_id" = "auths_user"."id") INNER JOIN "oauth2_provider_application" ON ("oauth2_provider_accesstoken"."application_id" = "oauth2_provider_application"."id") WHERE "oauth2_provider_accesstoken"."token" = 'CqxqZcZN71EyXOvauC8JLnQjgmobZv'; args=('CqxqZcZN71EyXOvauC8JLnQjgmobZv',)
[2016-11-04 17:42:29] DEBUG [django.db.backends:90] (0.000) SELECT "auths_menu"."id" FROM "auths_menu" WHERE ("auths_menu"."id" IS NOT NULL AND "auths_menu"."is_active" = 1 AND "auths_menu"."module" = 'BACKEND') ORDER BY "auths_menu"."pos" ASC; args=(True, 'BACKEND')
[2016-11-04 17:42:29] DEBUG [django.db.backends:90] (0.001) SELECT (1) AS "a" FROM "django_session" WHERE "django_session"."session_key" = 'kmt8jyypavkexe0ddhiktuwi1mozc2os' LIMIT 1; args=('kmt8jyypavkexe0ddhiktuwi1mozc2os',)
[2016-11-04 17:42:29] DEBUG [django.db.backends:90] (0.000) BEGIN; args=None
[2016-11-04 17:42:29] DEBUG [django.db.backends:90] (0.008) INSERT INTO "django_session" ("session_key", "session_data", "expire_date") SELECT 'kmt8jyypavkexe0ddhiktuwi1mozc2os', 'NmE3M2Q3NmYwOTU3YjJmZDBjYmQxYTVjODc5MTExNzM3NjY1YzYzNzp7Il9zZXNzaW9uX2V4cGlyeSI6MzB9', '2016-11-04 22:42:59.433190'; args=('kmt8jyypavkexe0ddhiktuwi1mozc2os', 'NmE3M2Q3NmYwOTU3YjJmZDBjYmQxYTVjODc5MTExNzM3NjY1YzYzNzp7Il9zZXNzaW9uX2V4cGlyeSI6MzB9', '2016-11-04 22:42:59.433190')
[2016-11-04 17:42:29] DEBUG [django.db.backends:90] (0.066) SELECT "auth_group"."id", "auth_group"."name" FROM "auth_group" INNER JOIN "auths_user_groups" ON ("auth_group"."id" = "auths_user_groups"."group_id") WHERE "auths_user_groups"."user_id" = '3651942c1384420da02bbf9e5eca3faa'; args=('3651942c1384420da02bbf9e5eca3faa',)
[2016-11-04 17:42:29] DEBUG [django.db.backends:90] (0.001) SELECT "auth_permission"."id", "auth_permission"."name", "auth_permission"."content_type_id", "auth_permission"."codename" FROM "auth_permission" INNER JOIN "auths_user_user_permissions" ON ("auth_permission"."id" = "auths_user_user_permissions"."permission_id") INNER JOIN "django_content_type" ON ("auth_permission"."content_type_id" = "django_content_type"."id") WHERE "auths_user_user_permissions"."user_id" = '3651942c1384420da02bbf9e5eca3faa' ORDER BY "django_content_type"."app_label" ASC, "django_content_type"."model" ASC, "auth_permission"."codename" ASC; args=('3651942c1384420da02bbf9e5eca3faa',)
[2016-11-04 17:42:29] INFO [django.server:131] "GET /api/auths/localuserinfo/ HTTP/1.1" 200 496
[2016-11-04 17:42:29] INFO [django.server:131] "GET /api/auths/usermenu/ HTTP/1.1" 200 11
[2016-11-04 17:42:29] DEBUG [django.db.backends:90] (0.007) SELECT "oauth2_provider_accesstoken"."id", "oauth2_provider_accesstoken"."user_id", "oauth2_provider_accesstoken"."token", "oauth2_provider_accesstoken"."application_id", "oauth2_provider_accesstoken"."expires", "oauth2_provider_accesstoken"."scope", "auths_user"."password", "auths_user"."last_login", "auths_user"."is_superuser", "auths_user"."username", "auths_user"."first_name", "auths_user"."last_name", "auths_user"."email", "auths_user"."is_staff", "auths_user"."is_active", "auths_user"."date_joined", "auths_user"."id", "auths_user"."last_hierarchy_id", "auths_user"."last_module_id", "auths_user"."person_id", "auths_user"."updated_at", "auths_user"."registered_by", "oauth2_provider_application"."id", "oauth2_provider_application"."client_id", "oauth2_provider_application"."user_id", "oauth2_provider_application"."redirect_uris", "oauth2_provider_application"."client_type", "oauth2_provider_application"."authorization_grant_type", "oauth2_provider_application"."client_secret", "oauth2_provider_application"."name", "oauth2_provider_application"."skip_authorization" FROM "oauth2_provider_accesstoken" LEFT OUTER JOIN "auths_user" ON ("oauth2_provider_accesstoken"."user_id" = "auths_user"."id") INNER JOIN "oauth2_provider_application" ON ("oauth2_provider_accesstoken"."application_id" = "oauth2_provider_application"."id") WHERE "oauth2_provider_accesstoken"."token" = 'CqxqZcZN71EyXOvauC8JLnQjgmobZv'; args=('CqxqZcZN71EyXOvauC8JLnQjgmobZv',)
[2016-11-04 17:42:29] DEBUG [django.db.backends:90] (0.001) SELECT "catalogo_categoria"."id", "catalogo_categoria"."nombre", "catalogo_categoria"."codigo", "catalogo_categoria"."estado" FROM "catalogo_categoria" WHERE ("catalogo_categoria"."codigo" LIKE '%%' ESCAPE '\' OR "catalogo_categoria"."nombre" LIKE '%%' ESCAPE '\'); args=('%%', '%%')
[2016-11-04 17:42:29] INFO [django.server:131] "GET /api/catalogo/categorias/ HTTP/1.1" 200 2
[2016-11-04 17:44:28] DEBUG [django.db.backends:90] (0.003) 
            SELECT name, type FROM sqlite_master
            WHERE type in ('table', 'view') AND NOT name='sqlite_sequence'
            ORDER BY name; args=None
[2016-11-04 17:44:28] DEBUG [django.db.backends:90] (0.001) SELECT "django_migrations"."app", "django_migrations"."name" FROM "django_migrations"; args=()
[2016-11-04 17:44:29] INFO [django.server:131] "OPTIONS /api/catalogo/categorias/ HTTP/1.1" 200 0
[2016-11-04 17:44:29] INFO [django.server:131] "OPTIONS /api/auths/localuserinfo/ HTTP/1.1" 200 0
[2016-11-04 17:44:29] INFO [django.server:131] "OPTIONS /api/auths/usermenu/ HTTP/1.1" 200 0
[2016-11-04 17:44:29] DEBUG [django.db.backends:90] (0.005) SELECT "oauth2_provider_accesstoken"."id", "oauth2_provider_accesstoken"."user_id", "oauth2_provider_accesstoken"."token", "oauth2_provider_accesstoken"."application_id", "oauth2_provider_accesstoken"."expires", "oauth2_provider_accesstoken"."scope", "auths_user"."password", "auths_user"."last_login", "auths_user"."is_superuser", "auths_user"."username", "auths_user"."first_name", "auths_user"."last_name", "auths_user"."email", "auths_user"."is_staff", "auths_user"."is_active", "auths_user"."date_joined", "auths_user"."id", "auths_user"."last_hierarchy_id", "auths_user"."last_module_id", "auths_user"."person_id", "auths_user"."updated_at", "auths_user"."registered_by", "oauth2_provider_application"."id", "oauth2_provider_application"."client_id", "oauth2_provider_application"."user_id", "oauth2_provider_application"."redirect_uris", "oauth2_provider_application"."client_type", "oauth2_provider_application"."authorization_grant_type", "oauth2_provider_application"."client_secret", "oauth2_provider_application"."name", "oauth2_provider_application"."skip_authorization" FROM "oauth2_provider_accesstoken" LEFT OUTER JOIN "auths_user" ON ("oauth2_provider_accesstoken"."user_id" = "auths_user"."id") INNER JOIN "oauth2_provider_application" ON ("oauth2_provider_accesstoken"."application_id" = "oauth2_provider_application"."id") WHERE "oauth2_provider_accesstoken"."token" = 'CqxqZcZN71EyXOvauC8JLnQjgmobZv'; args=('CqxqZcZN71EyXOvauC8JLnQjgmobZv',)
[2016-11-04 17:44:29] DEBUG [django.db.backends:90] (0.001) SELECT "catalogo_categoria"."id", "catalogo_categoria"."nombre", "catalogo_categoria"."codigo", "catalogo_categoria"."estado" FROM "catalogo_categoria" WHERE ("catalogo_categoria"."codigo" LIKE '%%' ESCAPE '\' OR "catalogo_categoria"."nombre" LIKE '%%' ESCAPE '\'); args=('%%', '%%')
[2016-11-04 17:44:29] INFO [django.server:131] "GET /api/catalogo/categorias/ HTTP/1.1" 200 2
[2016-11-04 17:44:29] DEBUG [django.db.backends:90] (0.004) SELECT "oauth2_provider_accesstoken"."id", "oauth2_provider_accesstoken"."user_id", "oauth2_provider_accesstoken"."token", "oauth2_provider_accesstoken"."application_id", "oauth2_provider_accesstoken"."expires", "oauth2_provider_accesstoken"."scope", "auths_user"."password", "auths_user"."last_login", "auths_user"."is_superuser", "auths_user"."username", "auths_user"."first_name", "auths_user"."last_name", "auths_user"."email", "auths_user"."is_staff", "auths_user"."is_active", "auths_user"."date_joined", "auths_user"."id", "auths_user"."last_hierarchy_id", "auths_user"."last_module_id", "auths_user"."person_id", "auths_user"."updated_at", "auths_user"."registered_by", "oauth2_provider_application"."id", "oauth2_provider_application"."client_id", "oauth2_provider_application"."user_id", "oauth2_provider_application"."redirect_uris", "oauth2_provider_application"."client_type", "oauth2_provider_application"."authorization_grant_type", "oauth2_provider_application"."client_secret", "oauth2_provider_application"."name", "oauth2_provider_application"."skip_authorization" FROM "oauth2_provider_accesstoken" LEFT OUTER JOIN "auths_user" ON ("oauth2_provider_accesstoken"."user_id" = "auths_user"."id") INNER JOIN "oauth2_provider_application" ON ("oauth2_provider_accesstoken"."application_id" = "oauth2_provider_application"."id") WHERE "oauth2_provider_accesstoken"."token" = 'CqxqZcZN71EyXOvauC8JLnQjgmobZv'; args=('CqxqZcZN71EyXOvauC8JLnQjgmobZv',)
[2016-11-04 17:44:29] DEBUG [django.db.backends:90] (0.000) SELECT "auth_group"."id", "auth_group"."name" FROM "auth_group" INNER JOIN "auths_user_groups" ON ("auth_group"."id" = "auths_user_groups"."group_id") WHERE "auths_user_groups"."user_id" = '3651942c1384420da02bbf9e5eca3faa'; args=('3651942c1384420da02bbf9e5eca3faa',)
[2016-11-04 17:44:29] DEBUG [django.db.backends:90] (0.001) SELECT "auth_permission"."id", "auth_permission"."name", "auth_permission"."content_type_id", "auth_permission"."codename" FROM "auth_permission" INNER JOIN "auths_user_user_permissions" ON ("auth_permission"."id" = "auths_user_user_permissions"."permission_id") INNER JOIN "django_content_type" ON ("auth_permission"."content_type_id" = "django_content_type"."id") WHERE "auths_user_user_permissions"."user_id" = '3651942c1384420da02bbf9e5eca3faa' ORDER BY "django_content_type"."app_label" ASC, "django_content_type"."model" ASC, "auth_permission"."codename" ASC; args=('3651942c1384420da02bbf9e5eca3faa',)
[2016-11-04 17:44:29] INFO [django.server:131] "GET /api/auths/localuserinfo/ HTTP/1.1" 200 496
[2016-11-04 17:44:29] DEBUG [django.db.backends:90] (0.004) SELECT "oauth2_provider_accesstoken"."id", "oauth2_provider_accesstoken"."user_id", "oauth2_provider_accesstoken"."token", "oauth2_provider_accesstoken"."application_id", "oauth2_provider_accesstoken"."expires", "oauth2_provider_accesstoken"."scope", "auths_user"."password", "auths_user"."last_login", "auths_user"."is_superuser", "auths_user"."username", "auths_user"."first_name", "auths_user"."last_name", "auths_user"."email", "auths_user"."is_staff", "auths_user"."is_active", "auths_user"."date_joined", "auths_user"."id", "auths_user"."last_hierarchy_id", "auths_user"."last_module_id", "auths_user"."person_id", "auths_user"."updated_at", "auths_user"."registered_by", "oauth2_provider_application"."id", "oauth2_provider_application"."client_id", "oauth2_provider_application"."user_id", "oauth2_provider_application"."redirect_uris", "oauth2_provider_application"."client_type", "oauth2_provider_application"."authorization_grant_type", "oauth2_provider_application"."client_secret", "oauth2_provider_application"."name", "oauth2_provider_application"."skip_authorization" FROM "oauth2_provider_accesstoken" LEFT OUTER JOIN "auths_user" ON ("oauth2_provider_accesstoken"."user_id" = "auths_user"."id") INNER JOIN "oauth2_provider_application" ON ("oauth2_provider_accesstoken"."application_id" = "oauth2_provider_application"."id") WHERE "oauth2_provider_accesstoken"."token" = 'CqxqZcZN71EyXOvauC8JLnQjgmobZv'; args=('CqxqZcZN71EyXOvauC8JLnQjgmobZv',)
[2016-11-04 17:44:29] DEBUG [django.db.backends:90] (0.000) SELECT "auths_menu"."id" FROM "auths_menu" WHERE ("auths_menu"."id" IS NOT NULL AND "auths_menu"."module" = 'BACKEND' AND "auths_menu"."is_active" = 1) ORDER BY "auths_menu"."pos" ASC; args=('BACKEND', True)
[2016-11-04 17:44:29] DEBUG [django.db.backends:90] (0.001) SELECT (1) AS "a" FROM "django_session" WHERE "django_session"."session_key" = 'c2xyxk0krowu3ex5eqhn7ofkjcofepio' LIMIT 1; args=('c2xyxk0krowu3ex5eqhn7ofkjcofepio',)
[2016-11-04 17:44:29] DEBUG [django.db.backends:90] (0.000) BEGIN; args=None
[2016-11-04 17:44:29] DEBUG [django.db.backends:90] (0.024) INSERT INTO "django_session" ("session_key", "session_data", "expire_date") SELECT 'c2xyxk0krowu3ex5eqhn7ofkjcofepio', 'NmE3M2Q3NmYwOTU3YjJmZDBjYmQxYTVjODc5MTExNzM3NjY1YzYzNzp7Il9zZXNzaW9uX2V4cGlyeSI6MzB9', '2016-11-04 22:44:59.870517'; args=('c2xyxk0krowu3ex5eqhn7ofkjcofepio', 'NmE3M2Q3NmYwOTU3YjJmZDBjYmQxYTVjODc5MTExNzM3NjY1YzYzNzp7Il9zZXNzaW9uX2V4cGlyeSI6MzB9', '2016-11-04 22:44:59.870517')
[2016-11-04 17:44:30] INFO [django.server:131] "GET /api/auths/usermenu/ HTTP/1.1" 200 11
[2016-11-04 18:14:44] DEBUG [django.db.backends:90] (0.004) 
            SELECT name, type FROM sqlite_master
            WHERE type in ('table', 'view') AND NOT name='sqlite_sequence'
            ORDER BY name; args=None
[2016-11-04 18:14:44] DEBUG [django.db.backends:90] (0.004) SELECT "django_migrations"."app", "django_migrations"."name" FROM "django_migrations"; args=()
[2016-11-04 18:15:24] INFO [django.server:131] "OPTIONS /api/auths/localuserinfo/ HTTP/1.1" 200 0
[2016-11-04 18:15:24] INFO [django.server:131] "OPTIONS /api/auths/usermenu/ HTTP/1.1" 200 0
[2016-11-04 18:15:24] DEBUG [django.db.backends:90] (0.004) SELECT "oauth2_provider_accesstoken"."id", "oauth2_provider_accesstoken"."user_id", "oauth2_provider_accesstoken"."token", "oauth2_provider_accesstoken"."application_id", "oauth2_provider_accesstoken"."expires", "oauth2_provider_accesstoken"."scope", "auths_user"."password", "auths_user"."last_login", "auths_user"."is_superuser", "auths_user"."username", "auths_user"."first_name", "auths_user"."last_name", "auths_user"."email", "auths_user"."is_staff", "auths_user"."is_active", "auths_user"."date_joined", "auths_user"."id", "auths_user"."last_hierarchy_id", "auths_user"."last_module_id", "auths_user"."person_id", "auths_user"."updated_at", "auths_user"."registered_by", "oauth2_provider_application"."id", "oauth2_provider_application"."client_id", "oauth2_provider_application"."user_id", "oauth2_provider_application"."redirect_uris", "oauth2_provider_application"."client_type", "oauth2_provider_application"."authorization_grant_type", "oauth2_provider_application"."client_secret", "oauth2_provider_application"."name", "oauth2_provider_application"."skip_authorization" FROM "oauth2_provider_accesstoken" LEFT OUTER JOIN "auths_user" ON ("oauth2_provider_accesstoken"."user_id" = "auths_user"."id") INNER JOIN "oauth2_provider_application" ON ("oauth2_provider_accesstoken"."application_id" = "oauth2_provider_application"."id") WHERE "oauth2_provider_accesstoken"."token" = 'CqxqZcZN71EyXOvauC8JLnQjgmobZv'; args=('CqxqZcZN71EyXOvauC8JLnQjgmobZv',)
[2016-11-04 18:15:24] DEBUG [django.db.backends:90] (0.003) SELECT "oauth2_provider_accesstoken"."id", "oauth2_provider_accesstoken"."user_id", "oauth2_provider_accesstoken"."token", "oauth2_provider_accesstoken"."application_id", "oauth2_provider_accesstoken"."expires", "oauth2_provider_accesstoken"."scope", "auths_user"."password", "auths_user"."last_login", "auths_user"."is_superuser", "auths_user"."username", "auths_user"."first_name", "auths_user"."last_name", "auths_user"."email", "auths_user"."is_staff", "auths_user"."is_active", "auths_user"."date_joined", "auths_user"."id", "auths_user"."last_hierarchy_id", "auths_user"."last_module_id", "auths_user"."person_id", "auths_user"."updated_at", "auths_user"."registered_by", "oauth2_provider_application"."id", "oauth2_provider_application"."client_id", "oauth2_provider_application"."user_id", "oauth2_provider_application"."redirect_uris", "oauth2_provider_application"."client_type", "oauth2_provider_application"."authorization_grant_type", "oauth2_provider_application"."client_secret", "oauth2_provider_application"."name", "oauth2_provider_application"."skip_authorization" FROM "oauth2_provider_accesstoken" LEFT OUTER JOIN "auths_user" ON ("oauth2_provider_accesstoken"."user_id" = "auths_user"."id") INNER JOIN "oauth2_provider_application" ON ("oauth2_provider_accesstoken"."application_id" = "oauth2_provider_application"."id") WHERE "oauth2_provider_accesstoken"."token" = 'CqxqZcZN71EyXOvauC8JLnQjgmobZv'; args=('CqxqZcZN71EyXOvauC8JLnQjgmobZv',)
[2016-11-04 18:15:24] DEBUG [django.db.backends:90] (0.000) SELECT "auth_group"."id", "auth_group"."name" FROM "auth_group" INNER JOIN "auths_user_groups" ON ("auth_group"."id" = "auths_user_groups"."group_id") WHERE "auths_user_groups"."user_id" = '3651942c1384420da02bbf9e5eca3faa'; args=('3651942c1384420da02bbf9e5eca3faa',)
[2016-11-04 18:15:24] DEBUG [django.db.backends:90] (0.000) SELECT "auth_permission"."id", "auth_permission"."name", "auth_permission"."content_type_id", "auth_permission"."codename" FROM "auth_permission" INNER JOIN "auths_user_user_permissions" ON ("auth_permission"."id" = "auths_user_user_permissions"."permission_id") INNER JOIN "django_content_type" ON ("auth_permission"."content_type_id" = "django_content_type"."id") WHERE "auths_user_user_permissions"."user_id" = '3651942c1384420da02bbf9e5eca3faa' ORDER BY "django_content_type"."app_label" ASC, "django_content_type"."model" ASC, "auth_permission"."codename" ASC; args=('3651942c1384420da02bbf9e5eca3faa',)
[2016-11-04 18:15:24] INFO [django.server:131] "GET /api/auths/localuserinfo/ HTTP/1.1" 200 496
[2016-11-04 18:15:24] DEBUG [django.db.backends:90] (0.001) SELECT "auths_menu"."id" FROM "auths_menu" WHERE ("auths_menu"."id" IS NOT NULL AND "auths_menu"."is_active" = 1 AND "auths_menu"."module" = 'BACKEND') ORDER BY "auths_menu"."pos" ASC; args=(True, 'BACKEND')
[2016-11-04 18:15:24] DEBUG [django.db.backends:90] (0.000) SELECT (1) AS "a" FROM "django_session" WHERE "django_session"."session_key" = 'wcrzhxcrv91jje5q22p146vl6vel55rk' LIMIT 1; args=('wcrzhxcrv91jje5q22p146vl6vel55rk',)
[2016-11-04 18:15:24] DEBUG [django.db.backends:90] (0.000) BEGIN; args=None
[2016-11-04 18:15:24] DEBUG [django.db.backends:90] (0.001) INSERT INTO "django_session" ("session_key", "session_data", "expire_date") SELECT 'wcrzhxcrv91jje5q22p146vl6vel55rk', 'NmE3M2Q3NmYwOTU3YjJmZDBjYmQxYTVjODc5MTExNzM3NjY1YzYzNzp7Il9zZXNzaW9uX2V4cGlyeSI6MzB9', '2016-11-04 23:15:54.790873'; args=('wcrzhxcrv91jje5q22p146vl6vel55rk', 'NmE3M2Q3NmYwOTU3YjJmZDBjYmQxYTVjODc5MTExNzM3NjY1YzYzNzp7Il9zZXNzaW9uX2V4cGlyeSI6MzB9', '2016-11-04 23:15:54.790873')
[2016-11-04 18:15:24] INFO [django.server:131] "GET /api/auths/usermenu/ HTTP/1.1" 200 11
[2016-11-04 18:16:01] DEBUG [django.db.backends:90] (0.003) SELECT "django_session"."session_key", "django_session"."session_data", "django_session"."expire_date" FROM "django_session" WHERE ("django_session"."session_key" = '4w7mksqqsrmucukumcpvs4jbtn8vd4qw' AND "django_session"."expire_date" > '2016-11-04 23:16:01.147216'); args=('4w7mksqqsrmucukumcpvs4jbtn8vd4qw', '2016-11-04 23:16:01.147216')
[2016-11-04 18:16:01] DEBUG [django.db.backends:90] (0.001) SELECT "auths_user"."password", "auths_user"."last_login", "auths_user"."is_superuser", "auths_user"."username", "auths_user"."first_name", "auths_user"."last_name", "auths_user"."email", "auths_user"."is_staff", "auths_user"."is_active", "auths_user"."date_joined", "auths_user"."id", "auths_user"."last_hierarchy_id", "auths_user"."last_module_id", "auths_user"."person_id", "auths_user"."updated_at", "auths_user"."registered_by" FROM "auths_user" WHERE "auths_user"."id" = '3651942c1384420da02bbf9e5eca3faa'; args=('3651942c1384420da02bbf9e5eca3faa',)
[2016-11-04 18:16:01] DEBUG [django.template:929] Exception while resolving variable 'is_popup' in template 'admin/index.html'.
Traceback (most recent call last):
  File "C:\Users\pc\AppData\Local\Programs\Python\Python35-32\lib\site-packages\django\template\base.py", line 885, in _resolve_lookup
    current = current[bit]
  File "C:\Users\pc\AppData\Local\Programs\Python\Python35-32\lib\site-packages\django\template\context.py", line 75, in __getitem__
    raise KeyError(key)
KeyError: 'is_popup'

During handling of the above exception, another exception occurred:

Traceback (most recent call last):
  File "C:\Users\pc\AppData\Local\Programs\Python\Python35-32\lib\site-packages\django\template\base.py", line 891, in _resolve_lookup
    if isinstance(current, BaseContext) and getattr(type(current), bit):
AttributeError: type object 'RequestContext' has no attribute 'is_popup'

During handling of the above exception, another exception occurred:

Traceback (most recent call last):
  File "C:\Users\pc\AppData\Local\Programs\Python\Python35-32\lib\site-packages\django\template\base.py", line 900, in _resolve_lookup
    current = current[int(bit)]
ValueError: invalid literal for int() with base 10: 'is_popup'

During handling of the above exception, another exception occurred:

Traceback (most recent call last):
  File "C:\Users\pc\AppData\Local\Programs\Python\Python35-32\lib\site-packages\django\template\base.py", line 907, in _resolve_lookup
    (bit, current))  # missing attribute
django.template.base.VariableDoesNotExist: Failed lookup for key [is_popup] in "[{'False': False, 'True': True, 'None': None}, {'user': <SimpleLazyObject: <User: admin>>, 'csrf_token': <SimpleLazyObject: <function csrf.<locals>._get_val at 0x0422FD20>>, 'request': <WSGIRequest: GET '/admin/'>, 'DEFAULT_MESSAGE_LEVELS': {'ERROR': 40, 'DEBUG': 10, 'INFO': 20, 'SUCCESS': 25, 'WARNING': 30}, 'perms': <django.contrib.auth.context_processors.PermWrapper object at 0x00D0AE50>, 'messages': <django.contrib.messages.storage.fallback.FallbackStorage object at 0x048F1DF0>}, {}, {'title': <django.utils.functional.lazy.<locals>.__proxy__ object at 0x034C1A90>, 'site_title': <django.utils.functional.lazy.<locals>.__proxy__ object at 0x034AFB30>, 'site_header': <django.utils.functional.lazy.<locals>.__proxy__ object at 0x034C1A30>, 'site_url': '/', 'LANGUAGE_BIDI': False, 'available_apps': [{'app_label': 'auth', 'app_url': '/admin/auth/', 'models': [{'add_url': '/admin/auth/group/add/', 'object_name': 'Group', 'admin_url': '/admin/auth/group/', 'perms': {'delete': True, 'add': True, 'change': True}, 'name': <django.utils.functional.lazy.<locals>.__proxy__ object at 0x0491F770>}, {'add_url': '/admin/auth/permission/add/', 'object_name': 'Permission', 'admin_url': '/admin/auth/permission/', 'perms': {'delete': True, 'add': True, 'change': True}, 'name': <django.utils.functional.lazy.<locals>.__proxy__ object at 0x0491FB50>}], 'has_module_perms': True, 'name': <django.utils.functional.lazy.<locals>.__proxy__ object at 0x034DE670>}, {'app_label': 'auths', 'app_url': '/admin/auths/', 'models': [{'add_url': '/admin/auths/hierarchytype/add/', 'object_name': 'HierarchyType', 'admin_url': '/admin/auths/hierarchytype/', 'perms': {'delete': True, 'add': True, 'change': True}, 'name': <django.utils.functional.lazy.<locals>.__proxy__ object at 0x0491F9D0>}, {'add_url': '/admin/auths/hierarchy/add/', 'object_name': 'Hierarchy', 'admin_url': '/admin/auths/hierarchy/', 'perms': {'delete': True, 'add': True, 'change': True}, 'name': <django.utils.functional.lazy.<locals>.__proxy__ object at 0x0491F7F0>}, {'add_url': '/admin/auths/menu/add/', 'object_name': 'Menu', 'admin_url': '/admin/auths/menu/', 'perms': {'delete': True, 'add': True, 'change': True}, 'name': <django.utils.functional.lazy.<locals>.__proxy__ object at 0x0491F7B0>}, {'add_url': '/admin/auths/person/add/', 'object_name': 'Person', 'admin_url': '/admin/auths/person/', 'perms': {'delete': True, 'add': True, 'change': True}, 'name': <django.utils.functional.lazy.<locals>.__proxy__ object at 0x0491F650>}, {'add_url': '/admin/auths/userhierarchygroup/add/', 'object_name': 'UserHierarchyGroup', 'admin_url': '/admin/auths/userhierarchygroup/', 'perms': {'delete': True, 'add': True, 'change': True}, 'name': <django.utils.functional.lazy.<locals>.__proxy__ object at 0x0491F630>}, {'add_url': '/admin/auths/userhierarchypermission/add/', 'object_name': 'UserHierarchyPermission', 'admin_url': '/admin/auths/userhierarchypermission/', 'perms': {'delete': True, 'add': True, 'change': True}, 'name': <django.utils.functional.lazy.<locals>.__proxy__ object at 0x0491FDB0>}, {'add_url': '/admin/auths/user/add/', 'object_name': 'User', 'admin_url': '/admin/auths/user/', 'perms': {'delete': True, 'add': True, 'change': True}, 'name': <django.utils.functional.lazy.<locals>.__proxy__ object at 0x0491FC10>}], 'has_module_perms': True, 'name': 'Auths'}, {'app_label': 'catalogo', 'app_url': '/admin/catalogo/', 'models': [{'add_url': '/admin/catalogo/autor/add/', 'object_name': 'Autor', 'admin_url': '/admin/catalogo/autor/', 'perms': {'delete': True, 'add': True, 'change': True}, 'name': 'Autores'}, {'add_url': '/admin/catalogo/categoria/add/', 'object_name': 'Categoria', 'admin_url': '/admin/catalogo/categoria/', 'perms': {'delete': True, 'add': True, 'change': True}, 'name': 'Categorias'}, {'add_url': '/admin/catalogo/libro/add/', 'object_name': 'Libro', 'admin_url': '/admin/catalogo/libro/', 'perms': {'delete': True, 'add': True, 'change': True}, 'name': 'Libros'}], 'has_module_perms': True, 'name': 'Catalogo'}, {'app_label': 'contenttypes', 'app_url': '/admin/contenttypes/', 'models': [{'add_url': '/admin/contenttypes/contenttype/add/', 'object_name': 'ContentType', 'admin_url': '/admin/contenttypes/contenttype/', 'perms': {'delete': True, 'add': True, 'change': True}, 'name': <django.utils.functional.lazy.<locals>.__proxy__ object at 0x0491FD30>}], 'has_module_perms': True, 'name': <django.utils.functional.lazy.<locals>.__proxy__ object at 0x034DE450>}, {'app_label': 'oauth2_provider', 'app_url': '/admin/oauth2_provider/', 'models': [{'add_url': '/admin/oauth2_provider/accesstoken/add/', 'object_name': 'AccessToken', 'admin_url': '/admin/oauth2_provider/accesstoken/', 'perms': {'delete': True, 'add': True, 'change': True}, 'name': <django.utils.functional.lazy.<locals>.__proxy__ object at 0x0491FB30>}, {'add_url': '/admin/oauth2_provider/application/add/', 'object_name': 'Application', 'admin_url': '/admin/oauth2_provider/application/', 'perms': {'delete': True, 'add': True, 'change': True}, 'name': <django.utils.functional.lazy.<locals>.__proxy__ object at 0x0491FA30>}, {'add_url': '/admin/oauth2_provider/grant/add/', 'object_name': 'Grant', 'admin_url': '/admin/oauth2_provider/grant/', 'perms': {'delete': True, 'add': True, 'change': True}, 'name': <django.utils.functional.lazy.<locals>.__proxy__ object at 0x0491F9F0>}, {'add_url': '/admin/oauth2_provider/refreshtoken/add/', 'object_name': 'RefreshToken', 'admin_url': '/admin/oauth2_provider/refreshtoken/', 'perms': {'delete': True, 'add': True, 'change': True}, 'name': <django.utils.functional.lazy.<locals>.__proxy__ object at 0x0491F5F0>}], 'has_module_perms': True, 'name': 'Django OAuth Toolkit'}], 'app_list': [{'app_label': 'auth', 'app_url': '/admin/auth/', 'models': [{'add_url': '/admin/auth/group/add/', 'object_name': 'Group', 'admin_url': '/admin/auth/group/', 'perms': {'delete': True, 'add': True, 'change': True}, 'name': <django.utils.functional.lazy.<locals>.__proxy__ object at 0x041DC990>}, {'add_url': '/admin/auth/permission/add/', 'object_name': 'Permission', 'admin_url': '/admin/auth/permission/', 'perms': {'delete': True, 'add': True, 'change': True}, 'name': <django.utils.functional.lazy.<locals>.__proxy__ object at 0x040BC470>}], 'has_module_perms': True, 'name': <django.utils.functional.lazy.<locals>.__proxy__ object at 0x034DE670>}, {'app_label': 'auths', 'app_url': '/admin/auths/', 'models': [{'add_url': '/admin/auths/hierarchytype/add/', 'object_name': 'HierarchyType', 'admin_url': '/admin/auths/hierarchytype/', 'perms': {'delete': True, 'add': True, 'change': True}, 'name': <django.utils.functional.lazy.<locals>.__proxy__ object at 0x040AEF30>}, {'add_url': '/admin/auths/hierarchy/add/', 'object_name': 'Hierarchy', 'admin_url': '/admin/auths/hierarchy/', 'perms': {'delete': True, 'add': True, 'change': True}, 'name': <django.utils.functional.lazy.<locals>.__proxy__ object at 0x048F1FB0>}, {'add_url': '/admin/auths/menu/add/', 'object_name': 'Menu', 'admin_url': '/admin/auths/menu/', 'perms': {'delete': True, 'add': True, 'change': True}, 'name': <django.utils.functional.lazy.<locals>.__proxy__ object at 0x041190D0>}, {'add_url': '/admin/auths/person/add/', 'object_name': 'Person', 'admin_url': '/admin/auths/person/', 'perms': {'delete': True, 'add': True, 'change': True}, 'name': <django.utils.functional.lazy.<locals>.__proxy__ object at 0x040BC330>}, {'add_url': '/admin/auths/userhierarchygroup/add/', 'object_name': 'UserHierarchyGroup', 'admin_url': '/admin/auths/userhierarchygroup/', 'perms': {'delete': True, 'add': True, 'change': True}, 'name': <django.utils.functional.lazy.<locals>.__proxy__ object at 0x040BC0F0>}, {'add_url': '/admin/auths/userhierarchypermission/add/', 'object_name': 'UserHierarchyPermission', 'admin_url': '/admin/auths/userhierarchypermission/', 'perms': {'delete': True, 'add': True, 'change': True}, 'name': <django.utils.functional.lazy.<locals>.__proxy__ object at 0x040AEED0>}, {'add_url': '/admin/auths/user/add/', 'object_name': 'User', 'admin_url': '/admin/auths/user/', 'perms': {'delete': True, 'add': True, 'change': True}, 'name': <django.utils.functional.lazy.<locals>.__proxy__ object at 0x040BC210>}], 'has_module_perms': True, 'name': 'Auths'}, {'app_label': 'catalogo', 'app_url': '/admin/catalogo/', 'models': [{'add_url': '/admin/catalogo/autor/add/', 'object_name': 'Autor', 'admin_url': '/admin/catalogo/autor/', 'perms': {'delete': True, 'add': True, 'change': True}, 'name': 'Autores'}, {'add_url': '/admin/catalogo/categoria/add/', 'object_name': 'Categoria', 'admin_url': '/admin/catalogo/categoria/', 'perms': {'delete': True, 'add': True, 'change': True}, 'name': 'Categorias'}, {'add_url': '/admin/catalogo/libro/add/', 'object_name': 'Libro', 'admin_url': '/admin/catalogo/libro/', 'perms': {'delete': True, 'add': True, 'change': True}, 'name': 'Libros'}], 'has_module_perms': True, 'name': 'Catalogo'}, {'app_label': 'contenttypes', 'app_url': '/admin/contenttypes/', 'models': [{'add_url': '/admin/contenttypes/contenttype/add/', 'object_name': 'ContentType', 'admin_url': '/admin/contenttypes/contenttype/', 'perms': {'delete': True, 'add': True, 'change': True}, 'name': <django.utils.functional.lazy.<locals>.__proxy__ object at 0x0491F670>}], 'has_module_perms': True, 'name': <django.utils.functional.lazy.<locals>.__proxy__ object at 0x034DE450>}, {'app_label': 'oauth2_provider', 'app_url': '/admin/oauth2_provider/', 'models': [{'add_url': '/admin/oauth2_provider/accesstoken/add/', 'object_name': 'AccessToken', 'admin_url': '/admin/oauth2_provider/accesstoken/', 'perms': {'delete': True, 'add': True, 'change': True}, 'name': <django.utils.functional.lazy.<locals>.__proxy__ object at 0x040BC490>}, {'add_url': '/admin/oauth2_provider/application/add/', 'object_name': 'Application', 'admin_url': '/admin/oauth2_provider/application/', 'perms': {'delete': True, 'add': True, 'change': True}, 'name': <django.utils.functional.lazy.<locals>.__proxy__ object at 0x040AEEF0>}, {'add_url': '/admin/oauth2_provider/grant/add/', 'object_name': 'Grant', 'admin_url': '/admin/oauth2_provider/grant/', 'perms': {'delete': True, 'add': True, 'change': True}, 'name': <django.utils.functional.lazy.<locals>.__proxy__ object at 0x040BC350>}, {'add_url': '/admin/oauth2_provider/refreshtoken/add/', 'object_name': 'RefreshToken', 'admin_url': '/admin/oauth2_provider/refreshtoken/', 'perms': {'delete': True, 'add': True, 'change': True}, 'name': <django.utils.functional.lazy.<locals>.__proxy__ object at 0x0415B690>}], 'has_module_perms': True, 'name': 'Django OAuth Toolkit'}], 'has_permission': True, 'LANGUAGE_CODE': 'en-us'}]"
[2016-11-04 18:16:01] DEBUG [django.template:929] Exception while resolving variable 'is_popup' in template 'admin/index.html'.
Traceback (most recent call last):
  File "C:\Users\pc\AppData\Local\Programs\Python\Python35-32\lib\site-packages\django\template\base.py", line 885, in _resolve_lookup
    current = current[bit]
  File "C:\Users\pc\AppData\Local\Programs\Python\Python35-32\lib\site-packages\django\template\context.py", line 75, in __getitem__
    raise KeyError(key)
KeyError: 'is_popup'

During handling of the above exception, another exception occurred:

Traceback (most recent call last):
  File "C:\Users\pc\AppData\Local\Programs\Python\Python35-32\lib\site-packages\django\template\base.py", line 891, in _resolve_lookup
    if isinstance(current, BaseContext) and getattr(type(current), bit):
AttributeError: type object 'RequestContext' has no attribute 'is_popup'

During handling of the above exception, another exception occurred:

Traceback (most recent call last):
  File "C:\Users\pc\AppData\Local\Programs\Python\Python35-32\lib\site-packages\django\template\base.py", line 900, in _resolve_lookup
    current = current[int(bit)]
ValueError: invalid literal for int() with base 10: 'is_popup'

During handling of the above exception, another exception occurred:

Traceback (most recent call last):
  File "C:\Users\pc\AppData\Local\Programs\Python\Python35-32\lib\site-packages\django\template\base.py", line 907, in _resolve_lookup
    (bit, current))  # missing attribute
django.template.base.VariableDoesNotExist: Failed lookup for key [is_popup] in "[{'False': False, 'True': True, 'None': None}, {'user': <SimpleLazyObject: <User: admin>>, 'csrf_token': <SimpleLazyObject: <function csrf.<locals>._get_val at 0x0422FD20>>, 'request': <WSGIRequest: GET '/admin/'>, 'DEFAULT_MESSAGE_LEVELS': {'ERROR': 40, 'DEBUG': 10, 'INFO': 20, 'SUCCESS': 25, 'WARNING': 30}, 'perms': <django.contrib.auth.context_processors.PermWrapper object at 0x00D0AE50>, 'messages': <django.contrib.messages.storage.fallback.FallbackStorage object at 0x048F1DF0>}, {}, {'title': <django.utils.functional.lazy.<locals>.__proxy__ object at 0x034C1A90>, 'site_title': <django.utils.functional.lazy.<locals>.__proxy__ object at 0x034AFB30>, 'site_header': <django.utils.functional.lazy.<locals>.__proxy__ object at 0x034C1A30>, 'site_url': '/', 'LANGUAGE_BIDI': False, 'available_apps': [{'app_label': 'auth', 'app_url': '/admin/auth/', 'models': [{'add_url': '/admin/auth/group/add/', 'object_name': 'Group', 'admin_url': '/admin/auth/group/', 'perms': {'delete': True, 'add': True, 'change': True}, 'name': <django.utils.functional.lazy.<locals>.__proxy__ object at 0x0491F770>}, {'add_url': '/admin/auth/permission/add/', 'object_name': 'Permission', 'admin_url': '/admin/auth/permission/', 'perms': {'delete': True, 'add': True, 'change': True}, 'name': <django.utils.functional.lazy.<locals>.__proxy__ object at 0x0491FB50>}], 'has_module_perms': True, 'name': <django.utils.functional.lazy.<locals>.__proxy__ object at 0x034DE670>}, {'app_label': 'auths', 'app_url': '/admin/auths/', 'models': [{'add_url': '/admin/auths/hierarchytype/add/', 'object_name': 'HierarchyType', 'admin_url': '/admin/auths/hierarchytype/', 'perms': {'delete': True, 'add': True, 'change': True}, 'name': <django.utils.functional.lazy.<locals>.__proxy__ object at 0x0491F9D0>}, {'add_url': '/admin/auths/hierarchy/add/', 'object_name': 'Hierarchy', 'admin_url': '/admin/auths/hierarchy/', 'perms': {'delete': True, 'add': True, 'change': True}, 'name': <django.utils.functional.lazy.<locals>.__proxy__ object at 0x0491F7F0>}, {'add_url': '/admin/auths/menu/add/', 'object_name': 'Menu', 'admin_url': '/admin/auths/menu/', 'perms': {'delete': True, 'add': True, 'change': True}, 'name': <django.utils.functional.lazy.<locals>.__proxy__ object at 0x0491F7B0>}, {'add_url': '/admin/auths/person/add/', 'object_name': 'Person', 'admin_url': '/admin/auths/person/', 'perms': {'delete': True, 'add': True, 'change': True}, 'name': <django.utils.functional.lazy.<locals>.__proxy__ object at 0x0491F650>}, {'add_url': '/admin/auths/userhierarchygroup/add/', 'object_name': 'UserHierarchyGroup', 'admin_url': '/admin/auths/userhierarchygroup/', 'perms': {'delete': True, 'add': True, 'change': True}, 'name': <django.utils.functional.lazy.<locals>.__proxy__ object at 0x0491F630>}, {'add_url': '/admin/auths/userhierarchypermission/add/', 'object_name': 'UserHierarchyPermission', 'admin_url': '/admin/auths/userhierarchypermission/', 'perms': {'delete': True, 'add': True, 'change': True}, 'name': <django.utils.functional.lazy.<locals>.__proxy__ object at 0x0491FDB0>}, {'add_url': '/admin/auths/user/add/', 'object_name': 'User', 'admin_url': '/admin/auths/user/', 'perms': {'delete': True, 'add': True, 'change': True}, 'name': <django.utils.functional.lazy.<locals>.__proxy__ object at 0x0491FC10>}], 'has_module_perms': True, 'name': 'Auths'}, {'app_label': 'catalogo', 'app_url': '/admin/catalogo/', 'models': [{'add_url': '/admin/catalogo/autor/add/', 'object_name': 'Autor', 'admin_url': '/admin/catalogo/autor/', 'perms': {'delete': True, 'add': True, 'change': True}, 'name': 'Autores'}, {'add_url': '/admin/catalogo/categoria/add/', 'object_name': 'Categoria', 'admin_url': '/admin/catalogo/categoria/', 'perms': {'delete': True, 'add': True, 'change': True}, 'name': 'Categorias'}, {'add_url': '/admin/catalogo/libro/add/', 'object_name': 'Libro', 'admin_url': '/admin/catalogo/libro/', 'perms': {'delete': True, 'add': True, 'change': True}, 'name': 'Libros'}], 'has_module_perms': True, 'name': 'Catalogo'}, {'app_label': 'contenttypes', 'app_url': '/admin/contenttypes/', 'models': [{'add_url': '/admin/contenttypes/contenttype/add/', 'object_name': 'ContentType', 'admin_url': '/admin/contenttypes/contenttype/', 'perms': {'delete': True, 'add': True, 'change': True}, 'name': <django.utils.functional.lazy.<locals>.__proxy__ object at 0x0491FD30>}], 'has_module_perms': True, 'name': <django.utils.functional.lazy.<locals>.__proxy__ object at 0x034DE450>}, {'app_label': 'oauth2_provider', 'app_url': '/admin/oauth2_provider/', 'models': [{'add_url': '/admin/oauth2_provider/accesstoken/add/', 'object_name': 'AccessToken', 'admin_url': '/admin/oauth2_provider/accesstoken/', 'perms': {'delete': True, 'add': True, 'change': True}, 'name': <django.utils.functional.lazy.<locals>.__proxy__ object at 0x0491FB30>}, {'add_url': '/admin/oauth2_provider/application/add/', 'object_name': 'Application', 'admin_url': '/admin/oauth2_provider/application/', 'perms': {'delete': True, 'add': True, 'change': True}, 'name': <django.utils.functional.lazy.<locals>.__proxy__ object at 0x0491FA30>}, {'add_url': '/admin/oauth2_provider/grant/add/', 'object_name': 'Grant', 'admin_url': '/admin/oauth2_provider/grant/', 'perms': {'delete': True, 'add': True, 'change': True}, 'name': <django.utils.functional.lazy.<locals>.__proxy__ object at 0x0491F9F0>}, {'add_url': '/admin/oauth2_provider/refreshtoken/add/', 'object_name': 'RefreshToken', 'admin_url': '/admin/oauth2_provider/refreshtoken/', 'perms': {'delete': True, 'add': True, 'change': True}, 'name': <django.utils.functional.lazy.<locals>.__proxy__ object at 0x0491F5F0>}], 'has_module_perms': True, 'name': 'Django OAuth Toolkit'}], 'app_list': [{'app_label': 'auth', 'app_url': '/admin/auth/', 'models': [{'add_url': '/admin/auth/group/add/', 'object_name': 'Group', 'admin_url': '/admin/auth/group/', 'perms': {'delete': True, 'add': True, 'change': True}, 'name': <django.utils.functional.lazy.<locals>.__proxy__ object at 0x041DC990>}, {'add_url': '/admin/auth/permission/add/', 'object_name': 'Permission', 'admin_url': '/admin/auth/permission/', 'perms': {'delete': True, 'add': True, 'change': True}, 'name': <django.utils.functional.lazy.<locals>.__proxy__ object at 0x040BC470>}], 'has_module_perms': True, 'name': <django.utils.functional.lazy.<locals>.__proxy__ object at 0x034DE670>}, {'app_label': 'auths', 'app_url': '/admin/auths/', 'models': [{'add_url': '/admin/auths/hierarchytype/add/', 'object_name': 'HierarchyType', 'admin_url': '/admin/auths/hierarchytype/', 'perms': {'delete': True, 'add': True, 'change': True}, 'name': <django.utils.functional.lazy.<locals>.__proxy__ object at 0x040AEF30>}, {'add_url': '/admin/auths/hierarchy/add/', 'object_name': 'Hierarchy', 'admin_url': '/admin/auths/hierarchy/', 'perms': {'delete': True, 'add': True, 'change': True}, 'name': <django.utils.functional.lazy.<locals>.__proxy__ object at 0x048F1FB0>}, {'add_url': '/admin/auths/menu/add/', 'object_name': 'Menu', 'admin_url': '/admin/auths/menu/', 'perms': {'delete': True, 'add': True, 'change': True}, 'name': <django.utils.functional.lazy.<locals>.__proxy__ object at 0x041190D0>}, {'add_url': '/admin/auths/person/add/', 'object_name': 'Person', 'admin_url': '/admin/auths/person/', 'perms': {'delete': True, 'add': True, 'change': True}, 'name': <django.utils.functional.lazy.<locals>.__proxy__ object at 0x040BC330>}, {'add_url': '/admin/auths/userhierarchygroup/add/', 'object_name': 'UserHierarchyGroup', 'admin_url': '/admin/auths/userhierarchygroup/', 'perms': {'delete': True, 'add': True, 'change': True}, 'name': <django.utils.functional.lazy.<locals>.__proxy__ object at 0x040BC0F0>}, {'add_url': '/admin/auths/userhierarchypermission/add/', 'object_name': 'UserHierarchyPermission', 'admin_url': '/admin/auths/userhierarchypermission/', 'perms': {'delete': True, 'add': True, 'change': True}, 'name': <django.utils.functional.lazy.<locals>.__proxy__ object at 0x040AEED0>}, {'add_url': '/admin/auths/user/add/', 'object_name': 'User', 'admin_url': '/admin/auths/user/', 'perms': {'delete': True, 'add': True, 'change': True}, 'name': <django.utils.functional.lazy.<locals>.__proxy__ object at 0x040BC210>}], 'has_module_perms': True, 'name': 'Auths'}, {'app_label': 'catalogo', 'app_url': '/admin/catalogo/', 'models': [{'add_url': '/admin/catalogo/autor/add/', 'object_name': 'Autor', 'admin_url': '/admin/catalogo/autor/', 'perms': {'delete': True, 'add': True, 'change': True}, 'name': 'Autores'}, {'add_url': '/admin/catalogo/categoria/add/', 'object_name': 'Categoria', 'admin_url': '/admin/catalogo/categoria/', 'perms': {'delete': True, 'add': True, 'change': True}, 'name': 'Categorias'}, {'add_url': '/admin/catalogo/libro/add/', 'object_name': 'Libro', 'admin_url': '/admin/catalogo/libro/', 'perms': {'delete': True, 'add': True, 'change': True}, 'name': 'Libros'}], 'has_module_perms': True, 'name': 'Catalogo'}, {'app_label': 'contenttypes', 'app_url': '/admin/contenttypes/', 'models': [{'add_url': '/admin/contenttypes/contenttype/add/', 'object_name': 'ContentType', 'admin_url': '/admin/contenttypes/contenttype/', 'perms': {'delete': True, 'add': True, 'change': True}, 'name': <django.utils.functional.lazy.<locals>.__proxy__ object at 0x0491F670>}], 'has_module_perms': True, 'name': <django.utils.functional.lazy.<locals>.__proxy__ object at 0x034DE450>}, {'app_label': 'oauth2_provider', 'app_url': '/admin/oauth2_provider/', 'models': [{'add_url': '/admin/oauth2_provider/accesstoken/add/', 'object_name': 'AccessToken', 'admin_url': '/admin/oauth2_provider/accesstoken/', 'perms': {'delete': True, 'add': True, 'change': True}, 'name': <django.utils.functional.lazy.<locals>.__proxy__ object at 0x040BC490>}, {'add_url': '/admin/oauth2_provider/application/add/', 'object_name': 'Application', 'admin_url': '/admin/oauth2_provider/application/', 'perms': {'delete': True, 'add': True, 'change': True}, 'name': <django.utils.functional.lazy.<locals>.__proxy__ object at 0x040AEEF0>}, {'add_url': '/admin/oauth2_provider/grant/add/', 'object_name': 'Grant', 'admin_url': '/admin/oauth2_provider/grant/', 'perms': {'delete': True, 'add': True, 'change': True}, 'name': <django.utils.functional.lazy.<locals>.__proxy__ object at 0x040BC350>}, {'add_url': '/admin/oauth2_provider/refreshtoken/add/', 'object_name': 'RefreshToken', 'admin_url': '/admin/oauth2_provider/refreshtoken/', 'perms': {'delete': True, 'add': True, 'change': True}, 'name': <django.utils.functional.lazy.<locals>.__proxy__ object at 0x0415B690>}], 'has_module_perms': True, 'name': 'Django OAuth Toolkit'}], 'has_permission': True, 'LANGUAGE_CODE': 'en-us'}]"
[2016-11-04 18:16:01] DEBUG [django.db.backends:90] (0.001) SELECT "django_admin_log"."id", "django_admin_log"."action_time", "django_admin_log"."user_id", "django_admin_log"."content_type_id", "django_admin_log"."object_id", "django_admin_log"."object_repr", "django_admin_log"."action_flag", "django_admin_log"."change_message", "auths_user"."password", "auths_user"."last_login", "auths_user"."is_superuser", "auths_user"."username", "auths_user"."first_name", "auths_user"."last_name", "auths_user"."email", "auths_user"."is_staff", "auths_user"."is_active", "auths_user"."date_joined", "auths_user"."id", "auths_user"."last_hierarchy_id", "auths_user"."last_module_id", "auths_user"."person_id", "auths_user"."updated_at", "auths_user"."registered_by", "django_content_type"."id", "django_content_type"."app_label", "django_content_type"."model" FROM "django_admin_log" INNER JOIN "auths_user" ON ("django_admin_log"."user_id" = "auths_user"."id") LEFT OUTER JOIN "django_content_type" ON ("django_admin_log"."content_type_id" = "django_content_type"."id") WHERE "django_admin_log"."user_id" = '3651942c1384420da02bbf9e5eca3faa' ORDER BY "django_admin_log"."action_time" DESC LIMIT 10; args=('3651942c1384420da02bbf9e5eca3faa',)
[2016-11-04 18:16:01] INFO [django.server:131] "GET /admin/ HTTP/1.1" 200 10333
[2016-11-04 18:16:01] INFO [django.server:131] "GET /static/admin/css/base.css HTTP/1.1" 304 0
[2016-11-04 18:16:01] INFO [django.server:131] "GET /static/admin/css/dashboard.css HTTP/1.1" 304 0
[2016-11-04 18:16:02] INFO [django.server:131] "GET /static/admin/css/fonts.css HTTP/1.1" 304 0
[2016-11-04 18:16:02] INFO [django.server:131] "GET /static/admin/fonts/Roboto-Light-webfont.woff HTTP/1.1" 304 0
[2016-11-04 18:16:02] INFO [django.server:131] "GET /static/admin/fonts/Roboto-Regular-webfont.woff HTTP/1.1" 304 0
[2016-11-04 18:16:02] INFO [django.server:131] "GET /static/admin/img/icon-changelink.svg HTTP/1.1" 304 0
[2016-11-04 18:16:02] INFO [django.server:131] "GET /static/admin/img/icon-addlink.svg HTTP/1.1" 304 0
[2016-11-04 18:16:02] INFO [django.server:131] "GET /static/admin/fonts/Roboto-Bold-webfont.woff HTTP/1.1" 304 0
[2016-11-04 18:16:02] DEBUG [django.template:929] Exception while resolving variable 'name' in template 'unknown'.
Traceback (most recent call last):
  File "C:\Users\pc\AppData\Local\Programs\Python\Python35-32\lib\site-packages\django\core\handlers\exception.py", line 39, in inner
    response = get_response(request)
  File "C:\Users\pc\AppData\Local\Programs\Python\Python35-32\lib\site-packages\django\core\handlers\base.py", line 172, in _get_response
    resolver_match = resolver.resolve(request.path_info)
  File "C:\Users\pc\AppData\Local\Programs\Python\Python35-32\lib\site-packages\django\urls\resolvers.py", line 300, in resolve
    raise Resolver404({'tried': tried, 'path': new_path})
django.urls.exceptions.Resolver404: {'path': 'favicon.ico', 'tried': [[<RegexURLResolver <RegexURLPattern list> (admin:admin) ^admin/>], [<RegexURLResolver <module 'django.contrib.admindocs.urls' from 'C:\\Users\\pc\\AppData\\Local\\Programs\\Python\\Python35-32\\lib\\site-packages\\django\\contrib\\admindocs\\urls.py'> (None:None) ^admin/doc/>], [<RegexURLResolver <module 'rest_framework.urls' from 'C:\\Users\\pc\\AppData\\Local\\Programs\\Python\\Python35-32\\lib\\site-packages\\rest_framework\\urls.py'> (rest_framework:rest_framework) ^api-auth/>], [<RegexURLResolver <module 'oauth2_provider.urls' from 'C:\\Users\\pc\\AppData\\Local\\Programs\\Python\\Python35-32\\lib\\site-packages\\oauth2_provider\\urls.py'> (None:oauth2_provider) ^o/>], [<RegexURLResolver <module 'vemo_service_apps.auths_api.urls' from 'D:\\vemo\\vemo_service\\vemo_service_apps\\auths_api\\urls.py'> (None:None) ^api/auths/>], [<RegexURLResolver <module 'vemo_service_apps.catalogo_api.urls' from 'D:\\vemo\\vemo_service\\vemo_service_apps\\catalogo_api\\urls.py'> (None:None) ^api/catalogo/>]]}

During handling of the above exception, another exception occurred:

Traceback (most recent call last):
  File "C:\Users\pc\AppData\Local\Programs\Python\Python35-32\lib\site-packages\django\template\base.py", line 885, in _resolve_lookup
    current = current[bit]
TypeError: 'RegexURLResolver' object is not subscriptable

During handling of the above exception, another exception occurred:

Traceback (most recent call last):
  File "C:\Users\pc\AppData\Local\Programs\Python\Python35-32\lib\site-packages\django\template\base.py", line 893, in _resolve_lookup
    current = getattr(current, bit)
AttributeError: 'RegexURLResolver' object has no attribute 'name'

During handling of the above exception, another exception occurred:

Traceback (most recent call last):
  File "C:\Users\pc\AppData\Local\Programs\Python\Python35-32\lib\site-packages\django\template\base.py", line 900, in _resolve_lookup
    current = current[int(bit)]
ValueError: invalid literal for int() with base 10: 'name'

During handling of the above exception, another exception occurred:

Traceback (most recent call last):
  File "C:\Users\pc\AppData\Local\Programs\Python\Python35-32\lib\site-packages\django\template\base.py", line 907, in _resolve_lookup
    (bit, current))  # missing attribute
django.template.base.VariableDoesNotExist: Failed lookup for key [name] in '<RegexURLResolver <RegexURLPattern list> (admin:admin) ^admin/>'
[2016-11-04 18:16:02] DEBUG [django.template:929] Exception while resolving variable 'name' in template 'unknown'.
Traceback (most recent call last):
  File "C:\Users\pc\AppData\Local\Programs\Python\Python35-32\lib\site-packages\django\core\handlers\exception.py", line 39, in inner
    response = get_response(request)
  File "C:\Users\pc\AppData\Local\Programs\Python\Python35-32\lib\site-packages\django\core\handlers\base.py", line 172, in _get_response
    resolver_match = resolver.resolve(request.path_info)
  File "C:\Users\pc\AppData\Local\Programs\Python\Python35-32\lib\site-packages\django\urls\resolvers.py", line 300, in resolve
    raise Resolver404({'tried': tried, 'path': new_path})
django.urls.exceptions.Resolver404: {'path': 'favicon.ico', 'tried': [[<RegexURLResolver <RegexURLPattern list> (admin:admin) ^admin/>], [<RegexURLResolver <module 'django.contrib.admindocs.urls' from 'C:\\Users\\pc\\AppData\\Local\\Programs\\Python\\Python35-32\\lib\\site-packages\\django\\contrib\\admindocs\\urls.py'> (None:None) ^admin/doc/>], [<RegexURLResolver <module 'rest_framework.urls' from 'C:\\Users\\pc\\AppData\\Local\\Programs\\Python\\Python35-32\\lib\\site-packages\\rest_framework\\urls.py'> (rest_framework:rest_framework) ^api-auth/>], [<RegexURLResolver <module 'oauth2_provider.urls' from 'C:\\Users\\pc\\AppData\\Local\\Programs\\Python\\Python35-32\\lib\\site-packages\\oauth2_provider\\urls.py'> (None:oauth2_provider) ^o/>], [<RegexURLResolver <module 'vemo_service_apps.auths_api.urls' from 'D:\\vemo\\vemo_service\\vemo_service_apps\\auths_api\\urls.py'> (None:None) ^api/auths/>], [<RegexURLResolver <module 'vemo_service_apps.catalogo_api.urls' from 'D:\\vemo\\vemo_service\\vemo_service_apps\\catalogo_api\\urls.py'> (None:None) ^api/catalogo/>]]}

During handling of the above exception, another exception occurred:

Traceback (most recent call last):
  File "C:\Users\pc\AppData\Local\Programs\Python\Python35-32\lib\site-packages\django\template\base.py", line 885, in _resolve_lookup
    current = current[bit]
TypeError: 'RegexURLResolver' object is not subscriptable

During handling of the above exception, another exception occurred:

Traceback (most recent call last):
  File "C:\Users\pc\AppData\Local\Programs\Python\Python35-32\lib\site-packages\django\template\base.py", line 893, in _resolve_lookup
    current = getattr(current, bit)
AttributeError: 'RegexURLResolver' object has no attribute 'name'

During handling of the above exception, another exception occurred:

Traceback (most recent call last):
  File "C:\Users\pc\AppData\Local\Programs\Python\Python35-32\lib\site-packages\django\template\base.py", line 900, in _resolve_lookup
    current = current[int(bit)]
ValueError: invalid literal for int() with base 10: 'name'

During handling of the above exception, another exception occurred:

Traceback (most recent call last):
  File "C:\Users\pc\AppData\Local\Programs\Python\Python35-32\lib\site-packages\django\template\base.py", line 907, in _resolve_lookup
    (bit, current))  # missing attribute
django.template.base.VariableDoesNotExist: Failed lookup for key [name] in "<RegexURLResolver <module 'django.contrib.admindocs.urls' from 'C:\\\\Users\\\\pc\\\\AppData\\\\Local\\\\Programs\\\\Python\\\\Python35-32\\\\lib\\\\site-packages\\\\django\\\\contrib\\\\admindocs\\\\urls.py'> (None:None) ^admin/doc/>"
[2016-11-04 18:16:02] DEBUG [django.template:929] Exception while resolving variable 'name' in template 'unknown'.
Traceback (most recent call last):
  File "C:\Users\pc\AppData\Local\Programs\Python\Python35-32\lib\site-packages\django\core\handlers\exception.py", line 39, in inner
    response = get_response(request)
  File "C:\Users\pc\AppData\Local\Programs\Python\Python35-32\lib\site-packages\django\core\handlers\base.py", line 172, in _get_response
    resolver_match = resolver.resolve(request.path_info)
  File "C:\Users\pc\AppData\Local\Programs\Python\Python35-32\lib\site-packages\django\urls\resolvers.py", line 300, in resolve
    raise Resolver404({'tried': tried, 'path': new_path})
django.urls.exceptions.Resolver404: {'path': 'favicon.ico', 'tried': [[<RegexURLResolver <RegexURLPattern list> (admin:admin) ^admin/>], [<RegexURLResolver <module 'django.contrib.admindocs.urls' from 'C:\\Users\\pc\\AppData\\Local\\Programs\\Python\\Python35-32\\lib\\site-packages\\django\\contrib\\admindocs\\urls.py'> (None:None) ^admin/doc/>], [<RegexURLResolver <module 'rest_framework.urls' from 'C:\\Users\\pc\\AppData\\Local\\Programs\\Python\\Python35-32\\lib\\site-packages\\rest_framework\\urls.py'> (rest_framework:rest_framework) ^api-auth/>], [<RegexURLResolver <module 'oauth2_provider.urls' from 'C:\\Users\\pc\\AppData\\Local\\Programs\\Python\\Python35-32\\lib\\site-packages\\oauth2_provider\\urls.py'> (None:oauth2_provider) ^o/>], [<RegexURLResolver <module 'vemo_service_apps.auths_api.urls' from 'D:\\vemo\\vemo_service\\vemo_service_apps\\auths_api\\urls.py'> (None:None) ^api/auths/>], [<RegexURLResolver <module 'vemo_service_apps.catalogo_api.urls' from 'D:\\vemo\\vemo_service\\vemo_service_apps\\catalogo_api\\urls.py'> (None:None) ^api/catalogo/>]]}

During handling of the above exception, another exception occurred:

Traceback (most recent call last):
  File "C:\Users\pc\AppData\Local\Programs\Python\Python35-32\lib\site-packages\django\template\base.py", line 885, in _resolve_lookup
    current = current[bit]
TypeError: 'RegexURLResolver' object is not subscriptable

During handling of the above exception, another exception occurred:

Traceback (most recent call last):
  File "C:\Users\pc\AppData\Local\Programs\Python\Python35-32\lib\site-packages\django\template\base.py", line 893, in _resolve_lookup
    current = getattr(current, bit)
AttributeError: 'RegexURLResolver' object has no attribute 'name'

During handling of the above exception, another exception occurred:

Traceback (most recent call last):
  File "C:\Users\pc\AppData\Local\Programs\Python\Python35-32\lib\site-packages\django\template\base.py", line 900, in _resolve_lookup
    current = current[int(bit)]
ValueError: invalid literal for int() with base 10: 'name'

During handling of the above exception, another exception occurred:

Traceback (most recent call last):
  File "C:\Users\pc\AppData\Local\Programs\Python\Python35-32\lib\site-packages\django\template\base.py", line 907, in _resolve_lookup
    (bit, current))  # missing attribute
django.template.base.VariableDoesNotExist: Failed lookup for key [name] in "<RegexURLResolver <module 'rest_framework.urls' from 'C:\\\\Users\\\\pc\\\\AppData\\\\Local\\\\Programs\\\\Python\\\\Python35-32\\\\lib\\\\site-packages\\\\rest_framework\\\\urls.py'> (rest_framework:rest_framework) ^api-auth/>"
[2016-11-04 18:16:02] DEBUG [django.template:929] Exception while resolving variable 'name' in template 'unknown'.
Traceback (most recent call last):
  File "C:\Users\pc\AppData\Local\Programs\Python\Python35-32\lib\site-packages\django\core\handlers\exception.py", line 39, in inner
    response = get_response(request)
  File "C:\Users\pc\AppData\Local\Programs\Python\Python35-32\lib\site-packages\django\core\handlers\base.py", line 172, in _get_response
    resolver_match = resolver.resolve(request.path_info)
  File "C:\Users\pc\AppData\Local\Programs\Python\Python35-32\lib\site-packages\django\urls\resolvers.py", line 300, in resolve
    raise Resolver404({'tried': tried, 'path': new_path})
django.urls.exceptions.Resolver404: {'path': 'favicon.ico', 'tried': [[<RegexURLResolver <RegexURLPattern list> (admin:admin) ^admin/>], [<RegexURLResolver <module 'django.contrib.admindocs.urls' from 'C:\\Users\\pc\\AppData\\Local\\Programs\\Python\\Python35-32\\lib\\site-packages\\django\\contrib\\admindocs\\urls.py'> (None:None) ^admin/doc/>], [<RegexURLResolver <module 'rest_framework.urls' from 'C:\\Users\\pc\\AppData\\Local\\Programs\\Python\\Python35-32\\lib\\site-packages\\rest_framework\\urls.py'> (rest_framework:rest_framework) ^api-auth/>], [<RegexURLResolver <module 'oauth2_provider.urls' from 'C:\\Users\\pc\\AppData\\Local\\Programs\\Python\\Python35-32\\lib\\site-packages\\oauth2_provider\\urls.py'> (None:oauth2_provider) ^o/>], [<RegexURLResolver <module 'vemo_service_apps.auths_api.urls' from 'D:\\vemo\\vemo_service\\vemo_service_apps\\auths_api\\urls.py'> (None:None) ^api/auths/>], [<RegexURLResolver <module 'vemo_service_apps.catalogo_api.urls' from 'D:\\vemo\\vemo_service\\vemo_service_apps\\catalogo_api\\urls.py'> (None:None) ^api/catalogo/>]]}

During handling of the above exception, another exception occurred:

Traceback (most recent call last):
  File "C:\Users\pc\AppData\Local\Programs\Python\Python35-32\lib\site-packages\django\template\base.py", line 885, in _resolve_lookup
    current = current[bit]
TypeError: 'RegexURLResolver' object is not subscriptable

During handling of the above exception, another exception occurred:

Traceback (most recent call last):
  File "C:\Users\pc\AppData\Local\Programs\Python\Python35-32\lib\site-packages\django\template\base.py", line 893, in _resolve_lookup
    current = getattr(current, bit)
AttributeError: 'RegexURLResolver' object has no attribute 'name'

During handling of the above exception, another exception occurred:

Traceback (most recent call last):
  File "C:\Users\pc\AppData\Local\Programs\Python\Python35-32\lib\site-packages\django\template\base.py", line 900, in _resolve_lookup
    current = current[int(bit)]
ValueError: invalid literal for int() with base 10: 'name'

During handling of the above exception, another exception occurred:

Traceback (most recent call last):
  File "C:\Users\pc\AppData\Local\Programs\Python\Python35-32\lib\site-packages\django\template\base.py", line 907, in _resolve_lookup
    (bit, current))  # missing attribute
django.template.base.VariableDoesNotExist: Failed lookup for key [name] in "<RegexURLResolver <module 'oauth2_provider.urls' from 'C:\\\\Users\\\\pc\\\\AppData\\\\Local\\\\Programs\\\\Python\\\\Python35-32\\\\lib\\\\site-packages\\\\oauth2_provider\\\\urls.py'> (None:oauth2_provider) ^o/>"
[2016-11-04 18:16:02] DEBUG [django.template:929] Exception while resolving variable 'name' in template 'unknown'.
Traceback (most recent call last):
  File "C:\Users\pc\AppData\Local\Programs\Python\Python35-32\lib\site-packages\django\core\handlers\exception.py", line 39, in inner
    response = get_response(request)
  File "C:\Users\pc\AppData\Local\Programs\Python\Python35-32\lib\site-packages\django\core\handlers\base.py", line 172, in _get_response
    resolver_match = resolver.resolve(request.path_info)
  File "C:\Users\pc\AppData\Local\Programs\Python\Python35-32\lib\site-packages\django\urls\resolvers.py", line 300, in resolve
    raise Resolver404({'tried': tried, 'path': new_path})
django.urls.exceptions.Resolver404: {'path': 'favicon.ico', 'tried': [[<RegexURLResolver <RegexURLPattern list> (admin:admin) ^admin/>], [<RegexURLResolver <module 'django.contrib.admindocs.urls' from 'C:\\Users\\pc\\AppData\\Local\\Programs\\Python\\Python35-32\\lib\\site-packages\\django\\contrib\\admindocs\\urls.py'> (None:None) ^admin/doc/>], [<RegexURLResolver <module 'rest_framework.urls' from 'C:\\Users\\pc\\AppData\\Local\\Programs\\Python\\Python35-32\\lib\\site-packages\\rest_framework\\urls.py'> (rest_framework:rest_framework) ^api-auth/>], [<RegexURLResolver <module 'oauth2_provider.urls' from 'C:\\Users\\pc\\AppData\\Local\\Programs\\Python\\Python35-32\\lib\\site-packages\\oauth2_provider\\urls.py'> (None:oauth2_provider) ^o/>], [<RegexURLResolver <module 'vemo_service_apps.auths_api.urls' from 'D:\\vemo\\vemo_service\\vemo_service_apps\\auths_api\\urls.py'> (None:None) ^api/auths/>], [<RegexURLResolver <module 'vemo_service_apps.catalogo_api.urls' from 'D:\\vemo\\vemo_service\\vemo_service_apps\\catalogo_api\\urls.py'> (None:None) ^api/catalogo/>]]}

During handling of the above exception, another exception occurred:

Traceback (most recent call last):
  File "C:\Users\pc\AppData\Local\Programs\Python\Python35-32\lib\site-packages\django\template\base.py", line 885, in _resolve_lookup
    current = current[bit]
TypeError: 'RegexURLResolver' object is not subscriptable

During handling of the above exception, another exception occurred:

Traceback (most recent call last):
  File "C:\Users\pc\AppData\Local\Programs\Python\Python35-32\lib\site-packages\django\template\base.py", line 893, in _resolve_lookup
    current = getattr(current, bit)
AttributeError: 'RegexURLResolver' object has no attribute 'name'

During handling of the above exception, another exception occurred:

Traceback (most recent call last):
  File "C:\Users\pc\AppData\Local\Programs\Python\Python35-32\lib\site-packages\django\template\base.py", line 900, in _resolve_lookup
    current = current[int(bit)]
ValueError: invalid literal for int() with base 10: 'name'

During handling of the above exception, another exception occurred:

Traceback (most recent call last):
  File "C:\Users\pc\AppData\Local\Programs\Python\Python35-32\lib\site-packages\django\template\base.py", line 907, in _resolve_lookup
    (bit, current))  # missing attribute
django.template.base.VariableDoesNotExist: Failed lookup for key [name] in "<RegexURLResolver <module 'vemo_service_apps.auths_api.urls' from 'D:\\\\vemo\\\\vemo_service\\\\vemo_service_apps\\\\auths_api\\\\urls.py'> (None:None) ^api/auths/>"
[2016-11-04 18:16:02] DEBUG [django.template:929] Exception while resolving variable 'name' in template 'unknown'.
Traceback (most recent call last):
  File "C:\Users\pc\AppData\Local\Programs\Python\Python35-32\lib\site-packages\django\core\handlers\exception.py", line 39, in inner
    response = get_response(request)
  File "C:\Users\pc\AppData\Local\Programs\Python\Python35-32\lib\site-packages\django\core\handlers\base.py", line 172, in _get_response
    resolver_match = resolver.resolve(request.path_info)
  File "C:\Users\pc\AppData\Local\Programs\Python\Python35-32\lib\site-packages\django\urls\resolvers.py", line 300, in resolve
    raise Resolver404({'tried': tried, 'path': new_path})
django.urls.exceptions.Resolver404: {'path': 'favicon.ico', 'tried': [[<RegexURLResolver <RegexURLPattern list> (admin:admin) ^admin/>], [<RegexURLResolver <module 'django.contrib.admindocs.urls' from 'C:\\Users\\pc\\AppData\\Local\\Programs\\Python\\Python35-32\\lib\\site-packages\\django\\contrib\\admindocs\\urls.py'> (None:None) ^admin/doc/>], [<RegexURLResolver <module 'rest_framework.urls' from 'C:\\Users\\pc\\AppData\\Local\\Programs\\Python\\Python35-32\\lib\\site-packages\\rest_framework\\urls.py'> (rest_framework:rest_framework) ^api-auth/>], [<RegexURLResolver <module 'oauth2_provider.urls' from 'C:\\Users\\pc\\AppData\\Local\\Programs\\Python\\Python35-32\\lib\\site-packages\\oauth2_provider\\urls.py'> (None:oauth2_provider) ^o/>], [<RegexURLResolver <module 'vemo_service_apps.auths_api.urls' from 'D:\\vemo\\vemo_service\\vemo_service_apps\\auths_api\\urls.py'> (None:None) ^api/auths/>], [<RegexURLResolver <module 'vemo_service_apps.catalogo_api.urls' from 'D:\\vemo\\vemo_service\\vemo_service_apps\\catalogo_api\\urls.py'> (None:None) ^api/catalogo/>]]}

During handling of the above exception, another exception occurred:

Traceback (most recent call last):
  File "C:\Users\pc\AppData\Local\Programs\Python\Python35-32\lib\site-packages\django\template\base.py", line 885, in _resolve_lookup
    current = current[bit]
TypeError: 'RegexURLResolver' object is not subscriptable

During handling of the above exception, another exception occurred:

Traceback (most recent call last):
  File "C:\Users\pc\AppData\Local\Programs\Python\Python35-32\lib\site-packages\django\template\base.py", line 893, in _resolve_lookup
    current = getattr(current, bit)
AttributeError: 'RegexURLResolver' object has no attribute 'name'

During handling of the above exception, another exception occurred:

Traceback (most recent call last):
  File "C:\Users\pc\AppData\Local\Programs\Python\Python35-32\lib\site-packages\django\template\base.py", line 900, in _resolve_lookup
    current = current[int(bit)]
ValueError: invalid literal for int() with base 10: 'name'

During handling of the above exception, another exception occurred:

Traceback (most recent call last):
  File "C:\Users\pc\AppData\Local\Programs\Python\Python35-32\lib\site-packages\django\template\base.py", line 907, in _resolve_lookup
    (bit, current))  # missing attribute
django.template.base.VariableDoesNotExist: Failed lookup for key [name] in "<RegexURLResolver <module 'vemo_service_apps.catalogo_api.urls' from 'D:\\\\vemo\\\\vemo_service\\\\vemo_service_apps\\\\catalogo_api\\\\urls.py'> (None:None) ^api/catalogo/>"
[2016-11-04 18:16:02] WARNING [django.request:152] Not Found: /favicon.ico
[2016-11-04 18:16:02] WARNING [django.server:131] "GET /favicon.ico HTTP/1.1" 404 2488
[2016-11-04 18:16:02] DEBUG [django.template:929] Exception while resolving variable 'name' in template 'unknown'.
Traceback (most recent call last):
  File "C:\Users\pc\AppData\Local\Programs\Python\Python35-32\lib\site-packages\django\core\handlers\exception.py", line 39, in inner
    response = get_response(request)
  File "C:\Users\pc\AppData\Local\Programs\Python\Python35-32\lib\site-packages\django\core\handlers\base.py", line 172, in _get_response
    resolver_match = resolver.resolve(request.path_info)
  File "C:\Users\pc\AppData\Local\Programs\Python\Python35-32\lib\site-packages\django\urls\resolvers.py", line 300, in resolve
    raise Resolver404({'tried': tried, 'path': new_path})
django.urls.exceptions.Resolver404: {'path': 'favicon.ico', 'tried': [[<RegexURLResolver <RegexURLPattern list> (admin:admin) ^admin/>], [<RegexURLResolver <module 'django.contrib.admindocs.urls' from 'C:\\Users\\pc\\AppData\\Local\\Programs\\Python\\Python35-32\\lib\\site-packages\\django\\contrib\\admindocs\\urls.py'> (None:None) ^admin/doc/>], [<RegexURLResolver <module 'rest_framework.urls' from 'C:\\Users\\pc\\AppData\\Local\\Programs\\Python\\Python35-32\\lib\\site-packages\\rest_framework\\urls.py'> (rest_framework:rest_framework) ^api-auth/>], [<RegexURLResolver <module 'oauth2_provider.urls' from 'C:\\Users\\pc\\AppData\\Local\\Programs\\Python\\Python35-32\\lib\\site-packages\\oauth2_provider\\urls.py'> (None:oauth2_provider) ^o/>], [<RegexURLResolver <module 'vemo_service_apps.auths_api.urls' from 'D:\\vemo\\vemo_service\\vemo_service_apps\\auths_api\\urls.py'> (None:None) ^api/auths/>], [<RegexURLResolver <module 'vemo_service_apps.catalogo_api.urls' from 'D:\\vemo\\vemo_service\\vemo_service_apps\\catalogo_api\\urls.py'> (None:None) ^api/catalogo/>]]}

During handling of the above exception, another exception occurred:

Traceback (most recent call last):
  File "C:\Users\pc\AppData\Local\Programs\Python\Python35-32\lib\site-packages\django\template\base.py", line 885, in _resolve_lookup
    current = current[bit]
TypeError: 'RegexURLResolver' object is not subscriptable

During handling of the above exception, another exception occurred:

Traceback (most recent call last):
  File "C:\Users\pc\AppData\Local\Programs\Python\Python35-32\lib\site-packages\django\template\base.py", line 893, in _resolve_lookup
    current = getattr(current, bit)
AttributeError: 'RegexURLResolver' object has no attribute 'name'

During handling of the above exception, another exception occurred:

Traceback (most recent call last):
  File "C:\Users\pc\AppData\Local\Programs\Python\Python35-32\lib\site-packages\django\template\base.py", line 900, in _resolve_lookup
    current = current[int(bit)]
ValueError: invalid literal for int() with base 10: 'name'

During handling of the above exception, another exception occurred:

Traceback (most recent call last):
  File "C:\Users\pc\AppData\Local\Programs\Python\Python35-32\lib\site-packages\django\template\base.py", line 907, in _resolve_lookup
    (bit, current))  # missing attribute
django.template.base.VariableDoesNotExist: Failed lookup for key [name] in '<RegexURLResolver <RegexURLPattern list> (admin:admin) ^admin/>'
[2016-11-04 18:16:02] DEBUG [django.template:929] Exception while resolving variable 'name' in template 'unknown'.
Traceback (most recent call last):
  File "C:\Users\pc\AppData\Local\Programs\Python\Python35-32\lib\site-packages\django\core\handlers\exception.py", line 39, in inner
    response = get_response(request)
  File "C:\Users\pc\AppData\Local\Programs\Python\Python35-32\lib\site-packages\django\core\handlers\base.py", line 172, in _get_response
    resolver_match = resolver.resolve(request.path_info)
  File "C:\Users\pc\AppData\Local\Programs\Python\Python35-32\lib\site-packages\django\urls\resolvers.py", line 300, in resolve
    raise Resolver404({'tried': tried, 'path': new_path})
django.urls.exceptions.Resolver404: {'path': 'favicon.ico', 'tried': [[<RegexURLResolver <RegexURLPattern list> (admin:admin) ^admin/>], [<RegexURLResolver <module 'django.contrib.admindocs.urls' from 'C:\\Users\\pc\\AppData\\Local\\Programs\\Python\\Python35-32\\lib\\site-packages\\django\\contrib\\admindocs\\urls.py'> (None:None) ^admin/doc/>], [<RegexURLResolver <module 'rest_framework.urls' from 'C:\\Users\\pc\\AppData\\Local\\Programs\\Python\\Python35-32\\lib\\site-packages\\rest_framework\\urls.py'> (rest_framework:rest_framework) ^api-auth/>], [<RegexURLResolver <module 'oauth2_provider.urls' from 'C:\\Users\\pc\\AppData\\Local\\Programs\\Python\\Python35-32\\lib\\site-packages\\oauth2_provider\\urls.py'> (None:oauth2_provider) ^o/>], [<RegexURLResolver <module 'vemo_service_apps.auths_api.urls' from 'D:\\vemo\\vemo_service\\vemo_service_apps\\auths_api\\urls.py'> (None:None) ^api/auths/>], [<RegexURLResolver <module 'vemo_service_apps.catalogo_api.urls' from 'D:\\vemo\\vemo_service\\vemo_service_apps\\catalogo_api\\urls.py'> (None:None) ^api/catalogo/>]]}

During handling of the above exception, another exception occurred:

Traceback (most recent call last):
  File "C:\Users\pc\AppData\Local\Programs\Python\Python35-32\lib\site-packages\django\template\base.py", line 885, in _resolve_lookup
    current = current[bit]
TypeError: 'RegexURLResolver' object is not subscriptable

During handling of the above exception, another exception occurred:

Traceback (most recent call last):
  File "C:\Users\pc\AppData\Local\Programs\Python\Python35-32\lib\site-packages\django\template\base.py", line 893, in _resolve_lookup
    current = getattr(current, bit)
AttributeError: 'RegexURLResolver' object has no attribute 'name'

During handling of the above exception, another exception occurred:

Traceback (most recent call last):
  File "C:\Users\pc\AppData\Local\Programs\Python\Python35-32\lib\site-packages\django\template\base.py", line 900, in _resolve_lookup
    current = current[int(bit)]
ValueError: invalid literal for int() with base 10: 'name'

During handling of the above exception, another exception occurred:

Traceback (most recent call last):
  File "C:\Users\pc\AppData\Local\Programs\Python\Python35-32\lib\site-packages\django\template\base.py", line 907, in _resolve_lookup
    (bit, current))  # missing attribute
django.template.base.VariableDoesNotExist: Failed lookup for key [name] in "<RegexURLResolver <module 'django.contrib.admindocs.urls' from 'C:\\\\Users\\\\pc\\\\AppData\\\\Local\\\\Programs\\\\Python\\\\Python35-32\\\\lib\\\\site-packages\\\\django\\\\contrib\\\\admindocs\\\\urls.py'> (None:None) ^admin/doc/>"
[2016-11-04 18:16:02] DEBUG [django.template:929] Exception while resolving variable 'name' in template 'unknown'.
Traceback (most recent call last):
  File "C:\Users\pc\AppData\Local\Programs\Python\Python35-32\lib\site-packages\django\core\handlers\exception.py", line 39, in inner
    response = get_response(request)
  File "C:\Users\pc\AppData\Local\Programs\Python\Python35-32\lib\site-packages\django\core\handlers\base.py", line 172, in _get_response
    resolver_match = resolver.resolve(request.path_info)
  File "C:\Users\pc\AppData\Local\Programs\Python\Python35-32\lib\site-packages\django\urls\resolvers.py", line 300, in resolve
    raise Resolver404({'tried': tried, 'path': new_path})
django.urls.exceptions.Resolver404: {'path': 'favicon.ico', 'tried': [[<RegexURLResolver <RegexURLPattern list> (admin:admin) ^admin/>], [<RegexURLResolver <module 'django.contrib.admindocs.urls' from 'C:\\Users\\pc\\AppData\\Local\\Programs\\Python\\Python35-32\\lib\\site-packages\\django\\contrib\\admindocs\\urls.py'> (None:None) ^admin/doc/>], [<RegexURLResolver <module 'rest_framework.urls' from 'C:\\Users\\pc\\AppData\\Local\\Programs\\Python\\Python35-32\\lib\\site-packages\\rest_framework\\urls.py'> (rest_framework:rest_framework) ^api-auth/>], [<RegexURLResolver <module 'oauth2_provider.urls' from 'C:\\Users\\pc\\AppData\\Local\\Programs\\Python\\Python35-32\\lib\\site-packages\\oauth2_provider\\urls.py'> (None:oauth2_provider) ^o/>], [<RegexURLResolver <module 'vemo_service_apps.auths_api.urls' from 'D:\\vemo\\vemo_service\\vemo_service_apps\\auths_api\\urls.py'> (None:None) ^api/auths/>], [<RegexURLResolver <module 'vemo_service_apps.catalogo_api.urls' from 'D:\\vemo\\vemo_service\\vemo_service_apps\\catalogo_api\\urls.py'> (None:None) ^api/catalogo/>]]}

During handling of the above exception, another exception occurred:

Traceback (most recent call last):
  File "C:\Users\pc\AppData\Local\Programs\Python\Python35-32\lib\site-packages\django\template\base.py", line 885, in _resolve_lookup
    current = current[bit]
TypeError: 'RegexURLResolver' object is not subscriptable

During handling of the above exception, another exception occurred:

Traceback (most recent call last):
  File "C:\Users\pc\AppData\Local\Programs\Python\Python35-32\lib\site-packages\django\template\base.py", line 893, in _resolve_lookup
    current = getattr(current, bit)
AttributeError: 'RegexURLResolver' object has no attribute 'name'

During handling of the above exception, another exception occurred:

Traceback (most recent call last):
  File "C:\Users\pc\AppData\Local\Programs\Python\Python35-32\lib\site-packages\django\template\base.py", line 900, in _resolve_lookup
    current = current[int(bit)]
ValueError: invalid literal for int() with base 10: 'name'

During handling of the above exception, another exception occurred:

Traceback (most recent call last):
  File "C:\Users\pc\AppData\Local\Programs\Python\Python35-32\lib\site-packages\django\template\base.py", line 907, in _resolve_lookup
    (bit, current))  # missing attribute
django.template.base.VariableDoesNotExist: Failed lookup for key [name] in "<RegexURLResolver <module 'rest_framework.urls' from 'C:\\\\Users\\\\pc\\\\AppData\\\\Local\\\\Programs\\\\Python\\\\Python35-32\\\\lib\\\\site-packages\\\\rest_framework\\\\urls.py'> (rest_framework:rest_framework) ^api-auth/>"
[2016-11-04 18:16:02] DEBUG [django.template:929] Exception while resolving variable 'name' in template 'unknown'.
Traceback (most recent call last):
  File "C:\Users\pc\AppData\Local\Programs\Python\Python35-32\lib\site-packages\django\core\handlers\exception.py", line 39, in inner
    response = get_response(request)
  File "C:\Users\pc\AppData\Local\Programs\Python\Python35-32\lib\site-packages\django\core\handlers\base.py", line 172, in _get_response
    resolver_match = resolver.resolve(request.path_info)
  File "C:\Users\pc\AppData\Local\Programs\Python\Python35-32\lib\site-packages\django\urls\resolvers.py", line 300, in resolve
    raise Resolver404({'tried': tried, 'path': new_path})
django.urls.exceptions.Resolver404: {'path': 'favicon.ico', 'tried': [[<RegexURLResolver <RegexURLPattern list> (admin:admin) ^admin/>], [<RegexURLResolver <module 'django.contrib.admindocs.urls' from 'C:\\Users\\pc\\AppData\\Local\\Programs\\Python\\Python35-32\\lib\\site-packages\\django\\contrib\\admindocs\\urls.py'> (None:None) ^admin/doc/>], [<RegexURLResolver <module 'rest_framework.urls' from 'C:\\Users\\pc\\AppData\\Local\\Programs\\Python\\Python35-32\\lib\\site-packages\\rest_framework\\urls.py'> (rest_framework:rest_framework) ^api-auth/>], [<RegexURLResolver <module 'oauth2_provider.urls' from 'C:\\Users\\pc\\AppData\\Local\\Programs\\Python\\Python35-32\\lib\\site-packages\\oauth2_provider\\urls.py'> (None:oauth2_provider) ^o/>], [<RegexURLResolver <module 'vemo_service_apps.auths_api.urls' from 'D:\\vemo\\vemo_service\\vemo_service_apps\\auths_api\\urls.py'> (None:None) ^api/auths/>], [<RegexURLResolver <module 'vemo_service_apps.catalogo_api.urls' from 'D:\\vemo\\vemo_service\\vemo_service_apps\\catalogo_api\\urls.py'> (None:None) ^api/catalogo/>]]}

During handling of the above exception, another exception occurred:

Traceback (most recent call last):
  File "C:\Users\pc\AppData\Local\Programs\Python\Python35-32\lib\site-packages\django\template\base.py", line 885, in _resolve_lookup
    current = current[bit]
TypeError: 'RegexURLResolver' object is not subscriptable

During handling of the above exception, another exception occurred:

Traceback (most recent call last):
  File "C:\Users\pc\AppData\Local\Programs\Python\Python35-32\lib\site-packages\django\template\base.py", line 893, in _resolve_lookup
    current = getattr(current, bit)
AttributeError: 'RegexURLResolver' object has no attribute 'name'

During handling of the above exception, another exception occurred:

Traceback (most recent call last):
  File "C:\Users\pc\AppData\Local\Programs\Python\Python35-32\lib\site-packages\django\template\base.py", line 900, in _resolve_lookup
    current = current[int(bit)]
ValueError: invalid literal for int() with base 10: 'name'

During handling of the above exception, another exception occurred:

Traceback (most recent call last):
  File "C:\Users\pc\AppData\Local\Programs\Python\Python35-32\lib\site-packages\django\template\base.py", line 907, in _resolve_lookup
    (bit, current))  # missing attribute
django.template.base.VariableDoesNotExist: Failed lookup for key [name] in "<RegexURLResolver <module 'oauth2_provider.urls' from 'C:\\\\Users\\\\pc\\\\AppData\\\\Local\\\\Programs\\\\Python\\\\Python35-32\\\\lib\\\\site-packages\\\\oauth2_provider\\\\urls.py'> (None:oauth2_provider) ^o/>"
[2016-11-04 18:16:02] DEBUG [django.template:929] Exception while resolving variable 'name' in template 'unknown'.
Traceback (most recent call last):
  File "C:\Users\pc\AppData\Local\Programs\Python\Python35-32\lib\site-packages\django\core\handlers\exception.py", line 39, in inner
    response = get_response(request)
  File "C:\Users\pc\AppData\Local\Programs\Python\Python35-32\lib\site-packages\django\core\handlers\base.py", line 172, in _get_response
    resolver_match = resolver.resolve(request.path_info)
  File "C:\Users\pc\AppData\Local\Programs\Python\Python35-32\lib\site-packages\django\urls\resolvers.py", line 300, in resolve
    raise Resolver404({'tried': tried, 'path': new_path})
django.urls.exceptions.Resolver404: {'path': 'favicon.ico', 'tried': [[<RegexURLResolver <RegexURLPattern list> (admin:admin) ^admin/>], [<RegexURLResolver <module 'django.contrib.admindocs.urls' from 'C:\\Users\\pc\\AppData\\Local\\Programs\\Python\\Python35-32\\lib\\site-packages\\django\\contrib\\admindocs\\urls.py'> (None:None) ^admin/doc/>], [<RegexURLResolver <module 'rest_framework.urls' from 'C:\\Users\\pc\\AppData\\Local\\Programs\\Python\\Python35-32\\lib\\site-packages\\rest_framework\\urls.py'> (rest_framework:rest_framework) ^api-auth/>], [<RegexURLResolver <module 'oauth2_provider.urls' from 'C:\\Users\\pc\\AppData\\Local\\Programs\\Python\\Python35-32\\lib\\site-packages\\oauth2_provider\\urls.py'> (None:oauth2_provider) ^o/>], [<RegexURLResolver <module 'vemo_service_apps.auths_api.urls' from 'D:\\vemo\\vemo_service\\vemo_service_apps\\auths_api\\urls.py'> (None:None) ^api/auths/>], [<RegexURLResolver <module 'vemo_service_apps.catalogo_api.urls' from 'D:\\vemo\\vemo_service\\vemo_service_apps\\catalogo_api\\urls.py'> (None:None) ^api/catalogo/>]]}

During handling of the above exception, another exception occurred:

Traceback (most recent call last):
  File "C:\Users\pc\AppData\Local\Programs\Python\Python35-32\lib\site-packages\django\template\base.py", line 885, in _resolve_lookup
    current = current[bit]
TypeError: 'RegexURLResolver' object is not subscriptable

During handling of the above exception, another exception occurred:

Traceback (most recent call last):
  File "C:\Users\pc\AppData\Local\Programs\Python\Python35-32\lib\site-packages\django\template\base.py", line 893, in _resolve_lookup
    current = getattr(current, bit)
AttributeError: 'RegexURLResolver' object has no attribute 'name'

During handling of the above exception, another exception occurred:

Traceback (most recent call last):
  File "C:\Users\pc\AppData\Local\Programs\Python\Python35-32\lib\site-packages\django\template\base.py", line 900, in _resolve_lookup
    current = current[int(bit)]
ValueError: invalid literal for int() with base 10: 'name'

During handling of the above exception, another exception occurred:

Traceback (most recent call last):
  File "C:\Users\pc\AppData\Local\Programs\Python\Python35-32\lib\site-packages\django\template\base.py", line 907, in _resolve_lookup
    (bit, current))  # missing attribute
django.template.base.VariableDoesNotExist: Failed lookup for key [name] in "<RegexURLResolver <module 'vemo_service_apps.auths_api.urls' from 'D:\\\\vemo\\\\vemo_service\\\\vemo_service_apps\\\\auths_api\\\\urls.py'> (None:None) ^api/auths/>"
[2016-11-04 18:16:02] DEBUG [django.template:929] Exception while resolving variable 'name' in template 'unknown'.
Traceback (most recent call last):
  File "C:\Users\pc\AppData\Local\Programs\Python\Python35-32\lib\site-packages\django\core\handlers\exception.py", line 39, in inner
    response = get_response(request)
  File "C:\Users\pc\AppData\Local\Programs\Python\Python35-32\lib\site-packages\django\core\handlers\base.py", line 172, in _get_response
    resolver_match = resolver.resolve(request.path_info)
  File "C:\Users\pc\AppData\Local\Programs\Python\Python35-32\lib\site-packages\django\urls\resolvers.py", line 300, in resolve
    raise Resolver404({'tried': tried, 'path': new_path})
django.urls.exceptions.Resolver404: {'path': 'favicon.ico', 'tried': [[<RegexURLResolver <RegexURLPattern list> (admin:admin) ^admin/>], [<RegexURLResolver <module 'django.contrib.admindocs.urls' from 'C:\\Users\\pc\\AppData\\Local\\Programs\\Python\\Python35-32\\lib\\site-packages\\django\\contrib\\admindocs\\urls.py'> (None:None) ^admin/doc/>], [<RegexURLResolver <module 'rest_framework.urls' from 'C:\\Users\\pc\\AppData\\Local\\Programs\\Python\\Python35-32\\lib\\site-packages\\rest_framework\\urls.py'> (rest_framework:rest_framework) ^api-auth/>], [<RegexURLResolver <module 'oauth2_provider.urls' from 'C:\\Users\\pc\\AppData\\Local\\Programs\\Python\\Python35-32\\lib\\site-packages\\oauth2_provider\\urls.py'> (None:oauth2_provider) ^o/>], [<RegexURLResolver <module 'vemo_service_apps.auths_api.urls' from 'D:\\vemo\\vemo_service\\vemo_service_apps\\auths_api\\urls.py'> (None:None) ^api/auths/>], [<RegexURLResolver <module 'vemo_service_apps.catalogo_api.urls' from 'D:\\vemo\\vemo_service\\vemo_service_apps\\catalogo_api\\urls.py'> (None:None) ^api/catalogo/>]]}

During handling of the above exception, another exception occurred:

Traceback (most recent call last):
  File "C:\Users\pc\AppData\Local\Programs\Python\Python35-32\lib\site-packages\django\template\base.py", line 885, in _resolve_lookup
    current = current[bit]
TypeError: 'RegexURLResolver' object is not subscriptable

During handling of the above exception, another exception occurred:

Traceback (most recent call last):
  File "C:\Users\pc\AppData\Local\Programs\Python\Python35-32\lib\site-packages\django\template\base.py", line 893, in _resolve_lookup
    current = getattr(current, bit)
AttributeError: 'RegexURLResolver' object has no attribute 'name'

During handling of the above exception, another exception occurred:

Traceback (most recent call last):
  File "C:\Users\pc\AppData\Local\Programs\Python\Python35-32\lib\site-packages\django\template\base.py", line 900, in _resolve_lookup
    current = current[int(bit)]
ValueError: invalid literal for int() with base 10: 'name'

During handling of the above exception, another exception occurred:

Traceback (most recent call last):
  File "C:\Users\pc\AppData\Local\Programs\Python\Python35-32\lib\site-packages\django\template\base.py", line 907, in _resolve_lookup
    (bit, current))  # missing attribute
django.template.base.VariableDoesNotExist: Failed lookup for key [name] in "<RegexURLResolver <module 'vemo_service_apps.catalogo_api.urls' from 'D:\\\\vemo\\\\vemo_service\\\\vemo_service_apps\\\\catalogo_api\\\\urls.py'> (None:None) ^api/catalogo/>"
[2016-11-04 18:16:02] WARNING [django.request:152] Not Found: /favicon.ico
[2016-11-04 18:16:02] WARNING [django.server:131] "GET /favicon.ico HTTP/1.1" 404 2488
[2016-11-04 18:16:11] INFO [django.server:131] "OPTIONS /api/auths/localuserinfo/ HTTP/1.1" 200 0
[2016-11-04 18:16:11] INFO [django.server:131] "OPTIONS /api/auths/usermenu/ HTTP/1.1" 200 0
[2016-11-04 18:16:11] DEBUG [django.db.backends:90] (0.003) SELECT "oauth2_provider_accesstoken"."id", "oauth2_provider_accesstoken"."user_id", "oauth2_provider_accesstoken"."token", "oauth2_provider_accesstoken"."application_id", "oauth2_provider_accesstoken"."expires", "oauth2_provider_accesstoken"."scope", "auths_user"."password", "auths_user"."last_login", "auths_user"."is_superuser", "auths_user"."username", "auths_user"."first_name", "auths_user"."last_name", "auths_user"."email", "auths_user"."is_staff", "auths_user"."is_active", "auths_user"."date_joined", "auths_user"."id", "auths_user"."last_hierarchy_id", "auths_user"."last_module_id", "auths_user"."person_id", "auths_user"."updated_at", "auths_user"."registered_by", "oauth2_provider_application"."id", "oauth2_provider_application"."client_id", "oauth2_provider_application"."user_id", "oauth2_provider_application"."redirect_uris", "oauth2_provider_application"."client_type", "oauth2_provider_application"."authorization_grant_type", "oauth2_provider_application"."client_secret", "oauth2_provider_application"."name", "oauth2_provider_application"."skip_authorization" FROM "oauth2_provider_accesstoken" LEFT OUTER JOIN "auths_user" ON ("oauth2_provider_accesstoken"."user_id" = "auths_user"."id") INNER JOIN "oauth2_provider_application" ON ("oauth2_provider_accesstoken"."application_id" = "oauth2_provider_application"."id") WHERE "oauth2_provider_accesstoken"."token" = 'CqxqZcZN71EyXOvauC8JLnQjgmobZv'; args=('CqxqZcZN71EyXOvauC8JLnQjgmobZv',)
[2016-11-04 18:16:11] DEBUG [django.db.backends:90] (0.003) SELECT "oauth2_provider_accesstoken"."id", "oauth2_provider_accesstoken"."user_id", "oauth2_provider_accesstoken"."token", "oauth2_provider_accesstoken"."application_id", "oauth2_provider_accesstoken"."expires", "oauth2_provider_accesstoken"."scope", "auths_user"."password", "auths_user"."last_login", "auths_user"."is_superuser", "auths_user"."username", "auths_user"."first_name", "auths_user"."last_name", "auths_user"."email", "auths_user"."is_staff", "auths_user"."is_active", "auths_user"."date_joined", "auths_user"."id", "auths_user"."last_hierarchy_id", "auths_user"."last_module_id", "auths_user"."person_id", "auths_user"."updated_at", "auths_user"."registered_by", "oauth2_provider_application"."id", "oauth2_provider_application"."client_id", "oauth2_provider_application"."user_id", "oauth2_provider_application"."redirect_uris", "oauth2_provider_application"."client_type", "oauth2_provider_application"."authorization_grant_type", "oauth2_provider_application"."client_secret", "oauth2_provider_application"."name", "oauth2_provider_application"."skip_authorization" FROM "oauth2_provider_accesstoken" LEFT OUTER JOIN "auths_user" ON ("oauth2_provider_accesstoken"."user_id" = "auths_user"."id") INNER JOIN "oauth2_provider_application" ON ("oauth2_provider_accesstoken"."application_id" = "oauth2_provider_application"."id") WHERE "oauth2_provider_accesstoken"."token" = 'CqxqZcZN71EyXOvauC8JLnQjgmobZv'; args=('CqxqZcZN71EyXOvauC8JLnQjgmobZv',)
[2016-11-04 18:16:11] DEBUG [django.db.backends:90] (0.002) SELECT "auths_menu"."id" FROM "auths_menu" WHERE ("auths_menu"."id" IS NOT NULL AND "auths_menu"."is_active" = 1 AND "auths_menu"."module" = 'BACKEND') ORDER BY "auths_menu"."pos" ASC; args=(True, 'BACKEND')
[2016-11-04 18:16:11] DEBUG [django.db.backends:90] (0.000) SELECT (1) AS "a" FROM "django_session" WHERE "django_session"."session_key" = 'ajxh0nvtslxltr7s0psf0hjzxcqcw8h1' LIMIT 1; args=('ajxh0nvtslxltr7s0psf0hjzxcqcw8h1',)
[2016-11-04 18:16:11] DEBUG [django.db.backends:90] (0.000) BEGIN; args=None
[2016-11-04 18:16:11] DEBUG [django.db.backends:90] (0.004) INSERT INTO "django_session" ("session_key", "session_data", "expire_date") SELECT 'ajxh0nvtslxltr7s0psf0hjzxcqcw8h1', 'NmE3M2Q3NmYwOTU3YjJmZDBjYmQxYTVjODc5MTExNzM3NjY1YzYzNzp7Il9zZXNzaW9uX2V4cGlyeSI6MzB9', '2016-11-04 23:16:41.647647'; args=('ajxh0nvtslxltr7s0psf0hjzxcqcw8h1', 'NmE3M2Q3NmYwOTU3YjJmZDBjYmQxYTVjODc5MTExNzM3NjY1YzYzNzp7Il9zZXNzaW9uX2V4cGlyeSI6MzB9', '2016-11-04 23:16:41.647647')
[2016-11-04 18:16:11] INFO [django.server:131] "GET /api/auths/usermenu/ HTTP/1.1" 200 11
[2016-11-04 18:16:11] DEBUG [django.db.backends:90] (0.098) SELECT "auth_group"."id", "auth_group"."name" FROM "auth_group" INNER JOIN "auths_user_groups" ON ("auth_group"."id" = "auths_user_groups"."group_id") WHERE "auths_user_groups"."user_id" = '3651942c1384420da02bbf9e5eca3faa'; args=('3651942c1384420da02bbf9e5eca3faa',)
[2016-11-04 18:16:11] DEBUG [django.db.backends:90] (0.004) SELECT "auth_permission"."id", "auth_permission"."name", "auth_permission"."content_type_id", "auth_permission"."codename" FROM "auth_permission" INNER JOIN "auths_user_user_permissions" ON ("auth_permission"."id" = "auths_user_user_permissions"."permission_id") INNER JOIN "django_content_type" ON ("auth_permission"."content_type_id" = "django_content_type"."id") WHERE "auths_user_user_permissions"."user_id" = '3651942c1384420da02bbf9e5eca3faa' ORDER BY "django_content_type"."app_label" ASC, "django_content_type"."model" ASC, "auth_permission"."codename" ASC; args=('3651942c1384420da02bbf9e5eca3faa',)
[2016-11-04 18:16:11] INFO [django.server:131] "GET /api/auths/localuserinfo/ HTTP/1.1" 200 496
