[2016-11-09 21:43:48] DEBUG [django.db.backends:90] (0.031) 
            SELECT name, type FROM sqlite_master
            WHERE type in ('table', 'view') AND NOT name='sqlite_sequence'
            ORDER BY name; args=None
[2016-11-09 21:43:48] DEBUG [django.db.backends:90] (0.000) SELECT "django_migrations"."app", "django_migrations"."name" FROM "django_migrations"; args=()
[2016-11-09 21:44:38] INFO [django.server:131] "OPTIONS /api/auths/usermenu/ HTTP/1.1" 200 0
[2016-11-09 21:44:38] INFO [django.server:131] "OPTIONS /api/auths/localuserinfo/ HTTP/1.1" 200 0
[2016-11-09 21:44:38] DEBUG [django.db.backends:90] (0.004) SELECT "oauth2_provider_accesstoken"."id", "oauth2_provider_accesstoken"."user_id", "oauth2_provider_accesstoken"."token", "oauth2_provider_accesstoken"."application_id", "oauth2_provider_accesstoken"."expires", "oauth2_provider_accesstoken"."scope", "auths_user"."password", "auths_user"."last_login", "auths_user"."is_superuser", "auths_user"."username", "auths_user"."first_name", "auths_user"."last_name", "auths_user"."email", "auths_user"."is_staff", "auths_user"."is_active", "auths_user"."date_joined", "auths_user"."id", "auths_user"."last_hierarchy_id", "auths_user"."last_module_id", "auths_user"."person_id", "auths_user"."updated_at", "auths_user"."registered_by", "oauth2_provider_application"."id", "oauth2_provider_application"."client_id", "oauth2_provider_application"."user_id", "oauth2_provider_application"."redirect_uris", "oauth2_provider_application"."client_type", "oauth2_provider_application"."authorization_grant_type", "oauth2_provider_application"."client_secret", "oauth2_provider_application"."name", "oauth2_provider_application"."skip_authorization" FROM "oauth2_provider_accesstoken" LEFT OUTER JOIN "auths_user" ON ("oauth2_provider_accesstoken"."user_id" = "auths_user"."id") INNER JOIN "oauth2_provider_application" ON ("oauth2_provider_accesstoken"."application_id" = "oauth2_provider_application"."id") WHERE "oauth2_provider_accesstoken"."token" = 'CqxqZcZN71EyXOvauC8JLnQjgmobZv'; args=('CqxqZcZN71EyXOvauC8JLnQjgmobZv',)
[2016-11-09 21:44:38] DEBUG [django.db.backends:90] (0.004) SELECT "oauth2_provider_accesstoken"."id", "oauth2_provider_accesstoken"."user_id", "oauth2_provider_accesstoken"."token", "oauth2_provider_accesstoken"."application_id", "oauth2_provider_accesstoken"."expires", "oauth2_provider_accesstoken"."scope", "auths_user"."password", "auths_user"."last_login", "auths_user"."is_superuser", "auths_user"."username", "auths_user"."first_name", "auths_user"."last_name", "auths_user"."email", "auths_user"."is_staff", "auths_user"."is_active", "auths_user"."date_joined", "auths_user"."id", "auths_user"."last_hierarchy_id", "auths_user"."last_module_id", "auths_user"."person_id", "auths_user"."updated_at", "auths_user"."registered_by", "oauth2_provider_application"."id", "oauth2_provider_application"."client_id", "oauth2_provider_application"."user_id", "oauth2_provider_application"."redirect_uris", "oauth2_provider_application"."client_type", "oauth2_provider_application"."authorization_grant_type", "oauth2_provider_application"."client_secret", "oauth2_provider_application"."name", "oauth2_provider_application"."skip_authorization" FROM "oauth2_provider_accesstoken" LEFT OUTER JOIN "auths_user" ON ("oauth2_provider_accesstoken"."user_id" = "auths_user"."id") INNER JOIN "oauth2_provider_application" ON ("oauth2_provider_accesstoken"."application_id" = "oauth2_provider_application"."id") WHERE "oauth2_provider_accesstoken"."token" = 'CqxqZcZN71EyXOvauC8JLnQjgmobZv'; args=('CqxqZcZN71EyXOvauC8JLnQjgmobZv',)
[2016-11-09 21:44:38] WARNING [django.server:131] "GET /api/auths/localuserinfo/ HTTP/1.1" 401 58
[2016-11-09 21:44:38] WARNING [django.server:131] "GET /api/auths/usermenu/ HTTP/1.1" 401 58
[2016-11-09 21:44:40] DEBUG [django.db.backends:90] (0.004) SELECT "auths_menu"."router_json" FROM "auths_menu" ORDER BY "auths_menu"."pos" ASC; args=()
[2016-11-09 21:44:40] INFO [django.server:131] "GET /api/auths/routers/ HTTP/1.1" 200 2
[2016-11-09 21:45:11] DEBUG [django.db.backends:90] (0.003) SELECT "django_session"."session_key", "django_session"."session_data", "django_session"."expire_date" FROM "django_session" WHERE ("django_session"."expire_date" > '2016-11-10 02:45:11.722459' AND "django_session"."session_key" = '4w7mksqqsrmucukumcpvs4jbtn8vd4qw'); args=('2016-11-10 02:45:11.722459', '4w7mksqqsrmucukumcpvs4jbtn8vd4qw')
[2016-11-09 21:45:11] DEBUG [django.db.backends:90] (0.002) SELECT "auths_user"."password", "auths_user"."last_login", "auths_user"."is_superuser", "auths_user"."username", "auths_user"."first_name", "auths_user"."last_name", "auths_user"."email", "auths_user"."is_staff", "auths_user"."is_active", "auths_user"."date_joined", "auths_user"."id", "auths_user"."last_hierarchy_id", "auths_user"."last_module_id", "auths_user"."person_id", "auths_user"."updated_at", "auths_user"."registered_by" FROM "auths_user" WHERE "auths_user"."id" = '3651942c1384420da02bbf9e5eca3faa'; args=('3651942c1384420da02bbf9e5eca3faa',)
[2016-11-09 21:45:12] DEBUG [django.template:929] Exception while resolving variable 'is_popup' in template 'admin/index.html'.
Traceback (most recent call last):
  File "C:\Users\pc\AppData\Local\Programs\Python\Python35-32\lib\site-packages\django\template\base.py", line 885, in _resolve_lookup
    current = current[bit]
  File "C:\Users\pc\AppData\Local\Programs\Python\Python35-32\lib\site-packages\django\template\context.py", line 75, in __getitem__
    raise KeyError(key)
KeyError: 'is_popup'

During handling of the above exception, another exception occurred:

Traceback (most recent call last):
  File "C:\Users\pc\AppData\Local\Programs\Python\Python35-32\lib\site-packages\django\template\base.py", line 891, in _resolve_lookup
    if isinstance(current, BaseContext) and getattr(type(current), bit):
AttributeError: type object 'RequestContext' has no attribute 'is_popup'

During handling of the above exception, another exception occurred:

Traceback (most recent call last):
  File "C:\Users\pc\AppData\Local\Programs\Python\Python35-32\lib\site-packages\django\template\base.py", line 900, in _resolve_lookup
    current = current[int(bit)]
ValueError: invalid literal for int() with base 10: 'is_popup'

During handling of the above exception, another exception occurred:

Traceback (most recent call last):
  File "C:\Users\pc\AppData\Local\Programs\Python\Python35-32\lib\site-packages\django\template\base.py", line 907, in _resolve_lookup
    (bit, current))  # missing attribute
django.template.base.VariableDoesNotExist: Failed lookup for key [is_popup] in "[{'False': False, 'True': True, 'None': None}, {'user': <SimpleLazyObject: <User: admin>>, 'messages': <django.contrib.messages.storage.fallback.FallbackStorage object at 0x0583B0B0>, 'perms': <django.contrib.auth.context_processors.PermWrapper object at 0x01C33870>, 'request': <WSGIRequest: GET '/admin/'>, 'csrf_token': <SimpleLazyObject: <function csrf.<locals>._get_val at 0x058118E8>>, 'DEFAULT_MESSAGE_LEVELS': {'WARNING': 30, 'DEBUG': 10, 'INFO': 20, 'ERROR': 40, 'SUCCESS': 25}}, {}, {'site_url': '/', 'title': <django.utils.functional.lazy.<locals>.__proxy__ object at 0x04411A90>, 'site_header': <django.utils.functional.lazy.<locals>.__proxy__ object at 0x04411A30>, 'LANGUAGE_CODE': 'en-us', 'available_apps': [{'app_url': '/admin/auth/', 'has_module_perms': True, 'app_label': 'auth', 'models': [{'perms': {'add': True, 'change': True, 'delete': True}, 'add_url': '/admin/auth/group/add/', 'object_name': 'Group', 'name': <django.utils.functional.lazy.<locals>.__proxy__ object at 0x0583BCB0>, 'admin_url': '/admin/auth/group/'}, {'perms': {'add': True, 'change': True, 'delete': True}, 'add_url': '/admin/auth/permission/add/', 'object_name': 'Permission', 'name': <django.utils.functional.lazy.<locals>.__proxy__ object at 0x0515FAD0>, 'admin_url': '/admin/auth/permission/'}], 'name': <django.utils.functional.lazy.<locals>.__proxy__ object at 0x0442E670>}, {'app_url': '/admin/auths/', 'has_module_perms': True, 'app_label': 'auths', 'models': [{'perms': {'add': True, 'change': True, 'delete': True}, 'add_url': '/admin/auths/hierarchytype/add/', 'object_name': 'HierarchyType', 'name': <django.utils.functional.lazy.<locals>.__proxy__ object at 0x0583B5D0>, 'admin_url': '/admin/auths/hierarchytype/'}, {'perms': {'add': True, 'change': True, 'delete': True}, 'add_url': '/admin/auths/hierarchy/add/', 'object_name': 'Hierarchy', 'name': <django.utils.functional.lazy.<locals>.__proxy__ object at 0x0583BEB0>, 'admin_url': '/admin/auths/hierarchy/'}, {'perms': {'add': True, 'change': True, 'delete': True}, 'add_url': '/admin/auths/menu/add/', 'object_name': 'Menu', 'name': <django.utils.functional.lazy.<locals>.__proxy__ object at 0x0583BCF0>, 'admin_url': '/admin/auths/menu/'}, {'perms': {'add': True, 'change': True, 'delete': True}, 'add_url': '/admin/auths/person/add/', 'object_name': 'Person', 'name': <django.utils.functional.lazy.<locals>.__proxy__ object at 0x0515F790>, 'admin_url': '/admin/auths/person/'}, {'perms': {'add': True, 'change': True, 'delete': True}, 'add_url': '/admin/auths/userhierarchygroup/add/', 'object_name': 'UserHierarchyGroup', 'name': <django.utils.functional.lazy.<locals>.__proxy__ object at 0x0515FC90>, 'admin_url': '/admin/auths/userhierarchygroup/'}, {'perms': {'add': True, 'change': True, 'delete': True}, 'add_url': '/admin/auths/userhierarchypermission/add/', 'object_name': 'UserHierarchyPermission', 'name': <django.utils.functional.lazy.<locals>.__proxy__ object at 0x0583B730>, 'admin_url': '/admin/auths/userhierarchypermission/'}, {'perms': {'add': True, 'change': True, 'delete': True}, 'add_url': '/admin/auths/user/add/', 'object_name': 'User', 'name': <django.utils.functional.lazy.<locals>.__proxy__ object at 0x0583B570>, 'admin_url': '/admin/auths/user/'}], 'name': 'Auths'}, {'app_url': '/admin/catalogo/', 'has_module_perms': True, 'app_label': 'catalogo', 'models': [{'perms': {'add': True, 'change': True, 'delete': True}, 'add_url': '/admin/catalogo/autor/add/', 'object_name': 'Autor', 'name': 'Autores', 'admin_url': '/admin/catalogo/autor/'}, {'perms': {'add': True, 'change': True, 'delete': True}, 'add_url': '/admin/catalogo/categoria/add/', 'object_name': 'Categoria', 'name': 'Categorias', 'admin_url': '/admin/catalogo/categoria/'}, {'perms': {'add': True, 'change': True, 'delete': True}, 'add_url': '/admin/catalogo/libro/add/', 'object_name': 'Libro', 'name': 'Libros', 'admin_url': '/admin/catalogo/libro/'}], 'name': 'Catalogo'}, {'app_url': '/admin/contenttypes/', 'has_module_perms': True, 'app_label': 'contenttypes', 'models': [{'perms': {'add': True, 'change': True, 'delete': True}, 'add_url': '/admin/contenttypes/contenttype/add/', 'object_name': 'ContentType', 'name': <django.utils.functional.lazy.<locals>.__proxy__ object at 0x0515F7B0>, 'admin_url': '/admin/contenttypes/contenttype/'}], 'name': <django.utils.functional.lazy.<locals>.__proxy__ object at 0x0442E450>}, {'app_url': '/admin/oauth2_provider/', 'has_module_perms': True, 'app_label': 'oauth2_provider', 'models': [{'perms': {'add': True, 'change': True, 'delete': True}, 'add_url': '/admin/oauth2_provider/accesstoken/add/', 'object_name': 'AccessToken', 'name': <django.utils.functional.lazy.<locals>.__proxy__ object at 0x0515F770>, 'admin_url': '/admin/oauth2_provider/accesstoken/'}, {'perms': {'add': True, 'change': True, 'delete': True}, 'add_url': '/admin/oauth2_provider/application/add/', 'object_name': 'Application', 'name': <django.utils.functional.lazy.<locals>.__proxy__ object at 0x0515FCD0>, 'admin_url': '/admin/oauth2_provider/application/'}, {'perms': {'add': True, 'change': True, 'delete': True}, 'add_url': '/admin/oauth2_provider/grant/add/', 'object_name': 'Grant', 'name': <django.utils.functional.lazy.<locals>.__proxy__ object at 0x0515F810>, 'admin_url': '/admin/oauth2_provider/grant/'}, {'perms': {'add': True, 'change': True, 'delete': True}, 'add_url': '/admin/oauth2_provider/refreshtoken/add/', 'object_name': 'RefreshToken', 'name': <django.utils.functional.lazy.<locals>.__proxy__ object at 0x0583BEF0>, 'admin_url': '/admin/oauth2_provider/refreshtoken/'}], 'name': 'Django OAuth Toolkit'}], 'LANGUAGE_BIDI': False, 'has_permission': True, 'app_list': [{'app_url': '/admin/auth/', 'has_module_perms': True, 'app_label': 'auth', 'models': [{'perms': {'add': True, 'change': True, 'delete': True}, 'add_url': '/admin/auth/group/add/', 'object_name': 'Group', 'name': <django.utils.functional.lazy.<locals>.__proxy__ object at 0x0583B9F0>, 'admin_url': '/admin/auth/group/'}, {'perms': {'add': True, 'change': True, 'delete': True}, 'add_url': '/admin/auth/permission/add/', 'object_name': 'Permission', 'name': <django.utils.functional.lazy.<locals>.__proxy__ object at 0x0517EBD0>, 'admin_url': '/admin/auth/permission/'}], 'name': <django.utils.functional.lazy.<locals>.__proxy__ object at 0x0442E670>}, {'app_url': '/admin/auths/', 'has_module_perms': True, 'app_label': 'auths', 'models': [{'perms': {'add': True, 'change': True, 'delete': True}, 'add_url': '/admin/auths/hierarchytype/add/', 'object_name': 'HierarchyType', 'name': <django.utils.functional.lazy.<locals>.__proxy__ object at 0x0517EBF0>, 'admin_url': '/admin/auths/hierarchytype/'}, {'perms': {'add': True, 'change': True, 'delete': True}, 'add_url': '/admin/auths/hierarchy/add/', 'object_name': 'Hierarchy', 'name': <django.utils.functional.lazy.<locals>.__proxy__ object at 0x05150AB0>, 'admin_url': '/admin/auths/hierarchy/'}, {'perms': {'add': True, 'change': True, 'delete': True}, 'add_url': '/admin/auths/menu/add/', 'object_name': 'Menu', 'name': <django.utils.functional.lazy.<locals>.__proxy__ object at 0x0517E910>, 'admin_url': '/admin/auths/menu/'}, {'perms': {'add': True, 'change': True, 'delete': True}, 'add_url': '/admin/auths/person/add/', 'object_name': 'Person', 'name': <django.utils.functional.lazy.<locals>.__proxy__ object at 0x0517E8F0>, 'admin_url': '/admin/auths/person/'}, {'perms': {'add': True, 'change': True, 'delete': True}, 'add_url': '/admin/auths/userhierarchygroup/add/', 'object_name': 'UserHierarchyGroup', 'name': <django.utils.functional.lazy.<locals>.__proxy__ object at 0x0517ECB0>, 'admin_url': '/admin/auths/userhierarchygroup/'}, {'perms': {'add': True, 'change': True, 'delete': True}, 'add_url': '/admin/auths/userhierarchypermission/add/', 'object_name': 'UserHierarchyPermission', 'name': <django.utils.functional.lazy.<locals>.__proxy__ object at 0x0517EB70>, 'admin_url': '/admin/auths/userhierarchypermission/'}, {'perms': {'add': True, 'change': True, 'delete': True}, 'add_url': '/admin/auths/user/add/', 'object_name': 'User', 'name': <django.utils.functional.lazy.<locals>.__proxy__ object at 0x05150B70>, 'admin_url': '/admin/auths/user/'}], 'name': 'Auths'}, {'app_url': '/admin/catalogo/', 'has_module_perms': True, 'app_label': 'catalogo', 'models': [{'perms': {'add': True, 'change': True, 'delete': True}, 'add_url': '/admin/catalogo/autor/add/', 'object_name': 'Autor', 'name': 'Autores', 'admin_url': '/admin/catalogo/autor/'}, {'perms': {'add': True, 'change': True, 'delete': True}, 'add_url': '/admin/catalogo/categoria/add/', 'object_name': 'Categoria', 'name': 'Categorias', 'admin_url': '/admin/catalogo/categoria/'}, {'perms': {'add': True, 'change': True, 'delete': True}, 'add_url': '/admin/catalogo/libro/add/', 'object_name': 'Libro', 'name': 'Libros', 'admin_url': '/admin/catalogo/libro/'}], 'name': 'Catalogo'}, {'app_url': '/admin/contenttypes/', 'has_module_perms': True, 'app_label': 'contenttypes', 'models': [{'perms': {'add': True, 'change': True, 'delete': True}, 'add_url': '/admin/contenttypes/contenttype/add/', 'object_name': 'ContentType', 'name': <django.utils.functional.lazy.<locals>.__proxy__ object at 0x0517EC10>, 'admin_url': '/admin/contenttypes/contenttype/'}], 'name': <django.utils.functional.lazy.<locals>.__proxy__ object at 0x0442E450>}, {'app_url': '/admin/oauth2_provider/', 'has_module_perms': True, 'app_label': 'oauth2_provider', 'models': [{'perms': {'add': True, 'change': True, 'delete': True}, 'add_url': '/admin/oauth2_provider/accesstoken/add/', 'object_name': 'AccessToken', 'name': <django.utils.functional.lazy.<locals>.__proxy__ object at 0x0517EE50>, 'admin_url': '/admin/oauth2_provider/accesstoken/'}, {'perms': {'add': True, 'change': True, 'delete': True}, 'add_url': '/admin/oauth2_provider/application/add/', 'object_name': 'Application', 'name': <django.utils.functional.lazy.<locals>.__proxy__ object at 0x0517EBB0>, 'admin_url': '/admin/oauth2_provider/application/'}, {'perms': {'add': True, 'change': True, 'delete': True}, 'add_url': '/admin/oauth2_provider/grant/add/', 'object_name': 'Grant', 'name': <django.utils.functional.lazy.<locals>.__proxy__ object at 0x0517EB50>, 'admin_url': '/admin/oauth2_provider/grant/'}, {'perms': {'add': True, 'change': True, 'delete': True}, 'add_url': '/admin/oauth2_provider/refreshtoken/add/', 'object_name': 'RefreshToken', 'name': <django.utils.functional.lazy.<locals>.__proxy__ object at 0x0517EA50>, 'admin_url': '/admin/oauth2_provider/refreshtoken/'}], 'name': 'Django OAuth Toolkit'}], 'site_title': <django.utils.functional.lazy.<locals>.__proxy__ object at 0x043FFB50>}]"
[2016-11-09 21:45:12] DEBUG [django.template:929] Exception while resolving variable 'is_popup' in template 'admin/index.html'.
Traceback (most recent call last):
  File "C:\Users\pc\AppData\Local\Programs\Python\Python35-32\lib\site-packages\django\template\base.py", line 885, in _resolve_lookup
    current = current[bit]
  File "C:\Users\pc\AppData\Local\Programs\Python\Python35-32\lib\site-packages\django\template\context.py", line 75, in __getitem__
    raise KeyError(key)
KeyError: 'is_popup'

During handling of the above exception, another exception occurred:

Traceback (most recent call last):
  File "C:\Users\pc\AppData\Local\Programs\Python\Python35-32\lib\site-packages\django\template\base.py", line 891, in _resolve_lookup
    if isinstance(current, BaseContext) and getattr(type(current), bit):
AttributeError: type object 'RequestContext' has no attribute 'is_popup'

During handling of the above exception, another exception occurred:

Traceback (most recent call last):
  File "C:\Users\pc\AppData\Local\Programs\Python\Python35-32\lib\site-packages\django\template\base.py", line 900, in _resolve_lookup
    current = current[int(bit)]
ValueError: invalid literal for int() with base 10: 'is_popup'

During handling of the above exception, another exception occurred:

Traceback (most recent call last):
  File "C:\Users\pc\AppData\Local\Programs\Python\Python35-32\lib\site-packages\django\template\base.py", line 907, in _resolve_lookup
    (bit, current))  # missing attribute
django.template.base.VariableDoesNotExist: Failed lookup for key [is_popup] in "[{'False': False, 'True': True, 'None': None}, {'user': <SimpleLazyObject: <User: admin>>, 'messages': <django.contrib.messages.storage.fallback.FallbackStorage object at 0x0583B0B0>, 'perms': <django.contrib.auth.context_processors.PermWrapper object at 0x01C33870>, 'request': <WSGIRequest: GET '/admin/'>, 'csrf_token': <SimpleLazyObject: <function csrf.<locals>._get_val at 0x058118E8>>, 'DEFAULT_MESSAGE_LEVELS': {'WARNING': 30, 'DEBUG': 10, 'INFO': 20, 'ERROR': 40, 'SUCCESS': 25}}, {}, {'site_url': '/', 'title': <django.utils.functional.lazy.<locals>.__proxy__ object at 0x04411A90>, 'site_header': <django.utils.functional.lazy.<locals>.__proxy__ object at 0x04411A30>, 'LANGUAGE_CODE': 'en-us', 'available_apps': [{'app_url': '/admin/auth/', 'has_module_perms': True, 'app_label': 'auth', 'models': [{'perms': {'add': True, 'change': True, 'delete': True}, 'add_url': '/admin/auth/group/add/', 'object_name': 'Group', 'name': <django.utils.functional.lazy.<locals>.__proxy__ object at 0x0583BCB0>, 'admin_url': '/admin/auth/group/'}, {'perms': {'add': True, 'change': True, 'delete': True}, 'add_url': '/admin/auth/permission/add/', 'object_name': 'Permission', 'name': <django.utils.functional.lazy.<locals>.__proxy__ object at 0x0515FAD0>, 'admin_url': '/admin/auth/permission/'}], 'name': <django.utils.functional.lazy.<locals>.__proxy__ object at 0x0442E670>}, {'app_url': '/admin/auths/', 'has_module_perms': True, 'app_label': 'auths', 'models': [{'perms': {'add': True, 'change': True, 'delete': True}, 'add_url': '/admin/auths/hierarchytype/add/', 'object_name': 'HierarchyType', 'name': <django.utils.functional.lazy.<locals>.__proxy__ object at 0x0583B5D0>, 'admin_url': '/admin/auths/hierarchytype/'}, {'perms': {'add': True, 'change': True, 'delete': True}, 'add_url': '/admin/auths/hierarchy/add/', 'object_name': 'Hierarchy', 'name': <django.utils.functional.lazy.<locals>.__proxy__ object at 0x0583BEB0>, 'admin_url': '/admin/auths/hierarchy/'}, {'perms': {'add': True, 'change': True, 'delete': True}, 'add_url': '/admin/auths/menu/add/', 'object_name': 'Menu', 'name': <django.utils.functional.lazy.<locals>.__proxy__ object at 0x0583BCF0>, 'admin_url': '/admin/auths/menu/'}, {'perms': {'add': True, 'change': True, 'delete': True}, 'add_url': '/admin/auths/person/add/', 'object_name': 'Person', 'name': <django.utils.functional.lazy.<locals>.__proxy__ object at 0x0515F790>, 'admin_url': '/admin/auths/person/'}, {'perms': {'add': True, 'change': True, 'delete': True}, 'add_url': '/admin/auths/userhierarchygroup/add/', 'object_name': 'UserHierarchyGroup', 'name': <django.utils.functional.lazy.<locals>.__proxy__ object at 0x0515FC90>, 'admin_url': '/admin/auths/userhierarchygroup/'}, {'perms': {'add': True, 'change': True, 'delete': True}, 'add_url': '/admin/auths/userhierarchypermission/add/', 'object_name': 'UserHierarchyPermission', 'name': <django.utils.functional.lazy.<locals>.__proxy__ object at 0x0583B730>, 'admin_url': '/admin/auths/userhierarchypermission/'}, {'perms': {'add': True, 'change': True, 'delete': True}, 'add_url': '/admin/auths/user/add/', 'object_name': 'User', 'name': <django.utils.functional.lazy.<locals>.__proxy__ object at 0x0583B570>, 'admin_url': '/admin/auths/user/'}], 'name': 'Auths'}, {'app_url': '/admin/catalogo/', 'has_module_perms': True, 'app_label': 'catalogo', 'models': [{'perms': {'add': True, 'change': True, 'delete': True}, 'add_url': '/admin/catalogo/autor/add/', 'object_name': 'Autor', 'name': 'Autores', 'admin_url': '/admin/catalogo/autor/'}, {'perms': {'add': True, 'change': True, 'delete': True}, 'add_url': '/admin/catalogo/categoria/add/', 'object_name': 'Categoria', 'name': 'Categorias', 'admin_url': '/admin/catalogo/categoria/'}, {'perms': {'add': True, 'change': True, 'delete': True}, 'add_url': '/admin/catalogo/libro/add/', 'object_name': 'Libro', 'name': 'Libros', 'admin_url': '/admin/catalogo/libro/'}], 'name': 'Catalogo'}, {'app_url': '/admin/contenttypes/', 'has_module_perms': True, 'app_label': 'contenttypes', 'models': [{'perms': {'add': True, 'change': True, 'delete': True}, 'add_url': '/admin/contenttypes/contenttype/add/', 'object_name': 'ContentType', 'name': <django.utils.functional.lazy.<locals>.__proxy__ object at 0x0515F7B0>, 'admin_url': '/admin/contenttypes/contenttype/'}], 'name': <django.utils.functional.lazy.<locals>.__proxy__ object at 0x0442E450>}, {'app_url': '/admin/oauth2_provider/', 'has_module_perms': True, 'app_label': 'oauth2_provider', 'models': [{'perms': {'add': True, 'change': True, 'delete': True}, 'add_url': '/admin/oauth2_provider/accesstoken/add/', 'object_name': 'AccessToken', 'name': <django.utils.functional.lazy.<locals>.__proxy__ object at 0x0515F770>, 'admin_url': '/admin/oauth2_provider/accesstoken/'}, {'perms': {'add': True, 'change': True, 'delete': True}, 'add_url': '/admin/oauth2_provider/application/add/', 'object_name': 'Application', 'name': <django.utils.functional.lazy.<locals>.__proxy__ object at 0x0515FCD0>, 'admin_url': '/admin/oauth2_provider/application/'}, {'perms': {'add': True, 'change': True, 'delete': True}, 'add_url': '/admin/oauth2_provider/grant/add/', 'object_name': 'Grant', 'name': <django.utils.functional.lazy.<locals>.__proxy__ object at 0x0515F810>, 'admin_url': '/admin/oauth2_provider/grant/'}, {'perms': {'add': True, 'change': True, 'delete': True}, 'add_url': '/admin/oauth2_provider/refreshtoken/add/', 'object_name': 'RefreshToken', 'name': <django.utils.functional.lazy.<locals>.__proxy__ object at 0x0583BEF0>, 'admin_url': '/admin/oauth2_provider/refreshtoken/'}], 'name': 'Django OAuth Toolkit'}], 'LANGUAGE_BIDI': False, 'has_permission': True, 'app_list': [{'app_url': '/admin/auth/', 'has_module_perms': True, 'app_label': 'auth', 'models': [{'perms': {'add': True, 'change': True, 'delete': True}, 'add_url': '/admin/auth/group/add/', 'object_name': 'Group', 'name': <django.utils.functional.lazy.<locals>.__proxy__ object at 0x0583B9F0>, 'admin_url': '/admin/auth/group/'}, {'perms': {'add': True, 'change': True, 'delete': True}, 'add_url': '/admin/auth/permission/add/', 'object_name': 'Permission', 'name': <django.utils.functional.lazy.<locals>.__proxy__ object at 0x0517EBD0>, 'admin_url': '/admin/auth/permission/'}], 'name': <django.utils.functional.lazy.<locals>.__proxy__ object at 0x0442E670>}, {'app_url': '/admin/auths/', 'has_module_perms': True, 'app_label': 'auths', 'models': [{'perms': {'add': True, 'change': True, 'delete': True}, 'add_url': '/admin/auths/hierarchytype/add/', 'object_name': 'HierarchyType', 'name': <django.utils.functional.lazy.<locals>.__proxy__ object at 0x0517EBF0>, 'admin_url': '/admin/auths/hierarchytype/'}, {'perms': {'add': True, 'change': True, 'delete': True}, 'add_url': '/admin/auths/hierarchy/add/', 'object_name': 'Hierarchy', 'name': <django.utils.functional.lazy.<locals>.__proxy__ object at 0x05150AB0>, 'admin_url': '/admin/auths/hierarchy/'}, {'perms': {'add': True, 'change': True, 'delete': True}, 'add_url': '/admin/auths/menu/add/', 'object_name': 'Menu', 'name': <django.utils.functional.lazy.<locals>.__proxy__ object at 0x0517E910>, 'admin_url': '/admin/auths/menu/'}, {'perms': {'add': True, 'change': True, 'delete': True}, 'add_url': '/admin/auths/person/add/', 'object_name': 'Person', 'name': <django.utils.functional.lazy.<locals>.__proxy__ object at 0x0517E8F0>, 'admin_url': '/admin/auths/person/'}, {'perms': {'add': True, 'change': True, 'delete': True}, 'add_url': '/admin/auths/userhierarchygroup/add/', 'object_name': 'UserHierarchyGroup', 'name': <django.utils.functional.lazy.<locals>.__proxy__ object at 0x0517ECB0>, 'admin_url': '/admin/auths/userhierarchygroup/'}, {'perms': {'add': True, 'change': True, 'delete': True}, 'add_url': '/admin/auths/userhierarchypermission/add/', 'object_name': 'UserHierarchyPermission', 'name': <django.utils.functional.lazy.<locals>.__proxy__ object at 0x0517EB70>, 'admin_url': '/admin/auths/userhierarchypermission/'}, {'perms': {'add': True, 'change': True, 'delete': True}, 'add_url': '/admin/auths/user/add/', 'object_name': 'User', 'name': <django.utils.functional.lazy.<locals>.__proxy__ object at 0x05150B70>, 'admin_url': '/admin/auths/user/'}], 'name': 'Auths'}, {'app_url': '/admin/catalogo/', 'has_module_perms': True, 'app_label': 'catalogo', 'models': [{'perms': {'add': True, 'change': True, 'delete': True}, 'add_url': '/admin/catalogo/autor/add/', 'object_name': 'Autor', 'name': 'Autores', 'admin_url': '/admin/catalogo/autor/'}, {'perms': {'add': True, 'change': True, 'delete': True}, 'add_url': '/admin/catalogo/categoria/add/', 'object_name': 'Categoria', 'name': 'Categorias', 'admin_url': '/admin/catalogo/categoria/'}, {'perms': {'add': True, 'change': True, 'delete': True}, 'add_url': '/admin/catalogo/libro/add/', 'object_name': 'Libro', 'name': 'Libros', 'admin_url': '/admin/catalogo/libro/'}], 'name': 'Catalogo'}, {'app_url': '/admin/contenttypes/', 'has_module_perms': True, 'app_label': 'contenttypes', 'models': [{'perms': {'add': True, 'change': True, 'delete': True}, 'add_url': '/admin/contenttypes/contenttype/add/', 'object_name': 'ContentType', 'name': <django.utils.functional.lazy.<locals>.__proxy__ object at 0x0517EC10>, 'admin_url': '/admin/contenttypes/contenttype/'}], 'name': <django.utils.functional.lazy.<locals>.__proxy__ object at 0x0442E450>}, {'app_url': '/admin/oauth2_provider/', 'has_module_perms': True, 'app_label': 'oauth2_provider', 'models': [{'perms': {'add': True, 'change': True, 'delete': True}, 'add_url': '/admin/oauth2_provider/accesstoken/add/', 'object_name': 'AccessToken', 'name': <django.utils.functional.lazy.<locals>.__proxy__ object at 0x0517EE50>, 'admin_url': '/admin/oauth2_provider/accesstoken/'}, {'perms': {'add': True, 'change': True, 'delete': True}, 'add_url': '/admin/oauth2_provider/application/add/', 'object_name': 'Application', 'name': <django.utils.functional.lazy.<locals>.__proxy__ object at 0x0517EBB0>, 'admin_url': '/admin/oauth2_provider/application/'}, {'perms': {'add': True, 'change': True, 'delete': True}, 'add_url': '/admin/oauth2_provider/grant/add/', 'object_name': 'Grant', 'name': <django.utils.functional.lazy.<locals>.__proxy__ object at 0x0517EB50>, 'admin_url': '/admin/oauth2_provider/grant/'}, {'perms': {'add': True, 'change': True, 'delete': True}, 'add_url': '/admin/oauth2_provider/refreshtoken/add/', 'object_name': 'RefreshToken', 'name': <django.utils.functional.lazy.<locals>.__proxy__ object at 0x0517EA50>, 'admin_url': '/admin/oauth2_provider/refreshtoken/'}], 'name': 'Django OAuth Toolkit'}], 'site_title': <django.utils.functional.lazy.<locals>.__proxy__ object at 0x043FFB50>}]"
[2016-11-09 21:45:12] DEBUG [django.db.backends:90] (0.001) SELECT "django_admin_log"."id", "django_admin_log"."action_time", "django_admin_log"."user_id", "django_admin_log"."content_type_id", "django_admin_log"."object_id", "django_admin_log"."object_repr", "django_admin_log"."action_flag", "django_admin_log"."change_message", "auths_user"."password", "auths_user"."last_login", "auths_user"."is_superuser", "auths_user"."username", "auths_user"."first_name", "auths_user"."last_name", "auths_user"."email", "auths_user"."is_staff", "auths_user"."is_active", "auths_user"."date_joined", "auths_user"."id", "auths_user"."last_hierarchy_id", "auths_user"."last_module_id", "auths_user"."person_id", "auths_user"."updated_at", "auths_user"."registered_by", "django_content_type"."id", "django_content_type"."app_label", "django_content_type"."model" FROM "django_admin_log" INNER JOIN "auths_user" ON ("django_admin_log"."user_id" = "auths_user"."id") LEFT OUTER JOIN "django_content_type" ON ("django_admin_log"."content_type_id" = "django_content_type"."id") WHERE "django_admin_log"."user_id" = '3651942c1384420da02bbf9e5eca3faa' ORDER BY "django_admin_log"."action_time" DESC LIMIT 10; args=('3651942c1384420da02bbf9e5eca3faa',)
[2016-11-09 21:45:12] INFO [django.server:131] "GET /admin/ HTTP/1.1" 200 10333
[2016-11-09 21:45:12] INFO [django.server:131] "GET /static/admin/css/base.css HTTP/1.1" 304 0
[2016-11-09 21:45:12] INFO [django.server:131] "GET /static/admin/css/dashboard.css HTTP/1.1" 304 0
[2016-11-09 21:45:12] INFO [django.server:131] "GET /static/admin/css/fonts.css HTTP/1.1" 304 0
[2016-11-09 21:45:12] INFO [django.server:131] "GET /static/admin/img/icon-addlink.svg HTTP/1.1" 304 0
[2016-11-09 21:45:12] INFO [django.server:131] "GET /static/admin/img/icon-changelink.svg HTTP/1.1" 304 0
[2016-11-09 21:45:12] INFO [django.server:131] "GET /static/admin/fonts/Roboto-Regular-webfont.woff HTTP/1.1" 304 0
[2016-11-09 21:45:12] INFO [django.server:131] "GET /static/admin/fonts/Roboto-Light-webfont.woff HTTP/1.1" 304 0
[2016-11-09 21:45:12] INFO [django.server:131] "GET /static/admin/fonts/Roboto-Bold-webfont.woff HTTP/1.1" 304 0
[2016-11-09 21:45:12] DEBUG [django.template:929] Exception while resolving variable 'name' in template 'unknown'.
Traceback (most recent call last):
  File "C:\Users\pc\AppData\Local\Programs\Python\Python35-32\lib\site-packages\django\core\handlers\exception.py", line 39, in inner
    response = get_response(request)
  File "C:\Users\pc\AppData\Local\Programs\Python\Python35-32\lib\site-packages\django\core\handlers\base.py", line 172, in _get_response
    resolver_match = resolver.resolve(request.path_info)
  File "C:\Users\pc\AppData\Local\Programs\Python\Python35-32\lib\site-packages\django\urls\resolvers.py", line 300, in resolve
    raise Resolver404({'tried': tried, 'path': new_path})
django.urls.exceptions.Resolver404: {'tried': [[<RegexURLResolver <RegexURLPattern list> (admin:admin) ^admin/>], [<RegexURLResolver <module 'django.contrib.admindocs.urls' from 'C:\\Users\\pc\\AppData\\Local\\Programs\\Python\\Python35-32\\lib\\site-packages\\django\\contrib\\admindocs\\urls.py'> (None:None) ^admin/doc/>], [<RegexURLResolver <module 'rest_framework.urls' from 'C:\\Users\\pc\\AppData\\Local\\Programs\\Python\\Python35-32\\lib\\site-packages\\rest_framework\\urls.py'> (rest_framework:rest_framework) ^api-auth/>], [<RegexURLResolver <module 'oauth2_provider.urls' from 'C:\\Users\\pc\\AppData\\Local\\Programs\\Python\\Python35-32\\lib\\site-packages\\oauth2_provider\\urls.py'> (None:oauth2_provider) ^o/>], [<RegexURLResolver <module 'vemo_service_apps.auths_api.urls' from 'D:\\vemo\\vemo_service\\vemo_service_apps\\auths_api\\urls.py'> (None:None) ^api/auths/>], [<RegexURLResolver <module 'vemo_service_apps.catalogo_api.urls' from 'D:\\vemo\\vemo_service\\vemo_service_apps\\catalogo_api\\urls.py'> (None:None) ^api/catalogo/>]], 'path': 'favicon.ico'}

During handling of the above exception, another exception occurred:

Traceback (most recent call last):
  File "C:\Users\pc\AppData\Local\Programs\Python\Python35-32\lib\site-packages\django\template\base.py", line 885, in _resolve_lookup
    current = current[bit]
TypeError: 'RegexURLResolver' object is not subscriptable

During handling of the above exception, another exception occurred:

Traceback (most recent call last):
  File "C:\Users\pc\AppData\Local\Programs\Python\Python35-32\lib\site-packages\django\template\base.py", line 893, in _resolve_lookup
    current = getattr(current, bit)
AttributeError: 'RegexURLResolver' object has no attribute 'name'

During handling of the above exception, another exception occurred:

Traceback (most recent call last):
  File "C:\Users\pc\AppData\Local\Programs\Python\Python35-32\lib\site-packages\django\template\base.py", line 900, in _resolve_lookup
    current = current[int(bit)]
ValueError: invalid literal for int() with base 10: 'name'

During handling of the above exception, another exception occurred:

Traceback (most recent call last):
  File "C:\Users\pc\AppData\Local\Programs\Python\Python35-32\lib\site-packages\django\template\base.py", line 907, in _resolve_lookup
    (bit, current))  # missing attribute
django.template.base.VariableDoesNotExist: Failed lookup for key [name] in '<RegexURLResolver <RegexURLPattern list> (admin:admin) ^admin/>'
[2016-11-09 21:45:12] DEBUG [django.template:929] Exception while resolving variable 'name' in template 'unknown'.
Traceback (most recent call last):
  File "C:\Users\pc\AppData\Local\Programs\Python\Python35-32\lib\site-packages\django\core\handlers\exception.py", line 39, in inner
    response = get_response(request)
  File "C:\Users\pc\AppData\Local\Programs\Python\Python35-32\lib\site-packages\django\core\handlers\base.py", line 172, in _get_response
    resolver_match = resolver.resolve(request.path_info)
  File "C:\Users\pc\AppData\Local\Programs\Python\Python35-32\lib\site-packages\django\urls\resolvers.py", line 300, in resolve
    raise Resolver404({'tried': tried, 'path': new_path})
django.urls.exceptions.Resolver404: {'tried': [[<RegexURLResolver <RegexURLPattern list> (admin:admin) ^admin/>], [<RegexURLResolver <module 'django.contrib.admindocs.urls' from 'C:\\Users\\pc\\AppData\\Local\\Programs\\Python\\Python35-32\\lib\\site-packages\\django\\contrib\\admindocs\\urls.py'> (None:None) ^admin/doc/>], [<RegexURLResolver <module 'rest_framework.urls' from 'C:\\Users\\pc\\AppData\\Local\\Programs\\Python\\Python35-32\\lib\\site-packages\\rest_framework\\urls.py'> (rest_framework:rest_framework) ^api-auth/>], [<RegexURLResolver <module 'oauth2_provider.urls' from 'C:\\Users\\pc\\AppData\\Local\\Programs\\Python\\Python35-32\\lib\\site-packages\\oauth2_provider\\urls.py'> (None:oauth2_provider) ^o/>], [<RegexURLResolver <module 'vemo_service_apps.auths_api.urls' from 'D:\\vemo\\vemo_service\\vemo_service_apps\\auths_api\\urls.py'> (None:None) ^api/auths/>], [<RegexURLResolver <module 'vemo_service_apps.catalogo_api.urls' from 'D:\\vemo\\vemo_service\\vemo_service_apps\\catalogo_api\\urls.py'> (None:None) ^api/catalogo/>]], 'path': 'favicon.ico'}

During handling of the above exception, another exception occurred:

Traceback (most recent call last):
  File "C:\Users\pc\AppData\Local\Programs\Python\Python35-32\lib\site-packages\django\template\base.py", line 885, in _resolve_lookup
    current = current[bit]
TypeError: 'RegexURLResolver' object is not subscriptable

During handling of the above exception, another exception occurred:

Traceback (most recent call last):
  File "C:\Users\pc\AppData\Local\Programs\Python\Python35-32\lib\site-packages\django\template\base.py", line 893, in _resolve_lookup
    current = getattr(current, bit)
AttributeError: 'RegexURLResolver' object has no attribute 'name'

During handling of the above exception, another exception occurred:

Traceback (most recent call last):
  File "C:\Users\pc\AppData\Local\Programs\Python\Python35-32\lib\site-packages\django\template\base.py", line 900, in _resolve_lookup
    current = current[int(bit)]
ValueError: invalid literal for int() with base 10: 'name'

During handling of the above exception, another exception occurred:

Traceback (most recent call last):
  File "C:\Users\pc\AppData\Local\Programs\Python\Python35-32\lib\site-packages\django\template\base.py", line 907, in _resolve_lookup
    (bit, current))  # missing attribute
django.template.base.VariableDoesNotExist: Failed lookup for key [name] in "<RegexURLResolver <module 'django.contrib.admindocs.urls' from 'C:\\\\Users\\\\pc\\\\AppData\\\\Local\\\\Programs\\\\Python\\\\Python35-32\\\\lib\\\\site-packages\\\\django\\\\contrib\\\\admindocs\\\\urls.py'> (None:None) ^admin/doc/>"
[2016-11-09 21:45:12] DEBUG [django.template:929] Exception while resolving variable 'name' in template 'unknown'.
Traceback (most recent call last):
  File "C:\Users\pc\AppData\Local\Programs\Python\Python35-32\lib\site-packages\django\core\handlers\exception.py", line 39, in inner
    response = get_response(request)
  File "C:\Users\pc\AppData\Local\Programs\Python\Python35-32\lib\site-packages\django\core\handlers\base.py", line 172, in _get_response
    resolver_match = resolver.resolve(request.path_info)
  File "C:\Users\pc\AppData\Local\Programs\Python\Python35-32\lib\site-packages\django\urls\resolvers.py", line 300, in resolve
    raise Resolver404({'tried': tried, 'path': new_path})
django.urls.exceptions.Resolver404: {'tried': [[<RegexURLResolver <RegexURLPattern list> (admin:admin) ^admin/>], [<RegexURLResolver <module 'django.contrib.admindocs.urls' from 'C:\\Users\\pc\\AppData\\Local\\Programs\\Python\\Python35-32\\lib\\site-packages\\django\\contrib\\admindocs\\urls.py'> (None:None) ^admin/doc/>], [<RegexURLResolver <module 'rest_framework.urls' from 'C:\\Users\\pc\\AppData\\Local\\Programs\\Python\\Python35-32\\lib\\site-packages\\rest_framework\\urls.py'> (rest_framework:rest_framework) ^api-auth/>], [<RegexURLResolver <module 'oauth2_provider.urls' from 'C:\\Users\\pc\\AppData\\Local\\Programs\\Python\\Python35-32\\lib\\site-packages\\oauth2_provider\\urls.py'> (None:oauth2_provider) ^o/>], [<RegexURLResolver <module 'vemo_service_apps.auths_api.urls' from 'D:\\vemo\\vemo_service\\vemo_service_apps\\auths_api\\urls.py'> (None:None) ^api/auths/>], [<RegexURLResolver <module 'vemo_service_apps.catalogo_api.urls' from 'D:\\vemo\\vemo_service\\vemo_service_apps\\catalogo_api\\urls.py'> (None:None) ^api/catalogo/>]], 'path': 'favicon.ico'}

During handling of the above exception, another exception occurred:

Traceback (most recent call last):
  File "C:\Users\pc\AppData\Local\Programs\Python\Python35-32\lib\site-packages\django\template\base.py", line 885, in _resolve_lookup
    current = current[bit]
TypeError: 'RegexURLResolver' object is not subscriptable

During handling of the above exception, another exception occurred:

Traceback (most recent call last):
  File "C:\Users\pc\AppData\Local\Programs\Python\Python35-32\lib\site-packages\django\template\base.py", line 893, in _resolve_lookup
    current = getattr(current, bit)
AttributeError: 'RegexURLResolver' object has no attribute 'name'

During handling of the above exception, another exception occurred:

Traceback (most recent call last):
  File "C:\Users\pc\AppData\Local\Programs\Python\Python35-32\lib\site-packages\django\template\base.py", line 900, in _resolve_lookup
    current = current[int(bit)]
ValueError: invalid literal for int() with base 10: 'name'

During handling of the above exception, another exception occurred:

Traceback (most recent call last):
  File "C:\Users\pc\AppData\Local\Programs\Python\Python35-32\lib\site-packages\django\template\base.py", line 907, in _resolve_lookup
    (bit, current))  # missing attribute
django.template.base.VariableDoesNotExist: Failed lookup for key [name] in "<RegexURLResolver <module 'rest_framework.urls' from 'C:\\\\Users\\\\pc\\\\AppData\\\\Local\\\\Programs\\\\Python\\\\Python35-32\\\\lib\\\\site-packages\\\\rest_framework\\\\urls.py'> (rest_framework:rest_framework) ^api-auth/>"
[2016-11-09 21:45:12] DEBUG [django.template:929] Exception while resolving variable 'name' in template 'unknown'.
Traceback (most recent call last):
  File "C:\Users\pc\AppData\Local\Programs\Python\Python35-32\lib\site-packages\django\core\handlers\exception.py", line 39, in inner
    response = get_response(request)
  File "C:\Users\pc\AppData\Local\Programs\Python\Python35-32\lib\site-packages\django\core\handlers\base.py", line 172, in _get_response
    resolver_match = resolver.resolve(request.path_info)
  File "C:\Users\pc\AppData\Local\Programs\Python\Python35-32\lib\site-packages\django\urls\resolvers.py", line 300, in resolve
    raise Resolver404({'tried': tried, 'path': new_path})
django.urls.exceptions.Resolver404: {'tried': [[<RegexURLResolver <RegexURLPattern list> (admin:admin) ^admin/>], [<RegexURLResolver <module 'django.contrib.admindocs.urls' from 'C:\\Users\\pc\\AppData\\Local\\Programs\\Python\\Python35-32\\lib\\site-packages\\django\\contrib\\admindocs\\urls.py'> (None:None) ^admin/doc/>], [<RegexURLResolver <module 'rest_framework.urls' from 'C:\\Users\\pc\\AppData\\Local\\Programs\\Python\\Python35-32\\lib\\site-packages\\rest_framework\\urls.py'> (rest_framework:rest_framework) ^api-auth/>], [<RegexURLResolver <module 'oauth2_provider.urls' from 'C:\\Users\\pc\\AppData\\Local\\Programs\\Python\\Python35-32\\lib\\site-packages\\oauth2_provider\\urls.py'> (None:oauth2_provider) ^o/>], [<RegexURLResolver <module 'vemo_service_apps.auths_api.urls' from 'D:\\vemo\\vemo_service\\vemo_service_apps\\auths_api\\urls.py'> (None:None) ^api/auths/>], [<RegexURLResolver <module 'vemo_service_apps.catalogo_api.urls' from 'D:\\vemo\\vemo_service\\vemo_service_apps\\catalogo_api\\urls.py'> (None:None) ^api/catalogo/>]], 'path': 'favicon.ico'}

During handling of the above exception, another exception occurred:

Traceback (most recent call last):
  File "C:\Users\pc\AppData\Local\Programs\Python\Python35-32\lib\site-packages\django\template\base.py", line 885, in _resolve_lookup
    current = current[bit]
TypeError: 'RegexURLResolver' object is not subscriptable

During handling of the above exception, another exception occurred:

Traceback (most recent call last):
  File "C:\Users\pc\AppData\Local\Programs\Python\Python35-32\lib\site-packages\django\template\base.py", line 893, in _resolve_lookup
    current = getattr(current, bit)
AttributeError: 'RegexURLResolver' object has no attribute 'name'

During handling of the above exception, another exception occurred:

Traceback (most recent call last):
  File "C:\Users\pc\AppData\Local\Programs\Python\Python35-32\lib\site-packages\django\template\base.py", line 900, in _resolve_lookup
    current = current[int(bit)]
ValueError: invalid literal for int() with base 10: 'name'

During handling of the above exception, another exception occurred:

Traceback (most recent call last):
  File "C:\Users\pc\AppData\Local\Programs\Python\Python35-32\lib\site-packages\django\template\base.py", line 907, in _resolve_lookup
    (bit, current))  # missing attribute
django.template.base.VariableDoesNotExist: Failed lookup for key [name] in "<RegexURLResolver <module 'oauth2_provider.urls' from 'C:\\\\Users\\\\pc\\\\AppData\\\\Local\\\\Programs\\\\Python\\\\Python35-32\\\\lib\\\\site-packages\\\\oauth2_provider\\\\urls.py'> (None:oauth2_provider) ^o/>"
[2016-11-09 21:45:12] DEBUG [django.template:929] Exception while resolving variable 'name' in template 'unknown'.
Traceback (most recent call last):
  File "C:\Users\pc\AppData\Local\Programs\Python\Python35-32\lib\site-packages\django\core\handlers\exception.py", line 39, in inner
    response = get_response(request)
  File "C:\Users\pc\AppData\Local\Programs\Python\Python35-32\lib\site-packages\django\core\handlers\base.py", line 172, in _get_response
    resolver_match = resolver.resolve(request.path_info)
  File "C:\Users\pc\AppData\Local\Programs\Python\Python35-32\lib\site-packages\django\urls\resolvers.py", line 300, in resolve
    raise Resolver404({'tried': tried, 'path': new_path})
django.urls.exceptions.Resolver404: {'tried': [[<RegexURLResolver <RegexURLPattern list> (admin:admin) ^admin/>], [<RegexURLResolver <module 'django.contrib.admindocs.urls' from 'C:\\Users\\pc\\AppData\\Local\\Programs\\Python\\Python35-32\\lib\\site-packages\\django\\contrib\\admindocs\\urls.py'> (None:None) ^admin/doc/>], [<RegexURLResolver <module 'rest_framework.urls' from 'C:\\Users\\pc\\AppData\\Local\\Programs\\Python\\Python35-32\\lib\\site-packages\\rest_framework\\urls.py'> (rest_framework:rest_framework) ^api-auth/>], [<RegexURLResolver <module 'oauth2_provider.urls' from 'C:\\Users\\pc\\AppData\\Local\\Programs\\Python\\Python35-32\\lib\\site-packages\\oauth2_provider\\urls.py'> (None:oauth2_provider) ^o/>], [<RegexURLResolver <module 'vemo_service_apps.auths_api.urls' from 'D:\\vemo\\vemo_service\\vemo_service_apps\\auths_api\\urls.py'> (None:None) ^api/auths/>], [<RegexURLResolver <module 'vemo_service_apps.catalogo_api.urls' from 'D:\\vemo\\vemo_service\\vemo_service_apps\\catalogo_api\\urls.py'> (None:None) ^api/catalogo/>]], 'path': 'favicon.ico'}

During handling of the above exception, another exception occurred:

Traceback (most recent call last):
  File "C:\Users\pc\AppData\Local\Programs\Python\Python35-32\lib\site-packages\django\template\base.py", line 885, in _resolve_lookup
    current = current[bit]
TypeError: 'RegexURLResolver' object is not subscriptable

During handling of the above exception, another exception occurred:

Traceback (most recent call last):
  File "C:\Users\pc\AppData\Local\Programs\Python\Python35-32\lib\site-packages\django\template\base.py", line 893, in _resolve_lookup
    current = getattr(current, bit)
AttributeError: 'RegexURLResolver' object has no attribute 'name'

During handling of the above exception, another exception occurred:

Traceback (most recent call last):
  File "C:\Users\pc\AppData\Local\Programs\Python\Python35-32\lib\site-packages\django\template\base.py", line 900, in _resolve_lookup
    current = current[int(bit)]
ValueError: invalid literal for int() with base 10: 'name'

During handling of the above exception, another exception occurred:

Traceback (most recent call last):
  File "C:\Users\pc\AppData\Local\Programs\Python\Python35-32\lib\site-packages\django\template\base.py", line 907, in _resolve_lookup
    (bit, current))  # missing attribute
django.template.base.VariableDoesNotExist: Failed lookup for key [name] in "<RegexURLResolver <module 'vemo_service_apps.auths_api.urls' from 'D:\\\\vemo\\\\vemo_service\\\\vemo_service_apps\\\\auths_api\\\\urls.py'> (None:None) ^api/auths/>"
[2016-11-09 21:45:12] DEBUG [django.template:929] Exception while resolving variable 'name' in template 'unknown'.
Traceback (most recent call last):
  File "C:\Users\pc\AppData\Local\Programs\Python\Python35-32\lib\site-packages\django\core\handlers\exception.py", line 39, in inner
    response = get_response(request)
  File "C:\Users\pc\AppData\Local\Programs\Python\Python35-32\lib\site-packages\django\core\handlers\base.py", line 172, in _get_response
    resolver_match = resolver.resolve(request.path_info)
  File "C:\Users\pc\AppData\Local\Programs\Python\Python35-32\lib\site-packages\django\urls\resolvers.py", line 300, in resolve
    raise Resolver404({'tried': tried, 'path': new_path})
django.urls.exceptions.Resolver404: {'tried': [[<RegexURLResolver <RegexURLPattern list> (admin:admin) ^admin/>], [<RegexURLResolver <module 'django.contrib.admindocs.urls' from 'C:\\Users\\pc\\AppData\\Local\\Programs\\Python\\Python35-32\\lib\\site-packages\\django\\contrib\\admindocs\\urls.py'> (None:None) ^admin/doc/>], [<RegexURLResolver <module 'rest_framework.urls' from 'C:\\Users\\pc\\AppData\\Local\\Programs\\Python\\Python35-32\\lib\\site-packages\\rest_framework\\urls.py'> (rest_framework:rest_framework) ^api-auth/>], [<RegexURLResolver <module 'oauth2_provider.urls' from 'C:\\Users\\pc\\AppData\\Local\\Programs\\Python\\Python35-32\\lib\\site-packages\\oauth2_provider\\urls.py'> (None:oauth2_provider) ^o/>], [<RegexURLResolver <module 'vemo_service_apps.auths_api.urls' from 'D:\\vemo\\vemo_service\\vemo_service_apps\\auths_api\\urls.py'> (None:None) ^api/auths/>], [<RegexURLResolver <module 'vemo_service_apps.catalogo_api.urls' from 'D:\\vemo\\vemo_service\\vemo_service_apps\\catalogo_api\\urls.py'> (None:None) ^api/catalogo/>]], 'path': 'favicon.ico'}

During handling of the above exception, another exception occurred:

Traceback (most recent call last):
  File "C:\Users\pc\AppData\Local\Programs\Python\Python35-32\lib\site-packages\django\template\base.py", line 885, in _resolve_lookup
    current = current[bit]
TypeError: 'RegexURLResolver' object is not subscriptable

During handling of the above exception, another exception occurred:

Traceback (most recent call last):
  File "C:\Users\pc\AppData\Local\Programs\Python\Python35-32\lib\site-packages\django\template\base.py", line 893, in _resolve_lookup
    current = getattr(current, bit)
AttributeError: 'RegexURLResolver' object has no attribute 'name'

During handling of the above exception, another exception occurred:

Traceback (most recent call last):
  File "C:\Users\pc\AppData\Local\Programs\Python\Python35-32\lib\site-packages\django\template\base.py", line 900, in _resolve_lookup
    current = current[int(bit)]
ValueError: invalid literal for int() with base 10: 'name'

During handling of the above exception, another exception occurred:

Traceback (most recent call last):
  File "C:\Users\pc\AppData\Local\Programs\Python\Python35-32\lib\site-packages\django\template\base.py", line 907, in _resolve_lookup
    (bit, current))  # missing attribute
django.template.base.VariableDoesNotExist: Failed lookup for key [name] in "<RegexURLResolver <module 'vemo_service_apps.catalogo_api.urls' from 'D:\\\\vemo\\\\vemo_service\\\\vemo_service_apps\\\\catalogo_api\\\\urls.py'> (None:None) ^api/catalogo/>"
[2016-11-09 21:45:12] WARNING [django.request:152] Not Found: /favicon.ico
[2016-11-09 21:45:12] WARNING [django.server:131] "GET /favicon.ico HTTP/1.1" 404 2488
[2016-11-09 21:45:13] DEBUG [django.template:929] Exception while resolving variable 'name' in template 'unknown'.
Traceback (most recent call last):
  File "C:\Users\pc\AppData\Local\Programs\Python\Python35-32\lib\site-packages\django\core\handlers\exception.py", line 39, in inner
    response = get_response(request)
  File "C:\Users\pc\AppData\Local\Programs\Python\Python35-32\lib\site-packages\django\core\handlers\base.py", line 172, in _get_response
    resolver_match = resolver.resolve(request.path_info)
  File "C:\Users\pc\AppData\Local\Programs\Python\Python35-32\lib\site-packages\django\urls\resolvers.py", line 300, in resolve
    raise Resolver404({'tried': tried, 'path': new_path})
django.urls.exceptions.Resolver404: {'tried': [[<RegexURLResolver <RegexURLPattern list> (admin:admin) ^admin/>], [<RegexURLResolver <module 'django.contrib.admindocs.urls' from 'C:\\Users\\pc\\AppData\\Local\\Programs\\Python\\Python35-32\\lib\\site-packages\\django\\contrib\\admindocs\\urls.py'> (None:None) ^admin/doc/>], [<RegexURLResolver <module 'rest_framework.urls' from 'C:\\Users\\pc\\AppData\\Local\\Programs\\Python\\Python35-32\\lib\\site-packages\\rest_framework\\urls.py'> (rest_framework:rest_framework) ^api-auth/>], [<RegexURLResolver <module 'oauth2_provider.urls' from 'C:\\Users\\pc\\AppData\\Local\\Programs\\Python\\Python35-32\\lib\\site-packages\\oauth2_provider\\urls.py'> (None:oauth2_provider) ^o/>], [<RegexURLResolver <module 'vemo_service_apps.auths_api.urls' from 'D:\\vemo\\vemo_service\\vemo_service_apps\\auths_api\\urls.py'> (None:None) ^api/auths/>], [<RegexURLResolver <module 'vemo_service_apps.catalogo_api.urls' from 'D:\\vemo\\vemo_service\\vemo_service_apps\\catalogo_api\\urls.py'> (None:None) ^api/catalogo/>]], 'path': 'favicon.ico'}

During handling of the above exception, another exception occurred:

Traceback (most recent call last):
  File "C:\Users\pc\AppData\Local\Programs\Python\Python35-32\lib\site-packages\django\template\base.py", line 885, in _resolve_lookup
    current = current[bit]
TypeError: 'RegexURLResolver' object is not subscriptable

During handling of the above exception, another exception occurred:

Traceback (most recent call last):
  File "C:\Users\pc\AppData\Local\Programs\Python\Python35-32\lib\site-packages\django\template\base.py", line 893, in _resolve_lookup
    current = getattr(current, bit)
AttributeError: 'RegexURLResolver' object has no attribute 'name'

During handling of the above exception, another exception occurred:

Traceback (most recent call last):
  File "C:\Users\pc\AppData\Local\Programs\Python\Python35-32\lib\site-packages\django\template\base.py", line 900, in _resolve_lookup
    current = current[int(bit)]
ValueError: invalid literal for int() with base 10: 'name'

During handling of the above exception, another exception occurred:

Traceback (most recent call last):
  File "C:\Users\pc\AppData\Local\Programs\Python\Python35-32\lib\site-packages\django\template\base.py", line 907, in _resolve_lookup
    (bit, current))  # missing attribute
django.template.base.VariableDoesNotExist: Failed lookup for key [name] in '<RegexURLResolver <RegexURLPattern list> (admin:admin) ^admin/>'
[2016-11-09 21:45:13] DEBUG [django.template:929] Exception while resolving variable 'name' in template 'unknown'.
Traceback (most recent call last):
  File "C:\Users\pc\AppData\Local\Programs\Python\Python35-32\lib\site-packages\django\core\handlers\exception.py", line 39, in inner
    response = get_response(request)
  File "C:\Users\pc\AppData\Local\Programs\Python\Python35-32\lib\site-packages\django\core\handlers\base.py", line 172, in _get_response
    resolver_match = resolver.resolve(request.path_info)
  File "C:\Users\pc\AppData\Local\Programs\Python\Python35-32\lib\site-packages\django\urls\resolvers.py", line 300, in resolve
    raise Resolver404({'tried': tried, 'path': new_path})
django.urls.exceptions.Resolver404: {'tried': [[<RegexURLResolver <RegexURLPattern list> (admin:admin) ^admin/>], [<RegexURLResolver <module 'django.contrib.admindocs.urls' from 'C:\\Users\\pc\\AppData\\Local\\Programs\\Python\\Python35-32\\lib\\site-packages\\django\\contrib\\admindocs\\urls.py'> (None:None) ^admin/doc/>], [<RegexURLResolver <module 'rest_framework.urls' from 'C:\\Users\\pc\\AppData\\Local\\Programs\\Python\\Python35-32\\lib\\site-packages\\rest_framework\\urls.py'> (rest_framework:rest_framework) ^api-auth/>], [<RegexURLResolver <module 'oauth2_provider.urls' from 'C:\\Users\\pc\\AppData\\Local\\Programs\\Python\\Python35-32\\lib\\site-packages\\oauth2_provider\\urls.py'> (None:oauth2_provider) ^o/>], [<RegexURLResolver <module 'vemo_service_apps.auths_api.urls' from 'D:\\vemo\\vemo_service\\vemo_service_apps\\auths_api\\urls.py'> (None:None) ^api/auths/>], [<RegexURLResolver <module 'vemo_service_apps.catalogo_api.urls' from 'D:\\vemo\\vemo_service\\vemo_service_apps\\catalogo_api\\urls.py'> (None:None) ^api/catalogo/>]], 'path': 'favicon.ico'}

During handling of the above exception, another exception occurred:

Traceback (most recent call last):
  File "C:\Users\pc\AppData\Local\Programs\Python\Python35-32\lib\site-packages\django\template\base.py", line 885, in _resolve_lookup
    current = current[bit]
TypeError: 'RegexURLResolver' object is not subscriptable

During handling of the above exception, another exception occurred:

Traceback (most recent call last):
  File "C:\Users\pc\AppData\Local\Programs\Python\Python35-32\lib\site-packages\django\template\base.py", line 893, in _resolve_lookup
    current = getattr(current, bit)
AttributeError: 'RegexURLResolver' object has no attribute 'name'

During handling of the above exception, another exception occurred:

Traceback (most recent call last):
  File "C:\Users\pc\AppData\Local\Programs\Python\Python35-32\lib\site-packages\django\template\base.py", line 900, in _resolve_lookup
    current = current[int(bit)]
ValueError: invalid literal for int() with base 10: 'name'

During handling of the above exception, another exception occurred:

Traceback (most recent call last):
  File "C:\Users\pc\AppData\Local\Programs\Python\Python35-32\lib\site-packages\django\template\base.py", line 907, in _resolve_lookup
    (bit, current))  # missing attribute
django.template.base.VariableDoesNotExist: Failed lookup for key [name] in "<RegexURLResolver <module 'django.contrib.admindocs.urls' from 'C:\\\\Users\\\\pc\\\\AppData\\\\Local\\\\Programs\\\\Python\\\\Python35-32\\\\lib\\\\site-packages\\\\django\\\\contrib\\\\admindocs\\\\urls.py'> (None:None) ^admin/doc/>"
[2016-11-09 21:45:13] DEBUG [django.template:929] Exception while resolving variable 'name' in template 'unknown'.
Traceback (most recent call last):
  File "C:\Users\pc\AppData\Local\Programs\Python\Python35-32\lib\site-packages\django\core\handlers\exception.py", line 39, in inner
    response = get_response(request)
  File "C:\Users\pc\AppData\Local\Programs\Python\Python35-32\lib\site-packages\django\core\handlers\base.py", line 172, in _get_response
    resolver_match = resolver.resolve(request.path_info)
  File "C:\Users\pc\AppData\Local\Programs\Python\Python35-32\lib\site-packages\django\urls\resolvers.py", line 300, in resolve
    raise Resolver404({'tried': tried, 'path': new_path})
django.urls.exceptions.Resolver404: {'tried': [[<RegexURLResolver <RegexURLPattern list> (admin:admin) ^admin/>], [<RegexURLResolver <module 'django.contrib.admindocs.urls' from 'C:\\Users\\pc\\AppData\\Local\\Programs\\Python\\Python35-32\\lib\\site-packages\\django\\contrib\\admindocs\\urls.py'> (None:None) ^admin/doc/>], [<RegexURLResolver <module 'rest_framework.urls' from 'C:\\Users\\pc\\AppData\\Local\\Programs\\Python\\Python35-32\\lib\\site-packages\\rest_framework\\urls.py'> (rest_framework:rest_framework) ^api-auth/>], [<RegexURLResolver <module 'oauth2_provider.urls' from 'C:\\Users\\pc\\AppData\\Local\\Programs\\Python\\Python35-32\\lib\\site-packages\\oauth2_provider\\urls.py'> (None:oauth2_provider) ^o/>], [<RegexURLResolver <module 'vemo_service_apps.auths_api.urls' from 'D:\\vemo\\vemo_service\\vemo_service_apps\\auths_api\\urls.py'> (None:None) ^api/auths/>], [<RegexURLResolver <module 'vemo_service_apps.catalogo_api.urls' from 'D:\\vemo\\vemo_service\\vemo_service_apps\\catalogo_api\\urls.py'> (None:None) ^api/catalogo/>]], 'path': 'favicon.ico'}

During handling of the above exception, another exception occurred:

Traceback (most recent call last):
  File "C:\Users\pc\AppData\Local\Programs\Python\Python35-32\lib\site-packages\django\template\base.py", line 885, in _resolve_lookup
    current = current[bit]
TypeError: 'RegexURLResolver' object is not subscriptable

During handling of the above exception, another exception occurred:

Traceback (most recent call last):
  File "C:\Users\pc\AppData\Local\Programs\Python\Python35-32\lib\site-packages\django\template\base.py", line 893, in _resolve_lookup
    current = getattr(current, bit)
AttributeError: 'RegexURLResolver' object has no attribute 'name'

During handling of the above exception, another exception occurred:

Traceback (most recent call last):
  File "C:\Users\pc\AppData\Local\Programs\Python\Python35-32\lib\site-packages\django\template\base.py", line 900, in _resolve_lookup
    current = current[int(bit)]
ValueError: invalid literal for int() with base 10: 'name'

During handling of the above exception, another exception occurred:

Traceback (most recent call last):
  File "C:\Users\pc\AppData\Local\Programs\Python\Python35-32\lib\site-packages\django\template\base.py", line 907, in _resolve_lookup
    (bit, current))  # missing attribute
django.template.base.VariableDoesNotExist: Failed lookup for key [name] in "<RegexURLResolver <module 'rest_framework.urls' from 'C:\\\\Users\\\\pc\\\\AppData\\\\Local\\\\Programs\\\\Python\\\\Python35-32\\\\lib\\\\site-packages\\\\rest_framework\\\\urls.py'> (rest_framework:rest_framework) ^api-auth/>"
[2016-11-09 21:45:13] DEBUG [django.template:929] Exception while resolving variable 'name' in template 'unknown'.
Traceback (most recent call last):
  File "C:\Users\pc\AppData\Local\Programs\Python\Python35-32\lib\site-packages\django\core\handlers\exception.py", line 39, in inner
    response = get_response(request)
  File "C:\Users\pc\AppData\Local\Programs\Python\Python35-32\lib\site-packages\django\core\handlers\base.py", line 172, in _get_response
    resolver_match = resolver.resolve(request.path_info)
  File "C:\Users\pc\AppData\Local\Programs\Python\Python35-32\lib\site-packages\django\urls\resolvers.py", line 300, in resolve
    raise Resolver404({'tried': tried, 'path': new_path})
django.urls.exceptions.Resolver404: {'tried': [[<RegexURLResolver <RegexURLPattern list> (admin:admin) ^admin/>], [<RegexURLResolver <module 'django.contrib.admindocs.urls' from 'C:\\Users\\pc\\AppData\\Local\\Programs\\Python\\Python35-32\\lib\\site-packages\\django\\contrib\\admindocs\\urls.py'> (None:None) ^admin/doc/>], [<RegexURLResolver <module 'rest_framework.urls' from 'C:\\Users\\pc\\AppData\\Local\\Programs\\Python\\Python35-32\\lib\\site-packages\\rest_framework\\urls.py'> (rest_framework:rest_framework) ^api-auth/>], [<RegexURLResolver <module 'oauth2_provider.urls' from 'C:\\Users\\pc\\AppData\\Local\\Programs\\Python\\Python35-32\\lib\\site-packages\\oauth2_provider\\urls.py'> (None:oauth2_provider) ^o/>], [<RegexURLResolver <module 'vemo_service_apps.auths_api.urls' from 'D:\\vemo\\vemo_service\\vemo_service_apps\\auths_api\\urls.py'> (None:None) ^api/auths/>], [<RegexURLResolver <module 'vemo_service_apps.catalogo_api.urls' from 'D:\\vemo\\vemo_service\\vemo_service_apps\\catalogo_api\\urls.py'> (None:None) ^api/catalogo/>]], 'path': 'favicon.ico'}

During handling of the above exception, another exception occurred:

Traceback (most recent call last):
  File "C:\Users\pc\AppData\Local\Programs\Python\Python35-32\lib\site-packages\django\template\base.py", line 885, in _resolve_lookup
    current = current[bit]
TypeError: 'RegexURLResolver' object is not subscriptable

During handling of the above exception, another exception occurred:

Traceback (most recent call last):
  File "C:\Users\pc\AppData\Local\Programs\Python\Python35-32\lib\site-packages\django\template\base.py", line 893, in _resolve_lookup
    current = getattr(current, bit)
AttributeError: 'RegexURLResolver' object has no attribute 'name'

During handling of the above exception, another exception occurred:

Traceback (most recent call last):
  File "C:\Users\pc\AppData\Local\Programs\Python\Python35-32\lib\site-packages\django\template\base.py", line 900, in _resolve_lookup
    current = current[int(bit)]
ValueError: invalid literal for int() with base 10: 'name'

During handling of the above exception, another exception occurred:

Traceback (most recent call last):
  File "C:\Users\pc\AppData\Local\Programs\Python\Python35-32\lib\site-packages\django\template\base.py", line 907, in _resolve_lookup
    (bit, current))  # missing attribute
django.template.base.VariableDoesNotExist: Failed lookup for key [name] in "<RegexURLResolver <module 'oauth2_provider.urls' from 'C:\\\\Users\\\\pc\\\\AppData\\\\Local\\\\Programs\\\\Python\\\\Python35-32\\\\lib\\\\site-packages\\\\oauth2_provider\\\\urls.py'> (None:oauth2_provider) ^o/>"
[2016-11-09 21:45:13] DEBUG [django.template:929] Exception while resolving variable 'name' in template 'unknown'.
Traceback (most recent call last):
  File "C:\Users\pc\AppData\Local\Programs\Python\Python35-32\lib\site-packages\django\core\handlers\exception.py", line 39, in inner
    response = get_response(request)
  File "C:\Users\pc\AppData\Local\Programs\Python\Python35-32\lib\site-packages\django\core\handlers\base.py", line 172, in _get_response
    resolver_match = resolver.resolve(request.path_info)
  File "C:\Users\pc\AppData\Local\Programs\Python\Python35-32\lib\site-packages\django\urls\resolvers.py", line 300, in resolve
    raise Resolver404({'tried': tried, 'path': new_path})
django.urls.exceptions.Resolver404: {'tried': [[<RegexURLResolver <RegexURLPattern list> (admin:admin) ^admin/>], [<RegexURLResolver <module 'django.contrib.admindocs.urls' from 'C:\\Users\\pc\\AppData\\Local\\Programs\\Python\\Python35-32\\lib\\site-packages\\django\\contrib\\admindocs\\urls.py'> (None:None) ^admin/doc/>], [<RegexURLResolver <module 'rest_framework.urls' from 'C:\\Users\\pc\\AppData\\Local\\Programs\\Python\\Python35-32\\lib\\site-packages\\rest_framework\\urls.py'> (rest_framework:rest_framework) ^api-auth/>], [<RegexURLResolver <module 'oauth2_provider.urls' from 'C:\\Users\\pc\\AppData\\Local\\Programs\\Python\\Python35-32\\lib\\site-packages\\oauth2_provider\\urls.py'> (None:oauth2_provider) ^o/>], [<RegexURLResolver <module 'vemo_service_apps.auths_api.urls' from 'D:\\vemo\\vemo_service\\vemo_service_apps\\auths_api\\urls.py'> (None:None) ^api/auths/>], [<RegexURLResolver <module 'vemo_service_apps.catalogo_api.urls' from 'D:\\vemo\\vemo_service\\vemo_service_apps\\catalogo_api\\urls.py'> (None:None) ^api/catalogo/>]], 'path': 'favicon.ico'}

During handling of the above exception, another exception occurred:

Traceback (most recent call last):
  File "C:\Users\pc\AppData\Local\Programs\Python\Python35-32\lib\site-packages\django\template\base.py", line 885, in _resolve_lookup
    current = current[bit]
TypeError: 'RegexURLResolver' object is not subscriptable

During handling of the above exception, another exception occurred:

Traceback (most recent call last):
  File "C:\Users\pc\AppData\Local\Programs\Python\Python35-32\lib\site-packages\django\template\base.py", line 893, in _resolve_lookup
    current = getattr(current, bit)
AttributeError: 'RegexURLResolver' object has no attribute 'name'

During handling of the above exception, another exception occurred:

Traceback (most recent call last):
  File "C:\Users\pc\AppData\Local\Programs\Python\Python35-32\lib\site-packages\django\template\base.py", line 900, in _resolve_lookup
    current = current[int(bit)]
ValueError: invalid literal for int() with base 10: 'name'

During handling of the above exception, another exception occurred:

Traceback (most recent call last):
  File "C:\Users\pc\AppData\Local\Programs\Python\Python35-32\lib\site-packages\django\template\base.py", line 907, in _resolve_lookup
    (bit, current))  # missing attribute
django.template.base.VariableDoesNotExist: Failed lookup for key [name] in "<RegexURLResolver <module 'vemo_service_apps.auths_api.urls' from 'D:\\\\vemo\\\\vemo_service\\\\vemo_service_apps\\\\auths_api\\\\urls.py'> (None:None) ^api/auths/>"
[2016-11-09 21:45:13] DEBUG [django.template:929] Exception while resolving variable 'name' in template 'unknown'.
Traceback (most recent call last):
  File "C:\Users\pc\AppData\Local\Programs\Python\Python35-32\lib\site-packages\django\core\handlers\exception.py", line 39, in inner
    response = get_response(request)
  File "C:\Users\pc\AppData\Local\Programs\Python\Python35-32\lib\site-packages\django\core\handlers\base.py", line 172, in _get_response
    resolver_match = resolver.resolve(request.path_info)
  File "C:\Users\pc\AppData\Local\Programs\Python\Python35-32\lib\site-packages\django\urls\resolvers.py", line 300, in resolve
    raise Resolver404({'tried': tried, 'path': new_path})
django.urls.exceptions.Resolver404: {'tried': [[<RegexURLResolver <RegexURLPattern list> (admin:admin) ^admin/>], [<RegexURLResolver <module 'django.contrib.admindocs.urls' from 'C:\\Users\\pc\\AppData\\Local\\Programs\\Python\\Python35-32\\lib\\site-packages\\django\\contrib\\admindocs\\urls.py'> (None:None) ^admin/doc/>], [<RegexURLResolver <module 'rest_framework.urls' from 'C:\\Users\\pc\\AppData\\Local\\Programs\\Python\\Python35-32\\lib\\site-packages\\rest_framework\\urls.py'> (rest_framework:rest_framework) ^api-auth/>], [<RegexURLResolver <module 'oauth2_provider.urls' from 'C:\\Users\\pc\\AppData\\Local\\Programs\\Python\\Python35-32\\lib\\site-packages\\oauth2_provider\\urls.py'> (None:oauth2_provider) ^o/>], [<RegexURLResolver <module 'vemo_service_apps.auths_api.urls' from 'D:\\vemo\\vemo_service\\vemo_service_apps\\auths_api\\urls.py'> (None:None) ^api/auths/>], [<RegexURLResolver <module 'vemo_service_apps.catalogo_api.urls' from 'D:\\vemo\\vemo_service\\vemo_service_apps\\catalogo_api\\urls.py'> (None:None) ^api/catalogo/>]], 'path': 'favicon.ico'}

During handling of the above exception, another exception occurred:

Traceback (most recent call last):
  File "C:\Users\pc\AppData\Local\Programs\Python\Python35-32\lib\site-packages\django\template\base.py", line 885, in _resolve_lookup
    current = current[bit]
TypeError: 'RegexURLResolver' object is not subscriptable

During handling of the above exception, another exception occurred:

Traceback (most recent call last):
  File "C:\Users\pc\AppData\Local\Programs\Python\Python35-32\lib\site-packages\django\template\base.py", line 893, in _resolve_lookup
    current = getattr(current, bit)
AttributeError: 'RegexURLResolver' object has no attribute 'name'

During handling of the above exception, another exception occurred:

Traceback (most recent call last):
  File "C:\Users\pc\AppData\Local\Programs\Python\Python35-32\lib\site-packages\django\template\base.py", line 900, in _resolve_lookup
    current = current[int(bit)]
ValueError: invalid literal for int() with base 10: 'name'

During handling of the above exception, another exception occurred:

Traceback (most recent call last):
  File "C:\Users\pc\AppData\Local\Programs\Python\Python35-32\lib\site-packages\django\template\base.py", line 907, in _resolve_lookup
    (bit, current))  # missing attribute
django.template.base.VariableDoesNotExist: Failed lookup for key [name] in "<RegexURLResolver <module 'vemo_service_apps.catalogo_api.urls' from 'D:\\\\vemo\\\\vemo_service\\\\vemo_service_apps\\\\catalogo_api\\\\urls.py'> (None:None) ^api/catalogo/>"
[2016-11-09 21:45:13] WARNING [django.request:152] Not Found: /favicon.ico
[2016-11-09 21:45:13] WARNING [django.server:131] "GET /favicon.ico HTTP/1.1" 404 2488
[2016-11-09 21:45:38] DEBUG [django.db.backends:90] (0.003) SELECT "oauth2_provider_application"."id", "oauth2_provider_application"."client_id", "oauth2_provider_application"."user_id", "oauth2_provider_application"."redirect_uris", "oauth2_provider_application"."client_type", "oauth2_provider_application"."authorization_grant_type", "oauth2_provider_application"."client_secret", "oauth2_provider_application"."name", "oauth2_provider_application"."skip_authorization" FROM "oauth2_provider_application" WHERE "oauth2_provider_application"."client_id" = 'gyEJ310NDKMKrYvOMbwSnu9UFkJkXE5E48dCLRZK'; args=('gyEJ310NDKMKrYvOMbwSnu9UFkJkXE5E48dCLRZK',)
[2016-11-09 21:45:38] DEBUG [django.db.backends:90] (0.001) SELECT "auths_user"."password", "auths_user"."last_login", "auths_user"."is_superuser", "auths_user"."username", "auths_user"."first_name", "auths_user"."last_name", "auths_user"."email", "auths_user"."is_staff", "auths_user"."is_active", "auths_user"."date_joined", "auths_user"."id", "auths_user"."last_hierarchy_id", "auths_user"."last_module_id", "auths_user"."person_id", "auths_user"."updated_at", "auths_user"."registered_by" FROM "auths_user" WHERE "auths_user"."username" = 'admin'; args=('admin',)
[2016-11-09 21:45:38] DEBUG [django.db.backends:90] (0.000) BEGIN; args=None
[2016-11-09 21:45:38] DEBUG [django.db.backends:90] (0.017) INSERT INTO "oauth2_provider_accesstoken" ("user_id", "token", "application_id", "expires", "scope") VALUES ('3651942c1384420da02bbf9e5eca3faa', 'F5EvjxKiiSVUiJ6XUqvwi7BzPlilnB', 1, '2016-11-10 12:45:38.859219', 'read write'); args=['3651942c1384420da02bbf9e5eca3faa', 'F5EvjxKiiSVUiJ6XUqvwi7BzPlilnB', 1, '2016-11-10 12:45:38.859219', 'read write']
[2016-11-09 21:45:38] DEBUG [django.db.backends:90] (0.001) BEGIN; args=None
[2016-11-09 21:45:38] DEBUG [django.db.backends:90] (0.002) INSERT INTO "oauth2_provider_refreshtoken" ("user_id", "token", "application_id", "access_token_id") VALUES ('3651942c1384420da02bbf9e5eca3faa', 'LegPRLtU56fioI3zpMO5rPyjj2uzWa', 1, 5); args=['3651942c1384420da02bbf9e5eca3faa', 'LegPRLtU56fioI3zpMO5rPyjj2uzWa', 1, 5]
[2016-11-09 21:45:39] INFO [django.server:131] "POST /o/token/ HTTP/1.1" 200 169
[2016-11-09 21:45:40] DEBUG [django.db.backends:90] (0.005) SELECT "oauth2_provider_accesstoken"."id", "oauth2_provider_accesstoken"."user_id", "oauth2_provider_accesstoken"."token", "oauth2_provider_accesstoken"."application_id", "oauth2_provider_accesstoken"."expires", "oauth2_provider_accesstoken"."scope", "auths_user"."password", "auths_user"."last_login", "auths_user"."is_superuser", "auths_user"."username", "auths_user"."first_name", "auths_user"."last_name", "auths_user"."email", "auths_user"."is_staff", "auths_user"."is_active", "auths_user"."date_joined", "auths_user"."id", "auths_user"."last_hierarchy_id", "auths_user"."last_module_id", "auths_user"."person_id", "auths_user"."updated_at", "auths_user"."registered_by", "oauth2_provider_application"."id", "oauth2_provider_application"."client_id", "oauth2_provider_application"."user_id", "oauth2_provider_application"."redirect_uris", "oauth2_provider_application"."client_type", "oauth2_provider_application"."authorization_grant_type", "oauth2_provider_application"."client_secret", "oauth2_provider_application"."name", "oauth2_provider_application"."skip_authorization" FROM "oauth2_provider_accesstoken" LEFT OUTER JOIN "auths_user" ON ("oauth2_provider_accesstoken"."user_id" = "auths_user"."id") INNER JOIN "oauth2_provider_application" ON ("oauth2_provider_accesstoken"."application_id" = "oauth2_provider_application"."id") WHERE "oauth2_provider_accesstoken"."token" = 'F5EvjxKiiSVUiJ6XUqvwi7BzPlilnB'; args=('F5EvjxKiiSVUiJ6XUqvwi7BzPlilnB',)
[2016-11-09 21:45:40] DEBUG [django.db.backends:90] (0.006) SELECT "oauth2_provider_accesstoken"."id", "oauth2_provider_accesstoken"."user_id", "oauth2_provider_accesstoken"."token", "oauth2_provider_accesstoken"."application_id", "oauth2_provider_accesstoken"."expires", "oauth2_provider_accesstoken"."scope", "auths_user"."password", "auths_user"."last_login", "auths_user"."is_superuser", "auths_user"."username", "auths_user"."first_name", "auths_user"."last_name", "auths_user"."email", "auths_user"."is_staff", "auths_user"."is_active", "auths_user"."date_joined", "auths_user"."id", "auths_user"."last_hierarchy_id", "auths_user"."last_module_id", "auths_user"."person_id", "auths_user"."updated_at", "auths_user"."registered_by", "oauth2_provider_application"."id", "oauth2_provider_application"."client_id", "oauth2_provider_application"."user_id", "oauth2_provider_application"."redirect_uris", "oauth2_provider_application"."client_type", "oauth2_provider_application"."authorization_grant_type", "oauth2_provider_application"."client_secret", "oauth2_provider_application"."name", "oauth2_provider_application"."skip_authorization" FROM "oauth2_provider_accesstoken" LEFT OUTER JOIN "auths_user" ON ("oauth2_provider_accesstoken"."user_id" = "auths_user"."id") INNER JOIN "oauth2_provider_application" ON ("oauth2_provider_accesstoken"."application_id" = "oauth2_provider_application"."id") WHERE "oauth2_provider_accesstoken"."token" = 'F5EvjxKiiSVUiJ6XUqvwi7BzPlilnB'; args=('F5EvjxKiiSVUiJ6XUqvwi7BzPlilnB',)
[2016-11-09 21:45:40] DEBUG [django.db.backends:90] (0.000) SELECT "auths_menu"."id" FROM "auths_menu" WHERE ("auths_menu"."id" IS NOT NULL AND "auths_menu"."is_active" = 1 AND "auths_menu"."module" = 'BACKEND') ORDER BY "auths_menu"."pos" ASC; args=(True, 'BACKEND')
[2016-11-09 21:45:40] DEBUG [django.db.backends:90] (0.001) SELECT (1) AS "a" FROM "django_session" WHERE "django_session"."session_key" = '0cux0i65gha6ie0dw4mc22scyx6zgasl' LIMIT 1; args=('0cux0i65gha6ie0dw4mc22scyx6zgasl',)
[2016-11-09 21:45:40] DEBUG [django.db.backends:90] (0.000) BEGIN; args=None
[2016-11-09 21:45:40] DEBUG [django.db.backends:90] (0.001) SELECT "auth_group"."id", "auth_group"."name" FROM "auth_group" INNER JOIN "auths_user_groups" ON ("auth_group"."id" = "auths_user_groups"."group_id") WHERE "auths_user_groups"."user_id" = '3651942c1384420da02bbf9e5eca3faa'; args=('3651942c1384420da02bbf9e5eca3faa',)
[2016-11-09 21:45:40] DEBUG [django.db.backends:90] (0.001) SELECT "auth_permission"."id", "auth_permission"."name", "auth_permission"."content_type_id", "auth_permission"."codename" FROM "auth_permission" INNER JOIN "auths_user_user_permissions" ON ("auth_permission"."id" = "auths_user_user_permissions"."permission_id") INNER JOIN "django_content_type" ON ("auth_permission"."content_type_id" = "django_content_type"."id") WHERE "auths_user_user_permissions"."user_id" = '3651942c1384420da02bbf9e5eca3faa' ORDER BY "django_content_type"."app_label" ASC, "django_content_type"."model" ASC, "auth_permission"."codename" ASC; args=('3651942c1384420da02bbf9e5eca3faa',)
[2016-11-09 21:45:40] DEBUG [django.db.backends:90] (0.044) INSERT INTO "django_session" ("session_key", "session_data", "expire_date") SELECT '0cux0i65gha6ie0dw4mc22scyx6zgasl', 'NmE3M2Q3NmYwOTU3YjJmZDBjYmQxYTVjODc5MTExNzM3NjY1YzYzNzp7Il9zZXNzaW9uX2V4cGlyeSI6MzB9', '2016-11-10 02:46:10.343831'; args=('0cux0i65gha6ie0dw4mc22scyx6zgasl', 'NmE3M2Q3NmYwOTU3YjJmZDBjYmQxYTVjODc5MTExNzM3NjY1YzYzNzp7Il9zZXNzaW9uX2V4cGlyeSI6MzB9', '2016-11-10 02:46:10.343831')
[2016-11-09 21:45:40] INFO [django.server:131] "GET /api/auths/localuserinfo/ HTTP/1.1" 200 496
[2016-11-09 21:45:40] INFO [django.server:131] "GET /api/auths/usermenu/ HTTP/1.1" 200 11
[2016-11-09 21:45:58] INFO [django.server:131] "OPTIONS /api/catalogo/categorias/ HTTP/1.1" 200 0
[2016-11-09 21:45:58] DEBUG [django.db.backends:90] (0.003) SELECT "oauth2_provider_accesstoken"."id", "oauth2_provider_accesstoken"."user_id", "oauth2_provider_accesstoken"."token", "oauth2_provider_accesstoken"."application_id", "oauth2_provider_accesstoken"."expires", "oauth2_provider_accesstoken"."scope", "auths_user"."password", "auths_user"."last_login", "auths_user"."is_superuser", "auths_user"."username", "auths_user"."first_name", "auths_user"."last_name", "auths_user"."email", "auths_user"."is_staff", "auths_user"."is_active", "auths_user"."date_joined", "auths_user"."id", "auths_user"."last_hierarchy_id", "auths_user"."last_module_id", "auths_user"."person_id", "auths_user"."updated_at", "auths_user"."registered_by", "oauth2_provider_application"."id", "oauth2_provider_application"."client_id", "oauth2_provider_application"."user_id", "oauth2_provider_application"."redirect_uris", "oauth2_provider_application"."client_type", "oauth2_provider_application"."authorization_grant_type", "oauth2_provider_application"."client_secret", "oauth2_provider_application"."name", "oauth2_provider_application"."skip_authorization" FROM "oauth2_provider_accesstoken" LEFT OUTER JOIN "auths_user" ON ("oauth2_provider_accesstoken"."user_id" = "auths_user"."id") INNER JOIN "oauth2_provider_application" ON ("oauth2_provider_accesstoken"."application_id" = "oauth2_provider_application"."id") WHERE "oauth2_provider_accesstoken"."token" = 'F5EvjxKiiSVUiJ6XUqvwi7BzPlilnB'; args=('F5EvjxKiiSVUiJ6XUqvwi7BzPlilnB',)
[2016-11-09 21:45:58] DEBUG [django.db.backends:90] (0.001) SELECT "catalogo_categoria"."id", "catalogo_categoria"."nombre", "catalogo_categoria"."codigo", "catalogo_categoria"."estado" FROM "catalogo_categoria" WHERE ("catalogo_categoria"."codigo" LIKE '%%' ESCAPE '\' OR "catalogo_categoria"."nombre" LIKE '%%' ESCAPE '\'); args=('%%', '%%')
[2016-11-09 21:45:58] INFO [django.server:131] "GET /api/catalogo/categorias/ HTTP/1.1" 200 2
[2016-11-09 21:46:00] INFO [django.server:131] "OPTIONS /api/catalogo/autors/ HTTP/1.1" 200 0
[2016-11-09 21:46:00] DEBUG [django.db.backends:90] (0.006) SELECT "oauth2_provider_accesstoken"."id", "oauth2_provider_accesstoken"."user_id", "oauth2_provider_accesstoken"."token", "oauth2_provider_accesstoken"."application_id", "oauth2_provider_accesstoken"."expires", "oauth2_provider_accesstoken"."scope", "auths_user"."password", "auths_user"."last_login", "auths_user"."is_superuser", "auths_user"."username", "auths_user"."first_name", "auths_user"."last_name", "auths_user"."email", "auths_user"."is_staff", "auths_user"."is_active", "auths_user"."date_joined", "auths_user"."id", "auths_user"."last_hierarchy_id", "auths_user"."last_module_id", "auths_user"."person_id", "auths_user"."updated_at", "auths_user"."registered_by", "oauth2_provider_application"."id", "oauth2_provider_application"."client_id", "oauth2_provider_application"."user_id", "oauth2_provider_application"."redirect_uris", "oauth2_provider_application"."client_type", "oauth2_provider_application"."authorization_grant_type", "oauth2_provider_application"."client_secret", "oauth2_provider_application"."name", "oauth2_provider_application"."skip_authorization" FROM "oauth2_provider_accesstoken" LEFT OUTER JOIN "auths_user" ON ("oauth2_provider_accesstoken"."user_id" = "auths_user"."id") INNER JOIN "oauth2_provider_application" ON ("oauth2_provider_accesstoken"."application_id" = "oauth2_provider_application"."id") WHERE "oauth2_provider_accesstoken"."token" = 'F5EvjxKiiSVUiJ6XUqvwi7BzPlilnB'; args=('F5EvjxKiiSVUiJ6XUqvwi7BzPlilnB',)
[2016-11-09 21:46:00] DEBUG [django.db.backends:90] (0.000) SELECT COUNT(*) AS "__count" FROM "catalogo_autor"; args=()
[2016-11-09 21:46:00] INFO [django.server:131] "GET /api/catalogo/autors/ HTTP/1.1" 200 124
[2016-11-09 22:20:13] DEBUG [django.db.backends:90] (0.005) SELECT "oauth2_provider_accesstoken"."id", "oauth2_provider_accesstoken"."user_id", "oauth2_provider_accesstoken"."token", "oauth2_provider_accesstoken"."application_id", "oauth2_provider_accesstoken"."expires", "oauth2_provider_accesstoken"."scope", "auths_user"."password", "auths_user"."last_login", "auths_user"."is_superuser", "auths_user"."username", "auths_user"."first_name", "auths_user"."last_name", "auths_user"."email", "auths_user"."is_staff", "auths_user"."is_active", "auths_user"."date_joined", "auths_user"."id", "auths_user"."last_hierarchy_id", "auths_user"."last_module_id", "auths_user"."person_id", "auths_user"."updated_at", "auths_user"."registered_by", "oauth2_provider_application"."id", "oauth2_provider_application"."client_id", "oauth2_provider_application"."user_id", "oauth2_provider_application"."redirect_uris", "oauth2_provider_application"."client_type", "oauth2_provider_application"."authorization_grant_type", "oauth2_provider_application"."client_secret", "oauth2_provider_application"."name", "oauth2_provider_application"."skip_authorization" FROM "oauth2_provider_accesstoken" LEFT OUTER JOIN "auths_user" ON ("oauth2_provider_accesstoken"."user_id" = "auths_user"."id") INNER JOIN "oauth2_provider_application" ON ("oauth2_provider_accesstoken"."application_id" = "oauth2_provider_application"."id") WHERE "oauth2_provider_accesstoken"."token" = 'F5EvjxKiiSVUiJ6XUqvwi7BzPlilnB'; args=('F5EvjxKiiSVUiJ6XUqvwi7BzPlilnB',)
[2016-11-09 22:20:13] DEBUG [django.db.backends:90] (0.007) SELECT "oauth2_provider_accesstoken"."id", "oauth2_provider_accesstoken"."user_id", "oauth2_provider_accesstoken"."token", "oauth2_provider_accesstoken"."application_id", "oauth2_provider_accesstoken"."expires", "oauth2_provider_accesstoken"."scope", "auths_user"."password", "auths_user"."last_login", "auths_user"."is_superuser", "auths_user"."username", "auths_user"."first_name", "auths_user"."last_name", "auths_user"."email", "auths_user"."is_staff", "auths_user"."is_active", "auths_user"."date_joined", "auths_user"."id", "auths_user"."last_hierarchy_id", "auths_user"."last_module_id", "auths_user"."person_id", "auths_user"."updated_at", "auths_user"."registered_by", "oauth2_provider_application"."id", "oauth2_provider_application"."client_id", "oauth2_provider_application"."user_id", "oauth2_provider_application"."redirect_uris", "oauth2_provider_application"."client_type", "oauth2_provider_application"."authorization_grant_type", "oauth2_provider_application"."client_secret", "oauth2_provider_application"."name", "oauth2_provider_application"."skip_authorization" FROM "oauth2_provider_accesstoken" LEFT OUTER JOIN "auths_user" ON ("oauth2_provider_accesstoken"."user_id" = "auths_user"."id") INNER JOIN "oauth2_provider_application" ON ("oauth2_provider_accesstoken"."application_id" = "oauth2_provider_application"."id") WHERE "oauth2_provider_accesstoken"."token" = 'F5EvjxKiiSVUiJ6XUqvwi7BzPlilnB'; args=('F5EvjxKiiSVUiJ6XUqvwi7BzPlilnB',)
[2016-11-09 22:20:13] DEBUG [django.db.backends:90] (0.001) SELECT "auths_menu"."id" FROM "auths_menu" WHERE ("auths_menu"."id" IS NOT NULL AND "auths_menu"."is_active" = 1 AND "auths_menu"."module" = 'BACKEND') ORDER BY "auths_menu"."pos" ASC; args=(True, 'BACKEND')
[2016-11-09 22:20:13] DEBUG [django.db.backends:90] (0.001) SELECT "auth_group"."id", "auth_group"."name" FROM "auth_group" INNER JOIN "auths_user_groups" ON ("auth_group"."id" = "auths_user_groups"."group_id") WHERE "auths_user_groups"."user_id" = '3651942c1384420da02bbf9e5eca3faa'; args=('3651942c1384420da02bbf9e5eca3faa',)
[2016-11-09 22:20:13] DEBUG [django.db.backends:90] (0.002) SELECT "auth_permission"."id", "auth_permission"."name", "auth_permission"."content_type_id", "auth_permission"."codename" FROM "auth_permission" INNER JOIN "auths_user_user_permissions" ON ("auth_permission"."id" = "auths_user_user_permissions"."permission_id") INNER JOIN "django_content_type" ON ("auth_permission"."content_type_id" = "django_content_type"."id") WHERE "auths_user_user_permissions"."user_id" = '3651942c1384420da02bbf9e5eca3faa' ORDER BY "django_content_type"."app_label" ASC, "django_content_type"."model" ASC, "auth_permission"."codename" ASC; args=('3651942c1384420da02bbf9e5eca3faa',)
[2016-11-09 22:20:13] INFO [django.server:131] "GET /api/auths/localuserinfo/ HTTP/1.1" 200 496
[2016-11-09 22:20:13] DEBUG [django.db.backends:90] (0.000) SELECT (1) AS "a" FROM "django_session" WHERE "django_session"."session_key" = 'qsj3zm9vmjnot6gef4l2i9o6sxu1trcz' LIMIT 1; args=('qsj3zm9vmjnot6gef4l2i9o6sxu1trcz',)
[2016-11-09 22:20:13] DEBUG [django.db.backends:90] (0.000) BEGIN; args=None
[2016-11-09 22:20:13] DEBUG [django.db.backends:90] (0.002) INSERT INTO "django_session" ("session_key", "session_data", "expire_date") SELECT 'qsj3zm9vmjnot6gef4l2i9o6sxu1trcz', 'NmE3M2Q3NmYwOTU3YjJmZDBjYmQxYTVjODc5MTExNzM3NjY1YzYzNzp7Il9zZXNzaW9uX2V4cGlyeSI6MzB9', '2016-11-10 03:20:43.947274'; args=('qsj3zm9vmjnot6gef4l2i9o6sxu1trcz', 'NmE3M2Q3NmYwOTU3YjJmZDBjYmQxYTVjODc5MTExNzM3NjY1YzYzNzp7Il9zZXNzaW9uX2V4cGlyeSI6MzB9', '2016-11-10 03:20:43.947274')
[2016-11-09 22:20:14] INFO [django.server:131] "GET /api/auths/usermenu/ HTTP/1.1" 200 11
[2016-11-09 22:20:14] DEBUG [django.db.backends:90] (0.004) SELECT "oauth2_provider_accesstoken"."id", "oauth2_provider_accesstoken"."user_id", "oauth2_provider_accesstoken"."token", "oauth2_provider_accesstoken"."application_id", "oauth2_provider_accesstoken"."expires", "oauth2_provider_accesstoken"."scope", "auths_user"."password", "auths_user"."last_login", "auths_user"."is_superuser", "auths_user"."username", "auths_user"."first_name", "auths_user"."last_name", "auths_user"."email", "auths_user"."is_staff", "auths_user"."is_active", "auths_user"."date_joined", "auths_user"."id", "auths_user"."last_hierarchy_id", "auths_user"."last_module_id", "auths_user"."person_id", "auths_user"."updated_at", "auths_user"."registered_by", "oauth2_provider_application"."id", "oauth2_provider_application"."client_id", "oauth2_provider_application"."user_id", "oauth2_provider_application"."redirect_uris", "oauth2_provider_application"."client_type", "oauth2_provider_application"."authorization_grant_type", "oauth2_provider_application"."client_secret", "oauth2_provider_application"."name", "oauth2_provider_application"."skip_authorization" FROM "oauth2_provider_accesstoken" LEFT OUTER JOIN "auths_user" ON ("oauth2_provider_accesstoken"."user_id" = "auths_user"."id") INNER JOIN "oauth2_provider_application" ON ("oauth2_provider_accesstoken"."application_id" = "oauth2_provider_application"."id") WHERE "oauth2_provider_accesstoken"."token" = 'F5EvjxKiiSVUiJ6XUqvwi7BzPlilnB'; args=('F5EvjxKiiSVUiJ6XUqvwi7BzPlilnB',)
[2016-11-09 22:20:14] DEBUG [django.db.backends:90] (0.001) SELECT COUNT(*) AS "__count" FROM "catalogo_autor"; args=()
[2016-11-09 22:20:14] INFO [django.server:131] "GET /api/catalogo/autors/ HTTP/1.1" 200 124
[2016-11-09 22:20:20] DEBUG [django.db.backends:90] (0.004) SELECT "oauth2_provider_accesstoken"."id", "oauth2_provider_accesstoken"."user_id", "oauth2_provider_accesstoken"."token", "oauth2_provider_accesstoken"."application_id", "oauth2_provider_accesstoken"."expires", "oauth2_provider_accesstoken"."scope", "auths_user"."password", "auths_user"."last_login", "auths_user"."is_superuser", "auths_user"."username", "auths_user"."first_name", "auths_user"."last_name", "auths_user"."email", "auths_user"."is_staff", "auths_user"."is_active", "auths_user"."date_joined", "auths_user"."id", "auths_user"."last_hierarchy_id", "auths_user"."last_module_id", "auths_user"."person_id", "auths_user"."updated_at", "auths_user"."registered_by", "oauth2_provider_application"."id", "oauth2_provider_application"."client_id", "oauth2_provider_application"."user_id", "oauth2_provider_application"."redirect_uris", "oauth2_provider_application"."client_type", "oauth2_provider_application"."authorization_grant_type", "oauth2_provider_application"."client_secret", "oauth2_provider_application"."name", "oauth2_provider_application"."skip_authorization" FROM "oauth2_provider_accesstoken" LEFT OUTER JOIN "auths_user" ON ("oauth2_provider_accesstoken"."user_id" = "auths_user"."id") INNER JOIN "oauth2_provider_application" ON ("oauth2_provider_accesstoken"."application_id" = "oauth2_provider_application"."id") WHERE "oauth2_provider_accesstoken"."token" = 'F5EvjxKiiSVUiJ6XUqvwi7BzPlilnB'; args=('F5EvjxKiiSVUiJ6XUqvwi7BzPlilnB',)
[2016-11-09 22:20:20] DEBUG [django.db.backends:90] (0.000) SELECT "catalogo_categoria"."id", "catalogo_categoria"."nombre", "catalogo_categoria"."codigo", "catalogo_categoria"."estado" FROM "catalogo_categoria" WHERE ("catalogo_categoria"."codigo" LIKE '%%' ESCAPE '\' OR "catalogo_categoria"."nombre" LIKE '%%' ESCAPE '\'); args=('%%', '%%')
[2016-11-09 22:20:20] INFO [django.server:131] "GET /api/catalogo/categorias/ HTTP/1.1" 200 2
[2016-11-09 22:20:27] DEBUG [django.db.backends:90] (0.006) SELECT "oauth2_provider_accesstoken"."id", "oauth2_provider_accesstoken"."user_id", "oauth2_provider_accesstoken"."token", "oauth2_provider_accesstoken"."application_id", "oauth2_provider_accesstoken"."expires", "oauth2_provider_accesstoken"."scope", "auths_user"."password", "auths_user"."last_login", "auths_user"."is_superuser", "auths_user"."username", "auths_user"."first_name", "auths_user"."last_name", "auths_user"."email", "auths_user"."is_staff", "auths_user"."is_active", "auths_user"."date_joined", "auths_user"."id", "auths_user"."last_hierarchy_id", "auths_user"."last_module_id", "auths_user"."person_id", "auths_user"."updated_at", "auths_user"."registered_by", "oauth2_provider_application"."id", "oauth2_provider_application"."client_id", "oauth2_provider_application"."user_id", "oauth2_provider_application"."redirect_uris", "oauth2_provider_application"."client_type", "oauth2_provider_application"."authorization_grant_type", "oauth2_provider_application"."client_secret", "oauth2_provider_application"."name", "oauth2_provider_application"."skip_authorization" FROM "oauth2_provider_accesstoken" LEFT OUTER JOIN "auths_user" ON ("oauth2_provider_accesstoken"."user_id" = "auths_user"."id") INNER JOIN "oauth2_provider_application" ON ("oauth2_provider_accesstoken"."application_id" = "oauth2_provider_application"."id") WHERE "oauth2_provider_accesstoken"."token" = 'F5EvjxKiiSVUiJ6XUqvwi7BzPlilnB'; args=('F5EvjxKiiSVUiJ6XUqvwi7BzPlilnB',)
[2016-11-09 22:20:27] DEBUG [django.db.backends:90] (0.000) SELECT COUNT(*) AS "__count" FROM "catalogo_autor"; args=()
[2016-11-09 22:20:27] INFO [django.server:131] "GET /api/catalogo/autors/ HTTP/1.1" 200 124
[2016-11-09 22:20:28] DEBUG [django.db.backends:90] (0.003) SELECT "oauth2_provider_accesstoken"."id", "oauth2_provider_accesstoken"."user_id", "oauth2_provider_accesstoken"."token", "oauth2_provider_accesstoken"."application_id", "oauth2_provider_accesstoken"."expires", "oauth2_provider_accesstoken"."scope", "auths_user"."password", "auths_user"."last_login", "auths_user"."is_superuser", "auths_user"."username", "auths_user"."first_name", "auths_user"."last_name", "auths_user"."email", "auths_user"."is_staff", "auths_user"."is_active", "auths_user"."date_joined", "auths_user"."id", "auths_user"."last_hierarchy_id", "auths_user"."last_module_id", "auths_user"."person_id", "auths_user"."updated_at", "auths_user"."registered_by", "oauth2_provider_application"."id", "oauth2_provider_application"."client_id", "oauth2_provider_application"."user_id", "oauth2_provider_application"."redirect_uris", "oauth2_provider_application"."client_type", "oauth2_provider_application"."authorization_grant_type", "oauth2_provider_application"."client_secret", "oauth2_provider_application"."name", "oauth2_provider_application"."skip_authorization" FROM "oauth2_provider_accesstoken" LEFT OUTER JOIN "auths_user" ON ("oauth2_provider_accesstoken"."user_id" = "auths_user"."id") INNER JOIN "oauth2_provider_application" ON ("oauth2_provider_accesstoken"."application_id" = "oauth2_provider_application"."id") WHERE "oauth2_provider_accesstoken"."token" = 'F5EvjxKiiSVUiJ6XUqvwi7BzPlilnB'; args=('F5EvjxKiiSVUiJ6XUqvwi7BzPlilnB',)
[2016-11-09 22:20:28] DEBUG [django.db.backends:90] (0.001) SELECT "catalogo_categoria"."id", "catalogo_categoria"."nombre", "catalogo_categoria"."codigo", "catalogo_categoria"."estado" FROM "catalogo_categoria" WHERE ("catalogo_categoria"."codigo" LIKE '%%' ESCAPE '\' OR "catalogo_categoria"."nombre" LIKE '%%' ESCAPE '\'); args=('%%', '%%')
[2016-11-09 22:20:28] INFO [django.server:131] "GET /api/catalogo/categorias/ HTTP/1.1" 200 2
[2016-11-09 22:24:08] DEBUG [django.db.backends:90] (0.004) SELECT "oauth2_provider_accesstoken"."id", "oauth2_provider_accesstoken"."user_id", "oauth2_provider_accesstoken"."token", "oauth2_provider_accesstoken"."application_id", "oauth2_provider_accesstoken"."expires", "oauth2_provider_accesstoken"."scope", "auths_user"."password", "auths_user"."last_login", "auths_user"."is_superuser", "auths_user"."username", "auths_user"."first_name", "auths_user"."last_name", "auths_user"."email", "auths_user"."is_staff", "auths_user"."is_active", "auths_user"."date_joined", "auths_user"."id", "auths_user"."last_hierarchy_id", "auths_user"."last_module_id", "auths_user"."person_id", "auths_user"."updated_at", "auths_user"."registered_by", "oauth2_provider_application"."id", "oauth2_provider_application"."client_id", "oauth2_provider_application"."user_id", "oauth2_provider_application"."redirect_uris", "oauth2_provider_application"."client_type", "oauth2_provider_application"."authorization_grant_type", "oauth2_provider_application"."client_secret", "oauth2_provider_application"."name", "oauth2_provider_application"."skip_authorization" FROM "oauth2_provider_accesstoken" LEFT OUTER JOIN "auths_user" ON ("oauth2_provider_accesstoken"."user_id" = "auths_user"."id") INNER JOIN "oauth2_provider_application" ON ("oauth2_provider_accesstoken"."application_id" = "oauth2_provider_application"."id") WHERE "oauth2_provider_accesstoken"."token" = 'F5EvjxKiiSVUiJ6XUqvwi7BzPlilnB'; args=('F5EvjxKiiSVUiJ6XUqvwi7BzPlilnB',)
[2016-11-09 22:24:08] DEBUG [django.db.backends:90] (0.004) SELECT "oauth2_provider_accesstoken"."id", "oauth2_provider_accesstoken"."user_id", "oauth2_provider_accesstoken"."token", "oauth2_provider_accesstoken"."application_id", "oauth2_provider_accesstoken"."expires", "oauth2_provider_accesstoken"."scope", "auths_user"."password", "auths_user"."last_login", "auths_user"."is_superuser", "auths_user"."username", "auths_user"."first_name", "auths_user"."last_name", "auths_user"."email", "auths_user"."is_staff", "auths_user"."is_active", "auths_user"."date_joined", "auths_user"."id", "auths_user"."last_hierarchy_id", "auths_user"."last_module_id", "auths_user"."person_id", "auths_user"."updated_at", "auths_user"."registered_by", "oauth2_provider_application"."id", "oauth2_provider_application"."client_id", "oauth2_provider_application"."user_id", "oauth2_provider_application"."redirect_uris", "oauth2_provider_application"."client_type", "oauth2_provider_application"."authorization_grant_type", "oauth2_provider_application"."client_secret", "oauth2_provider_application"."name", "oauth2_provider_application"."skip_authorization" FROM "oauth2_provider_accesstoken" LEFT OUTER JOIN "auths_user" ON ("oauth2_provider_accesstoken"."user_id" = "auths_user"."id") INNER JOIN "oauth2_provider_application" ON ("oauth2_provider_accesstoken"."application_id" = "oauth2_provider_application"."id") WHERE "oauth2_provider_accesstoken"."token" = 'F5EvjxKiiSVUiJ6XUqvwi7BzPlilnB'; args=('F5EvjxKiiSVUiJ6XUqvwi7BzPlilnB',)
[2016-11-09 22:24:08] DEBUG [django.db.backends:90] (0.001) SELECT "auth_group"."id", "auth_group"."name" FROM "auth_group" INNER JOIN "auths_user_groups" ON ("auth_group"."id" = "auths_user_groups"."group_id") WHERE "auths_user_groups"."user_id" = '3651942c1384420da02bbf9e5eca3faa'; args=('3651942c1384420da02bbf9e5eca3faa',)
[2016-11-09 22:24:08] DEBUG [django.db.backends:90] (0.001) SELECT "auth_permission"."id", "auth_permission"."name", "auth_permission"."content_type_id", "auth_permission"."codename" FROM "auth_permission" INNER JOIN "auths_user_user_permissions" ON ("auth_permission"."id" = "auths_user_user_permissions"."permission_id") INNER JOIN "django_content_type" ON ("auth_permission"."content_type_id" = "django_content_type"."id") WHERE "auths_user_user_permissions"."user_id" = '3651942c1384420da02bbf9e5eca3faa' ORDER BY "django_content_type"."app_label" ASC, "django_content_type"."model" ASC, "auth_permission"."codename" ASC; args=('3651942c1384420da02bbf9e5eca3faa',)
[2016-11-09 22:24:08] INFO [django.server:131] "GET /api/auths/localuserinfo/ HTTP/1.1" 200 496
[2016-11-09 22:24:08] DEBUG [django.db.backends:90] (0.000) SELECT "auths_menu"."id" FROM "auths_menu" WHERE ("auths_menu"."id" IS NOT NULL AND "auths_menu"."is_active" = 1 AND "auths_menu"."module" = 'BACKEND') ORDER BY "auths_menu"."pos" ASC; args=(True, 'BACKEND')
[2016-11-09 22:24:08] DEBUG [django.db.backends:90] (0.001) SELECT (1) AS "a" FROM "django_session" WHERE "django_session"."session_key" = '8rda6gxirmzqu19a7l540cbn7ot8z54h' LIMIT 1; args=('8rda6gxirmzqu19a7l540cbn7ot8z54h',)
[2016-11-09 22:24:08] DEBUG [django.db.backends:90] (0.000) BEGIN; args=None
[2016-11-09 22:24:08] DEBUG [django.db.backends:90] (0.020) INSERT INTO "django_session" ("session_key", "session_data", "expire_date") SELECT '8rda6gxirmzqu19a7l540cbn7ot8z54h', 'NmE3M2Q3NmYwOTU3YjJmZDBjYmQxYTVjODc5MTExNzM3NjY1YzYzNzp7Il9zZXNzaW9uX2V4cGlyeSI6MzB9', '2016-11-10 03:24:38.125270'; args=('8rda6gxirmzqu19a7l540cbn7ot8z54h', 'NmE3M2Q3NmYwOTU3YjJmZDBjYmQxYTVjODc5MTExNzM3NjY1YzYzNzp7Il9zZXNzaW9uX2V4cGlyeSI6MzB9', '2016-11-10 03:24:38.125270')
[2016-11-09 22:24:08] INFO [django.server:131] "GET /api/auths/usermenu/ HTTP/1.1" 200 11
[2016-11-09 22:24:08] DEBUG [django.db.backends:90] (0.003) SELECT "oauth2_provider_accesstoken"."id", "oauth2_provider_accesstoken"."user_id", "oauth2_provider_accesstoken"."token", "oauth2_provider_accesstoken"."application_id", "oauth2_provider_accesstoken"."expires", "oauth2_provider_accesstoken"."scope", "auths_user"."password", "auths_user"."last_login", "auths_user"."is_superuser", "auths_user"."username", "auths_user"."first_name", "auths_user"."last_name", "auths_user"."email", "auths_user"."is_staff", "auths_user"."is_active", "auths_user"."date_joined", "auths_user"."id", "auths_user"."last_hierarchy_id", "auths_user"."last_module_id", "auths_user"."person_id", "auths_user"."updated_at", "auths_user"."registered_by", "oauth2_provider_application"."id", "oauth2_provider_application"."client_id", "oauth2_provider_application"."user_id", "oauth2_provider_application"."redirect_uris", "oauth2_provider_application"."client_type", "oauth2_provider_application"."authorization_grant_type", "oauth2_provider_application"."client_secret", "oauth2_provider_application"."name", "oauth2_provider_application"."skip_authorization" FROM "oauth2_provider_accesstoken" LEFT OUTER JOIN "auths_user" ON ("oauth2_provider_accesstoken"."user_id" = "auths_user"."id") INNER JOIN "oauth2_provider_application" ON ("oauth2_provider_accesstoken"."application_id" = "oauth2_provider_application"."id") WHERE "oauth2_provider_accesstoken"."token" = 'F5EvjxKiiSVUiJ6XUqvwi7BzPlilnB'; args=('F5EvjxKiiSVUiJ6XUqvwi7BzPlilnB',)
[2016-11-09 22:24:08] DEBUG [django.db.backends:90] (0.001) SELECT "catalogo_categoria"."id", "catalogo_categoria"."nombre", "catalogo_categoria"."codigo", "catalogo_categoria"."estado" FROM "catalogo_categoria" WHERE ("catalogo_categoria"."codigo" LIKE '%%' ESCAPE '\' OR "catalogo_categoria"."nombre" LIKE '%%' ESCAPE '\'); args=('%%', '%%')
[2016-11-09 22:24:08] INFO [django.server:131] "GET /api/catalogo/categorias/ HTTP/1.1" 200 2
